Workbook

Sheet 封面与摘要
A1: 三环集团（300408.SZ / 06951.HK）详细财务与估值模型
A2: 编制日期：2026-09-30｜单位：百万元人民币（另注明除外）｜数据截至2026年半年报（2026-08-28）
A4: 使用说明
A5: 1. 在“假设”C5切换情景（1=基准，2=乐观，3=悲观）；蓝字为录入值/假设，黑字为本表公式，绿字为跨表链接，灰底为预测列，黄底为关键假设。
A6: 2. 模型链路：假设 → 收入拆解（量价、SOFC子模型）→ 成本拆解（分部毛利率、成本按性质）→ 人员与费用（人数×人均薪酬）→ 资本开支与折旧（在建工程、四类固定资产）→ 营运资金（分项周转天数）→ 融资与资金（利息、权益变动）→ 税务与其他损益（所得税桥）→ 三表预测 → 回报分析 → DCF/相对估值。
A7: 3. 利息收入按期初余额计息、利息费用按平均借款余额，模型无循环引用；货币资金由现金流量表倒挤，资产负债表自动配平。营业成本以分部毛利率为主驱动，生产人工与生产折旧偏离基准标定值的部分直接计入营业成本；DCF第二阶段与永续期按“再投资率=增速÷RONIC”计算FCFF。
A8: 4. “假设”第四节为敏感性冲击单元（默认0）；“敏感性分析”“情景对比”两表为重算引擎写入的静态结果，修改假设后需重跑才会更新；DCF表内的WACC×增长率表与反向DCF为实时公式。
A9: 5. 历史数据：三张报表来自Wind（公司公告值）；附注明细（固定资产变动、成本构成、员工、存货、税率调节等）取自年报/半年报原文，见“披露明细”。
A10: 6. “校验”表汇总应为0；A股股价、汇率、可比公司倍数请按最新行情更新。
A12: 核心输出（随情景自动更新）
A13: 指标 | C13: 2025A | D13: 2026E | E13: 2027E | F13: 2028E | G13: 2029E | H13: 2030E
A14: 营业收入 | C14: =三表预测!G6 -> 9007.1539 | D14: =三表预测!H6 -> 13863.187 | E14: =三表预测!I6 -> 17550.903 | F14: =三表预测!J6 -> 20155.217 | G14: =三表预测!K6 -> 22196.957 | H14: =三表预测!L6 -> 23693.89
A15: 同比 | C15: =三表预测!G7 -> 0.22131053 | D15: =三表预测!H7 -> 0.53913074 | E15: =三表预测!I7 -> 0.26600776 | F15: =三表预测!J7 -> 0.14838634 | G15: =三表预测!K7 -> 0.10130079 | H15: =三表预测!L7 -> 0.067438657
A16: 电子元件 | C16: =收入拆解!G17 -> 3308.0896 | D16: =收入拆解!H17 -> 5983.6724 | E16: =收入拆解!I17 -> 8077.9578 | F16: =收入拆解!J17 -> 9698.3961 | G16: =收入拆解!K17 -> 10862.204 | H16: =收入拆解!L17 -> 11709.456
A17: 通信器件 | C17: =收入拆解!G26 -> 2594.3099 | D17: =收入拆解!H26 -> 3955.5443 | E17: =收入拆解!I26 -> 4936.5193 | F17: =收入拆解!J26 -> 5686.8702 | G17: =收入拆解!K26 -> 6256.1259 | H17: =收入拆解!L26 -> 6735.9708
A18: 电子及陶瓷材料 | C18: =收入拆解!G41 -> 1959.378 | D18: =收入拆解!H41 -> 2525.459 | E18: =收入拆解!I41 -> 3018.5474 | F18: =收入拆解!J41 -> 3136.9255 | G18: =收入拆解!K41 -> 3338.3736 | H18: =收入拆解!L41 -> 3412.4894
A19: 其中SOFC隔膜片（2025A为第一大客户销售额代理） | C19: =收入拆解!G38 -> 330.718 | D19: =收入拆解!H38 -> 652.5 | E19: =收入拆解!I38 -> 920.83333 | F19: =收入拆解!J38 -> 829.44 | G19: =收入拆解!K38 -> 846.28923 | H19: =收入拆解!L38 -> 770.88
A20: 毛利率 | C20: =三表预测!G10 -> 0.4213753 | D20: =三表预测!H10 -> 0.44928717 | E20: =三表预测!I10 -> 0.45214207 | F20: =三表预测!J10 -> 0.44374172 | G20: =三表预测!K10 -> 0.43428588 | H20: =三表预测!L10 -> 0.42888197
A21: 期间费用率（销售+管理+研发） | C21: =人员与费用!G51 -> 0.13629013 | D21: =人员与费用!H51 -> 0.10788538 | E21: =人员与费用!I51 -> 0.10084219 | F21: =人员与费用!J51 -> 0.098670245 | G21: =人员与费用!K51 -> 0.098318583 | H21: =人员与费用!L51 -> 0.099206129
A22: 归母净利润 | C22: =三表预测!G26 -> 2618.3839 | D22: =三表预测!H26 -> 4260.3565 | E22: =三表预测!I26 -> 5632.1372 | F22: =三表预测!J26 -> 6237.7654 | G22: =三表预测!K26 -> 6667.0317 | H22: =三表预测!L26 -> 7002.6492
A23: 同比 | C23: =三表预测!G27 -> 0.1953639 | D23: =三表预测!H27 -> 0.62709392 | E23: =三表预测!I27 -> 0.3219873 | F23: =三表预测!J27 -> 0.10753079 | G23: =三表预测!K27 -> 0.068817316 | H23: =三表预测!L27 -> 0.050339864
A24: EPS（期末流通股本，元） | C24: =三表预测!G29 -> 1.3699036 | D24: =三表预测!H29 -> 2.1552782 | E24: =三表预测!I29 -> 2.8492505 | F24: =三表预测!J29 -> 3.1556326 | G24: =三表预测!K29 -> 3.3727948 | H24: =三表预测!L29 -> 3.5425808
A25: 实际税率 | C25: =税务与其他损益!G28 -> 0.13004434 | D25: =税务与其他损益!H28 -> 0.13252461 | E25: =税务与其他损益!I28 -> 0.13951906 | F25: =税务与其他损益!J28 -> 0.13905344 | G25: =税务与其他损益!K28 -> 0.13843215 | H25: =税务与其他损益!L28 -> 0.13780101
A26: ROE（杜邦，平均） | C26: =回报分析!G8 -> 0.12611169 | D26: =回报分析!H8 -> 0.16421577 | E26: =回报分析!I8 -> 0.17414502 | F26: =回报分析!J8 -> 0.17022453 | G26: =回报分析!K8 -> 0.16206424 | H26: =回报分析!L8 -> 0.15275034
A27: ROIC | C27: =回报分析!G11 -> 0.25480171 | D27: =回报分析!H11 -> 0.37290887 | E27: =回报分析!I11 -> 0.40110246 | F27: =回报分析!J11 -> 0.37370282 | G27: =回报分析!K11 -> 0.35914986 | H27: =回报分析!L11 -> 0.35367001
A28: 资本开支（历史=现金口径；预测=新增投入） | C28: =资本开支与折旧!G11 -> 580.092 | D28: =资本开支与折旧!H11 -> 1787.9753 | E28: =资本开支与折旧!I11 -> 2593.5925 | F28: =资本开支与折旧!J11 -> 2358.5137 | G28: =资本开支与折旧!K11 -> 1918.9354 | H28: =资本开支与折旧!L11 -> 1679.4592
A29: 折旧摊销 | C29: =资本开支与折旧!G91 -> 740.43309 | D29: =资本开支与折旧!H91 -> 813.65692 | E29: =资本开支与折旧!I91 -> 914.99495 | F29: =资本开支与折旧!J91 -> 1060.0309 | G29: =资本开支与折旧!K91 -> 1212.6478 | H29: =资本开支与折旧!L91 -> 1348.2187
A30: 营运资本/收入 | C30: =营运资金!G32 -> 0.36942359 | D30: =营运资金!H32 -> 0.33864913 | E30: =营运资金!I32 -> 0.3425847 | F30: =营运资金!J32 -> 0.34429006 | G30: =营运资金!K32 -> 0.34525345 | H30: =营运资金!L32 -> 0.34495758
A31: 自由现金流（经营现金流-资本开支） | C31: =三表预测!G93 -> 2297.5171 | D31: =三表预测!H93 -> 1878.0406 | E31: =三表预测!I93 -> 2579.2476 | F31: =三表预测!J93 -> 3956.3348 | G31: =三表预测!K93 -> 5180.0314 | H31: =三表预测!L93 -> 6105.2201
A32: 净现金（含一年以上定期存款） | C32: =融资与资金!G43 -> 12080.847 | D32: =融资与资金!H43 -> 18350.22 | E32: =融资与资金!I43 -> 19604.426 | F32: =融资与资金!J43 -> 21788 | G32: =融资与资金!K43 -> 25001.524 | H32: =融资与资金!L43 -> 29004.191
A33: 员工人数（期末） | C33: =人员与费用!G11 -> 17352 | D33: =人员与费用!H11 -> 19628.91 | E33: =人员与费用!I11 -> 21417.099 | F33: =人员与费用!J11 -> 22809.931 | G33: =人员与费用!K11 -> 23893.979 | H33: =人员与费用!L11 -> 24832.667
A34: PE（当前股价，流通股口径） | C34: =回报分析!G16 -> 86.502435 | D34: =回报分析!H16 -> 54.9813 | E34: =回报分析!I16 -> 41.589885 | F34: =回报分析!J16 -> 37.5519 | G34: =回报分析!K16 -> 35.134067 | H34: =回报分析!L16 -> 33.450189
A36: 估值摘要
A37: 当前情景（1基准/2乐观/3悲观） | C37: =假设!$C$5 -> 1
A38: A股股价（元） | C38: =假设!$C$6 -> 118.5
A39: WACC | C39: =DCF估值!$C$7 -> 0.089285
A40: 永续增长率 | C40: =DCF估值!$C$8 -> 0.03
A41: DCF每股价值（元，2026-12-31） | C41: =DCF估值!$C$41 -> 55.033813
A42: DCF每股价值折回当前（元） | C42: =DCF估值!$C$42 -> 53.854647
A43: 相对当前股价空间 | C43: =DCF估值!$C$44 -> -0.5455304
...

Sheet 财务汇总
A1: 三环集团（300408.SZ / 06951.HK）财务模型汇总
A2: 单位：百万元人民币（另注明除外）｜年度：2023A-2025A为报告值，2026E-2030E为基准情景（随“假设”C5切换）｜季度：单季报告值｜全部为链接公式
C3: 年度 / Annual | L3: 季度（单季）/ Quarterly
A4: 项目 | C4: 2023A | D4: 2024A | E4: 2025A | F4: 2026E | G4: 2027E | H4: 2028E | I4: 2029E | J4: 2030E | L4: 2025Q1 | M4: 2025Q2 | N4: 2025Q3 | O4: 2025Q4 | P4: 2026Q1 | Q4: 2026Q2
A5: 一、利润表
A6: 营业收入 | C6: =三表预测!E6 -> 5726.6885 | D6: =三表预测!F6 -> 7374.9908 | E6: =三表预测!G6 -> 9007.1539 | F6: =三表预测!H6 -> 13863.187 | G6: =三表预测!I6 -> 17550.903 | H6: =三表预测!J6 -> 20155.217 | I6: =三表预测!K6 -> 22196.957 | J6: =三表预测!L6 -> 23693.89 | L6: =季度数据!G5 -> 1833.141 | M6: =季度数据!H5 -> 2315.6541 | N6: =季度数据!I5 -> 2359.5738 | O6: =季度数据!J5 -> 2498.785 | P6: =季度数据!K5 -> 2680.9934 | Q6: =季度数据!L5 -> 3742.3384
A7: 同比 | C7: =三表预测!E7 -> 0.11211074 | D7: =三表预测!F7 -> 0.28782818 | E7: =三表预测!G7 -> 0.22131053 | F7: =三表预测!H7 -> 0.53913074 | G7: =三表预测!I7 -> 0.26600776 | H7: =三表预测!J7 -> 0.14838634 | I7: =三表预测!K7 -> 0.10130079 | J7: =三表预测!L7 -> 0.067438657 | L7: =IFERROR(季度数据!G5/季度数据!C5-1,0) -> 0.17237341 | M7: =IFERROR(季度数据!H5/季度数据!D5-1,0) -> 0.24244341 | N7: =IFERROR(季度数据!I5/季度数据!E5-1,0) -> 0.20794779 | O7: =IFERROR(季度数据!J5/季度数据!F5-1,0) -> 0.2530193 | P7: =IFERROR(季度数据!K5/季度数据!G5-1,0) -> 0.46251347 | Q7: =IFERROR(季度数据!L5/季度数据!H5-1,0) -> 0.61610424
A8: 毛利 | C8: =三表预测!E9 -> 2281.1586 | D8: =三表预测!F9 -> 3170.1271 | E8: =三表预测!G9 -> 3795.3922 | F8: =三表预测!H9 -> 6228.5523 | G8: =三表预测!I9 -> 7935.5016 | H8: =三表预测!J9 -> 8943.7107 | I8: =三表预测!K9 -> 9639.8248 | J8: =三表预测!L9 -> 10161.882 | L8: =季度数据!G5-季度数据!G6 -> 751.8142 | M8: =季度数据!H5-季度数据!H6 -> 989.6012 | N8: =季度数据!I5-季度数据!I6 -> 1023.8903 | O8: =季度数据!J5-季度数据!J6 -> 1030.0866 | P8: =季度数据!K5-季度数据!K6 -> 1165.9354 | Q8: =季度数据!L5-季度数据!L6 -> 1680.8635
A9: 毛利率 | C9: =三表预测!E10 -> 0.39833817 | D9: =三表预测!F10 -> 0.42984828 | E9: =三表预测!G10 -> 0.4213753 | F9: =三表预测!H10 -> 0.44928717 | G9: =三表预测!I10 -> 0.45214207 | H9: =三表预测!J10 -> 0.44374172 | I9: =三表预测!K10 -> 0.43428588 | J9: =三表预测!L10 -> 0.42888197 | L9: =IFERROR(1-季度数据!G6/季度数据!G5,0) -> 0.4101235 | M9: =IFERROR(1-季度数据!H6/季度数据!H5,0) -> 0.42735277 | N9: =IFERROR(1-季度数据!I6/季度数据!I5,0) -> 0.43393019 | O9: =IFERROR(1-季度数据!J6/季度数据!J5,0) -> 0.41223499 | P9: =IFERROR(1-季度数据!K6/季度数据!K5,0) -> 0.43488932 | Q9: =IFERROR(1-季度数据!L6/季度数据!L5,0) -> 0.44914792
A10: 销售费用 | C10: =三表预测!E12 -> 74.3431 | D10: =三表预测!F12 -> 79.3918 | E10: =三表预测!G12 -> 93.1993 | F10: =三表预测!H12 -> 105.04434 | G10: =三表预测!I12 -> 124.93085 | H10: =三表预测!J12 -> 141.37808 | I10: =三表预测!K12 -> 155.37852 | J10: =三表预测!L12 -> 167.88891 | L10: =季度数据!G8 -> 21.2322 | M10: =季度数据!H8 -> 20.7534 | N10: =季度数据!I8 -> 24.9725 | O10: =季度数据!J8 -> 26.2412 | P10: =季度数据!K8 -> 22.2371 | Q10: =季度数据!L8 -> 22.5728
A11: 管理费用 | C11: =三表预测!E13 -> 429.4141 | D11: =三表预测!F13 -> 409.8445 | E11: =三表预测!G13 -> 480.9502 | F11: =三表预测!H13 -> 609.33009 | G11: =三表预测!I13 -> 700.42727 | H11: =三表预测!J13 -> 776.84113 | I11: =三表预测!K13 -> 848.03725 | J11: =三表预测!L13 -> 907.31969 | L11: =季度数据!G9 -> 93.9391 | M11: =季度数据!H9 -> 97.5199 | N11: =季度数据!I9 -> 108.3876 | O11: =季度数据!J9 -> 181.1035 | P11: =季度数据!K9 -> 123.0153 | Q11: =季度数据!L9 -> 131.9151
A12: 研发费用 | C12: =三表预测!E14 -> 545.8062 | D12: =三表预测!F14 -> 583.0724 | E12: =三表预测!G14 -> 653.4367 | F12: =三表预测!H14 -> 781.26077 | G12: =三表预测!I14 -> 944.5133 | H12: =三表预测!J14 -> 1070.501 | I12: =三表预测!K14 -> 1178.9575 | J12: =三表预测!L14 -> 1275.3705 | L12: =季度数据!G10 -> 145.6916 | M12: =季度数据!H10 -> 146.9448 | N12: =季度数据!I10 -> 148.3194 | O12: =季度数据!J10 -> 212.4809 | P12: =季度数据!K10 -> 155.8096 | Q12: =季度数据!L10 -> 184.4559
A13: 期间费用率 | C13: =IFERROR((三表预测!E12+三表预测!E13+三表预测!E14)/三表预测!E6,0) -> 0.1832758 | D13: =IFERROR((三表预测!F12+三表预测!F13+三表预测!F14)/三表预测!F6,0) -> 0.14539797 | E13: =IFERROR((三表预测!G12+三表预测!G13+三表预测!G14)/三表预测!G6,0) -> 0.13629013 | F13: =IFERROR((三表预测!H12+三表预测!H13+三表预测!H14)/三表预测!H6,0) -> 0.10788538 | G13: =IFERROR((三表预测!I12+三表预测!I13+三表预测!I14)/三表预测!I6,0) -> 0.10084219 | H13: =IFERROR((三表预测!J12+三表预测!J13+三表预测!J14)/三表预测!J6,0) -> 0.098670245 | I13: =IFERROR((三表预测!K12+三表预测!K13+三表预测!K14)/三表预测!K6,0) -> 0.098318583 | J13: =IFERROR((三表预测!L12+三表预测!L13+三表预测!L14)/三表预测!L6,0) -> 0.099206129 | L13: =IFERROR((季度数据!G8+季度数据!G9+季度数据!G10)/季度数据!G5,0) -> 0.14230378 | M13: =IFERROR((季度数据!H8+季度数据!H9+季度数据!H10)/季度数据!H5,0) -> 0.11453269 | N13: =IFERROR((季度数据!I8+季度数据!I9+季度数据!I10)/季度数据!I5,0) -> 0.11937728 | O13: =IFERROR((季度数据!J8+季度数据!J9+季度数据!J10)/季度数据!J5,0) -> 0.16801189 | P13: =IFERROR((季度数据!K8+季度数据!K9+季度数据!K10)/季度数据!K5,0) -> 0.11229494 | Q13: =IFERROR((季度数据!L8+季度数据!L9+季度数据!L10)/季度数据!L5,0) -> 0.090570056
A14: 财务费用（负数为净收益） | C14: =三表预测!E15 -> -161.5113 | D14: =三表预测!F15 -> -172.5019 | E14: =三表预测!G15 -> -127.772 | F14: =三表预测!H15 -> -194.51809 | G14: =三表预测!I15 -> -262.79018 | H14: =三表预测!J15 -> -268.93355 | I14: =三表预测!K15 -> -287.43841 | J14: =三表预测!L15 -> -338.85479 | L14: =季度数据!G11 -> -38.1213 | M14: =季度数据!H11 -> -25.072 | N14: =季度数据!I11 -> -38.7991 | O14: =季度数据!J11 -> -25.7796 | P14: =季度数据!K11 -> -28.973 | Q14: =季度数据!L11 -> -12.9393
A15: 其他收益 | C15: =三表预测!E16 -> 348.6995 | D15: =三表预测!F16 -> 305.0967 | E15: =三表预测!G16 -> 390.1677 | F15: =三表预测!H16 -> 286.29204 | G15: =三表预测!I16 -> 317.12502 | H15: =三表预测!J16 -> 260.62087 | I15: =三表预测!K16 -> 263.78783 | J15: =三表预测!L16 -> 264.77556 | L15: =季度数据!G12 -> 87.1963 | M15: =季度数据!H12 -> 90.7529 | N15: =季度数据!I12 -> 87.9912 | O15: =季度数据!J12 -> 124.2274 | P15: =季度数据!K12 -> 85.4097 | Q15: =季度数据!L12 -> 53.7199
A16: 营业利润 | C16: =三表预测!E20 -> 1777.6464 | D16: =三表预测!F20 -> 2522.7052 | E16: =三表预测!G20 -> 3008.4653 | F16: =三表预测!H20 -> 4914.0391 | G16: =三表预测!I20 -> 6545.3364 | H16: =三表预测!J20 -> 7245.2411 | I16: =三表预测!K20 -> 7738.255 | J16: =三表预测!L20 -> 8121.848 | L16: =季度数据!G13 -> 616.3601 | M16: =季度数据!H13 -> 810.5954 | N16: =季度数据!I13 -> 831.3498 | O16: =季度数据!J13 -> 750.1603 | P16: =季度数据!K13 -> 911.3291 | Q16: =季度数据!L13 -> 1315.4431
A17: 营业利润率 | C17: =IFERROR(三表预测!E20/三表预测!E6,0) -> 0.31041437 | D17: =IFERROR(三表预测!F20/三表预测!F6,0) -> 0.34206215 | E17: =IFERROR(三表预测!G20/三表预测!G6,0) -> 0.33400843 | F17: =IFERROR(三表预测!H20/三表预测!H6,0) -> 0.35446676 | G17: =IFERROR(三表预测!I20/三表预测!I6,0) -> 0.37293445 | H17: =IFERROR(三表预测!J20/三表预测!J6,0) -> 0.35947224 | I17: =IFERROR(三表预测!K20/三表预测!K6,0) -> 0.34861783 | J17: =IFERROR(三表预测!L20/三表预测!L6,0) -> 0.34278239 | L17: =IFERROR(季度数据!G13/季度数据!G5,0) -> 0.33623169 | M17: =IFERROR(季度数据!H13/季度数据!H5,0) -> 0.35005029 | N17: =IFERROR(季度数据!I13/季度数据!I5,0) -> 0.35233049 | O17: =IFERROR(季度数据!J13/季度数据!J5,0) -> 0.30021002 | P17: =IFERROR(季度数据!K13/季度数据!K5,0) -> 0.33992217 | Q17: =IFERROR(季度数据!L13/季度数据!L5,0) -> 0.35150298
A18: 利润总额 | C18: =三表预测!E22 -> 1782.8474 | D18: =三表预测!F22 -> 2518.9437 | E18: =三表预测!G22 -> 3008.1761 | F18: =三表预测!H22 -> 4911.2131 | G18: =三表预测!I22 -> 6545.3364 | H18: =三表预测!J22 -> 7245.2411 | I18: =三表预测!K22 -> 7738.255 | J18: =三表预测!L22 -> 8121.848 | L18: =季度数据!G14 -> 618.439 | M18: =季度数据!H14 -> 808.6791 | N18: =季度数据!I14 -> 834.7089 | O18: =季度数据!J14 -> 746.3495 | P18: =季度数据!K14 -> 907.7421 | Q18: =季度数据!L14 -> 1316.2041
A19: 实际税率 | C19: =税务与其他损益!E28 -> 0.11201013 | D19: =税务与其他损益!F28 -> 0.1304952 | E19: =税务与其他损益!G28 -> 0.13004434 | F19: =税务与其他损益!H28 -> 0.13252461 | G19: =税务与其他损益!I28 -> 0.13951906 | H19: =税务与其他损益!J28 -> 0.13905344 | I19: =税务与其他损益!K28 -> 0.13843215 | J19: =税务与其他损益!L28 -> 0.13780101 | L19: =IFERROR(季度数据!G15/季度数据!G14,0) -> 0.13832229 | M19: =IFERROR(季度数据!H15/季度数据!H14,0) -> 0.12921021 | N19: =IFERROR(季度数据!I15/季度数据!I14,0) -> 0.13640073 | O19: =IFERROR(季度数据!J15/季度数据!J14,0) -> 0.11697991 | P19: =IFERROR(季度数据!K15/季度数据!K14,0) -> 0.12882183 | Q19: =IFERROR(季度数据!L15/季度数据!L14,0) -> 0.13296828
A20: 归母净利润 | C20: =三表预测!E26 -> 1580.9858 | D20: =三表预测!F26 -> 2190.4492 | E20: =三表预测!G26 -> 2618.3839 | F20: =三表预测!H26 -> 4260.3565 | G20: =三表预测!I26 -> 5632.1372 | H20: =三表预测!J26 -> 6237.7654 | I20: =三表预测!K26 -> 6667.0317 | J20: =三表预测!L26 -> 7002.6492 | L20: =季度数据!G17 -> 532.6514 | M20: =季度数据!H17 -> 704.4865 | N20: =季度数据!I17 -> 721.3812 | O20: =季度数据!J17 -> 659.8652 | P20: =季度数据!K17 -> 790.8996 | Q20: =季度数据!L17 -> 1141.2187
A21: 同比 | C21: =三表预测!E27 -> 0.050694156 | D21: =三表预测!F27 -> 0.38549581 | E21: =三表预测!G27 -> 0.1953639 | F21: =三表预测!H27 -> 0.62709392 | G21: =三表预测!I27 -> 0.3219873 | H21: =三表预测!J27 -> 0.10753079 | I21: =三表预测!K27 -> 0.068817316 | J21: =三表预测!L27 -> 0.050339864 | L21: =IFERROR(季度数据!G17/季度数据!C17-1,0) -> 0.23020146 | M21: =IFERROR(季度数据!H17/季度数据!D17-1,0) -> 0.18887191 | N21: =IFERROR(季度数据!I17/季度数据!E17-1,0) -> 0.24862278 | O21: =IFERROR(季度数据!J17/季度数据!F17-1,0) -> 0.12382194 | P21: =IFERROR(季度数据!K17/季度数据!G17-1,0) -> 0.4848353 | Q21: =IFERROR(季度数据!L17/季度数据!H17-1,0) -> 0.61992984
A22: 归母净利率 | C22: =三表预测!E28 -> 0.2760733 | D22: =三表预测!F28 -> 0.29701043 | E22: =三表预测!G28 -> 0.29070047 | F22: =三表预测!H28 -> 0.30731436 | G22: =三表预测!I28 -> 0.32090299 | H22: =三表预测!J28 -> 0.30948639 | I22: =三表预测!K28 -> 0.30035792 | J22: =三表预测!L28 -> 0.29554663 | L22: =IFERROR(季度数据!G17/季度数据!G5,0) -> 0.29056761 | M22: =IFERROR(季度数据!H17/季度数据!H5,0) -> 0.30422786 | N22: =IFERROR(季度数据!I17/季度数据!I5,0) -> 0.30572521 | O22: =IFERROR(季度数据!J17/季度数据!J5,0) -> 0.26407442 | P22: =IFERROR(季度数据!K17/季度数据!K5,0) -> 0.29500244 | Q22: =IFERROR(季度数据!L17/季度数据!L5,0) -> 0.30494802
A23: EPS（元，期末流通股本） | C23: =三表预测!E29 -> 0.82493502 | D23: =三表预测!F29 -> 1.142944 | E23: =三表预测!G29 -> 1.3699036 | F23: =三表预测!H29 -> 2.1552782 | G23: =三表预测!I29 -> 2.8492505 | H23: =三表预测!J29 -> 3.1556326 | I23: =三表预测!K29 -> 3.3727948 | J23: =三表预测!L29 -> 3.5425808
A24: EBITDA | C24: =三表预测!E33 -> 2123.0677 | D24: =三表预测!F33 -> 2931.1984 | E24: =三表预测!G33 -> 3500.2428 | F24: =三表预测!H33 -> 5413.0418 | G24: =三表预测!I33 -> 7131.1635 | H24: =三表预测!J33 -> 7969.9608 | I24: =三表预测!K33 -> 8597.0867 | J24: =三表预测!L33 -> 9064.8342
A25: EBITDA利润率 | C25: =三表预测!E34 -> 0.37073218 | D25: =三表预测!F34 -> 0.39745113 | E25: =三表预测!G34 -> 0.38860697 | F25: =三表预测!H34 -> 0.39046156 | G25: =三表预测!I34 -> 0.4063132 | H25: =三表预测!J34 -> 0.39542917 | I25: =三表预测!K34 -> 0.38730925 | J25: =三表预测!L34 -> 0.3825811
A26: 二、业务经营
A27: 电子元件收入 | D27: =收入拆解!F17 -> 2298.159 | E27: =收入拆解!G17 -> 3308.0896 | F27: =收入拆解!H17 -> 5983.6724 | G27: =收入拆解!I17 -> 8077.9578 | H27: =收入拆解!J17 -> 9698.3961 | I27: =收入拆解!K17 -> 10862.204 | J27: =收入拆解!L17 -> 11709.456
A28: 通信器件收入 | D28: =收入拆解!F26 -> 2305.9847 | E28: =收入拆解!G26 -> 2594.3099 | F28: =收入拆解!H26 -> 3955.5443 | G28: =收入拆解!I26 -> 4936.5193 | H28: =收入拆解!J26 -> 5686.8702 | I28: =收入拆解!K26 -> 6256.1259 | J28: =收入拆解!L26 -> 6735.9708
A29: 电子及陶瓷材料收入 | D29: =收入拆解!F41 -> 1677.2328 | E29: =收入拆解!G41 -> 1959.378 | F29: =收入拆解!H41 -> 2525.459 | G29: =收入拆解!I41 -> 3018.5474 | H29: =收入拆解!J41 -> 3136.9255 | I29: =收入拆解!K41 -> 3338.3736 | J29: =收入拆解!L41 -> 3412.4894
A30: 其中SOFC隔膜片（历史为第一大客户代理） | C30: =收入拆解!E38 -> 449.31873 | D30: =收入拆解!F38 -> 323.86965 | E30: =收入拆解!G38 -> 330.718 | F30: =收入拆解!H38 -> 652.5 | G30: =收入拆解!I38 -> 920.83333 | H30: =收入拆解!J38 -> 829.44 | I30: =收入拆解!K38 -> 846.28923 | J30: =收入拆解!L38 -> 770.88
A31: 设备组件收入 | D31: =收入拆解!F43 -> 536.82473 | E31: =收入拆解!G43 -> 601.75341 | F31: =收入拆解!H43 -> 692.01642 | G31: =收入拆解!I43 -> 775.05839 | H31: =收入拆解!J43 -> 852.56423 | I31: =收入拆解!K43 -> 920.76937 | J31: =收入拆解!L43 -> 976.01553
A32: 其他主营及其他业务收入 | D32: =收入拆解!F44+收入拆解!F45 -> 556.78962 | E32: =收入拆解!G44+收入拆解!G45 -> 543.62299 | F32: =收入拆解!H44+收入拆解!H45 -> 706.49528 | G32: =收入拆解!I44+收入拆解!I45 -> 742.82005 | H32: =收入拆解!J44+收入拆解!J45 -> 780.46105 | I32: =收入拆解!K44+收入拆解!K45 -> 819.4841 | J32: =收入拆解!L44+收入拆解!L45 -> 859.95831
A33: 电子、通信元件及材料（半年报口径） | D33: =收入拆解!F17+收入拆解!F26+收入拆解!F41+收入拆解!F43 -> 6818.2012 | E33: =收入拆解!G17+收入拆解!G26+收入拆解!G41+收入拆解!G43 -> 8463.5309 | F33: =收入拆解!H17+收入拆解!H26+收入拆解!H41+收入拆解!H43 -> 13156.692 | G33: =收入拆解!I17+收入拆解!I26+收入拆解!I41+收入拆解!I43 -> 16808.083 | H33: =收入拆解!J17+收入拆解!J26+收入拆解!J41+收入拆解!J43 -> 19374.756 | I33: =收入拆解!K17+收入拆解!K26+收入拆解!K41+收入拆解!K43 -> 21377.473 | J33: =收入拆解!L17+收入拆解!L26+收入拆解!L41+收入拆解!L43 -> 22833.931
A34: 销售量（亿只/片，公司口径） | C34: =收入拆解!E6 -> 2872.5609 | D34: =收入拆解!F6 -> 3816.1069 | E34: =收入拆解!G6 -> 5329.9092
A35: 员工人数（期末） | C35: =人员与费用!E11 -> 13501 | D35: =人员与费用!F11 -> 15515 | E35: =人员与费用!G11 -> 17352 | F35: =人员与费用!H11 -> 19628.91 | G35: =人员与费用!I11 -> 21417.099 | H35: =人员与费用!J11 -> 22809.931 | I35: =人员与费用!K11 -> 23893.979 | J35: =人员与费用!L11 -> 24832.667
A36: 人均薪酬（万元） | D36: =人员与费用!F22 -> 12.928528 | E36: =人员与费用!G22 -> 12.79326 | F36: =人员与费用!H22 -> 13.432923 | G36: =人员与费用!I22 -> 14.104569 | H36: =人员与费用!J22 -> 14.739274 | I36: =人员与费用!K22 -> 15.328845 | J36: =人员与费用!L22 -> 15.941999
A37: 资本开支 | C37: =资本开支与折旧!E11 -> 545.8847 | D37: =资本开支与折旧!F11 -> 639.0352 | E37: =资本开支与折旧!G11 -> 580.092 | F37: =资本开支与折旧!H11 -> 1787.9753 | G37: =资本开支与折旧!I11 -> 2593.5925 | H37: =资本开支与折旧!J11 -> 2358.5137 | I37: =资本开支与折旧!K11 -> 1918.9354 | J37: =资本开支与折旧!L11 -> 1679.4592 | L37: =季度数据!G19 -> 98.8266 | M37: =季度数据!H19 -> 108.3401 | N37: =季度数据!I19 -> 166.7533 | O37: =季度数据!J19 -> 206.172 | P37: =季度数据!K19 -> 188.4361 | Q37: =季度数据!L19 -> 287.9349
A38: 折旧与摊销 | C38: =资本开支与折旧!E91 -> 609.43241 | D38: =资本开支与折旧!F91 -> 651.2802 | E38: =资本开支与折旧!G91 -> 740.43309 | F38: =资本开支与折旧!H91 -> 813.65692 | G38: =资本开支与折旧!I91 -> 914.99495 | H38: =资本开支与折旧!J91 -> 1060.0309 | I38: =资本开支与折旧!K91 -> 1212.6478 | J38: =资本开支与折旧!L91 -> 1348.2187
A39: 应收周转天数（票据+账款+融资） | C39: =营运资金!E33 -> 143.99838 | D39: =营运资金!F33 -> 132.95096 | E39: =营运资金!G33 -> 132.10293 | F39: =营运资金!H33 -> 128 | G39: =营运资金!I33 -> 128 | H39: =营运资金!J33 -> 128 | I39: =营运资金!K33 -> 128 | J39: =营运资金!L33 -> 128
A40: 存货周转天数 | C40: =营运资金!E34 -> 185.76626 | D40: =营运资金!F34 -> 189.29501 | E40: =营运资金!G34 -> 167.50165 | F40: =营运资金!H34 -> 156.10015 | G40: =营运资金!I34 -> 157.07956 | H40: =营运资金!J34 -> 157.38008 | I40: =营运资金!K34 -> 157.47553 | J40: =营运资金!L34 -> 157.33805
...

Sheet Summary_EN
A1: Sanhuan Group (CCTC, 300408.SZ / 06951.HK) - Financial model summary
A2: RMB mn unless stated | Annual: 2023A-2025A reported, 2026E-2030E model (scenario per 假设!C5) | Quarterly: single-quarter reported | All cells are live links
C3: Annual | L3: Quarterly (single quarter)
A4: Item | C4: 2023A | D4: 2024A | E4: 2025A | F4: 2026E | G4: 2027E | H4: 2028E | I4: 2029E | J4: 2030E | L4: 2025Q1 | M4: 2025Q2 | N4: 2025Q3 | O4: 2025Q4 | P4: 2026Q1 | Q4: 2026Q2
A5: I. Income statement
A6: Revenue | C6: =三表预测!E6 -> 5726.6885 | D6: =三表预测!F6 -> 7374.9908 | E6: =三表预测!G6 -> 9007.1539 | F6: =三表预测!H6 -> 13863.187 | G6: =三表预测!I6 -> 17550.903 | H6: =三表预测!J6 -> 20155.217 | I6: =三表预测!K6 -> 22196.957 | J6: =三表预测!L6 -> 23693.89 | L6: =季度数据!G5 -> 1833.141 | M6: =季度数据!H5 -> 2315.6541 | N6: =季度数据!I5 -> 2359.5738 | O6: =季度数据!J5 -> 2498.785 | P6: =季度数据!K5 -> 2680.9934 | Q6: =季度数据!L5 -> 3742.3384
A7: YoY | C7: =三表预测!E7 -> 0.11211074 | D7: =三表预测!F7 -> 0.28782818 | E7: =三表预测!G7 -> 0.22131053 | F7: =三表预测!H7 -> 0.53913074 | G7: =三表预测!I7 -> 0.26600776 | H7: =三表预测!J7 -> 0.14838634 | I7: =三表预测!K7 -> 0.10130079 | J7: =三表预测!L7 -> 0.067438657 | L7: =IFERROR(季度数据!G5/季度数据!C5-1,0) -> 0.17237341 | M7: =IFERROR(季度数据!H5/季度数据!D5-1,0) -> 0.24244341 | N7: =IFERROR(季度数据!I5/季度数据!E5-1,0) -> 0.20794779 | O7: =IFERROR(季度数据!J5/季度数据!F5-1,0) -> 0.2530193 | P7: =IFERROR(季度数据!K5/季度数据!G5-1,0) -> 0.46251347 | Q7: =IFERROR(季度数据!L5/季度数据!H5-1,0) -> 0.61610424
A8: Gross profit | C8: =三表预测!E9 -> 2281.1586 | D8: =三表预测!F9 -> 3170.1271 | E8: =三表预测!G9 -> 3795.3922 | F8: =三表预测!H9 -> 6228.5523 | G8: =三表预测!I9 -> 7935.5016 | H8: =三表预测!J9 -> 8943.7107 | I8: =三表预测!K9 -> 9639.8248 | J8: =三表预测!L9 -> 10161.882 | L8: =季度数据!G5-季度数据!G6 -> 751.8142 | M8: =季度数据!H5-季度数据!H6 -> 989.6012 | N8: =季度数据!I5-季度数据!I6 -> 1023.8903 | O8: =季度数据!J5-季度数据!J6 -> 1030.0866 | P8: =季度数据!K5-季度数据!K6 -> 1165.9354 | Q8: =季度数据!L5-季度数据!L6 -> 1680.8635
A9: Gross margin | C9: =三表预测!E10 -> 0.39833817 | D9: =三表预测!F10 -> 0.42984828 | E9: =三表预测!G10 -> 0.4213753 | F9: =三表预测!H10 -> 0.44928717 | G9: =三表预测!I10 -> 0.45214207 | H9: =三表预测!J10 -> 0.44374172 | I9: =三表预测!K10 -> 0.43428588 | J9: =三表预测!L10 -> 0.42888197 | L9: =IFERROR(1-季度数据!G6/季度数据!G5,0) -> 0.4101235 | M9: =IFERROR(1-季度数据!H6/季度数据!H5,0) -> 0.42735277 | N9: =IFERROR(1-季度数据!I6/季度数据!I5,0) -> 0.43393019 | O9: =IFERROR(1-季度数据!J6/季度数据!J5,0) -> 0.41223499 | P9: =IFERROR(1-季度数据!K6/季度数据!K5,0) -> 0.43488932 | Q9: =IFERROR(1-季度数据!L6/季度数据!L5,0) -> 0.44914792
A10: Selling expenses | C10: =三表预测!E12 -> 74.3431 | D10: =三表预测!F12 -> 79.3918 | E10: =三表预测!G12 -> 93.1993 | F10: =三表预测!H12 -> 105.04434 | G10: =三表预测!I12 -> 124.93085 | H10: =三表预测!J12 -> 141.37808 | I10: =三表预测!K12 -> 155.37852 | J10: =三表预测!L12 -> 167.88891 | L10: =季度数据!G8 -> 21.2322 | M10: =季度数据!H8 -> 20.7534 | N10: =季度数据!I8 -> 24.9725 | O10: =季度数据!J8 -> 26.2412 | P10: =季度数据!K8 -> 22.2371 | Q10: =季度数据!L8 -> 22.5728
A11: G&A expenses | C11: =三表预测!E13 -> 429.4141 | D11: =三表预测!F13 -> 409.8445 | E11: =三表预测!G13 -> 480.9502 | F11: =三表预测!H13 -> 609.33009 | G11: =三表预测!I13 -> 700.42727 | H11: =三表预测!J13 -> 776.84113 | I11: =三表预测!K13 -> 848.03725 | J11: =三表预测!L13 -> 907.31969 | L11: =季度数据!G9 -> 93.9391 | M11: =季度数据!H9 -> 97.5199 | N11: =季度数据!I9 -> 108.3876 | O11: =季度数据!J9 -> 181.1035 | P11: =季度数据!K9 -> 123.0153 | Q11: =季度数据!L9 -> 131.9151
A12: R&D expenses | C12: =三表预测!E14 -> 545.8062 | D12: =三表预测!F14 -> 583.0724 | E12: =三表预测!G14 -> 653.4367 | F12: =三表预测!H14 -> 781.26077 | G12: =三表预测!I14 -> 944.5133 | H12: =三表预测!J14 -> 1070.501 | I12: =三表预测!K14 -> 1178.9575 | J12: =三表预测!L14 -> 1275.3705 | L12: =季度数据!G10 -> 145.6916 | M12: =季度数据!H10 -> 146.9448 | N12: =季度数据!I10 -> 148.3194 | O12: =季度数据!J10 -> 212.4809 | P12: =季度数据!K10 -> 155.8096 | Q12: =季度数据!L10 -> 184.4559
A13: Opex / revenue | C13: =IFERROR((三表预测!E12+三表预测!E13+三表预测!E14)/三表预测!E6,0) -> 0.1832758 | D13: =IFERROR((三表预测!F12+三表预测!F13+三表预测!F14)/三表预测!F6,0) -> 0.14539797 | E13: =IFERROR((三表预测!G12+三表预测!G13+三表预测!G14)/三表预测!G6,0) -> 0.13629013 | F13: =IFERROR((三表预测!H12+三表预测!H13+三表预测!H14)/三表预测!H6,0) -> 0.10788538 | G13: =IFERROR((三表预测!I12+三表预测!I13+三表预测!I14)/三表预测!I6,0) -> 0.10084219 | H13: =IFERROR((三表预测!J12+三表预测!J13+三表预测!J14)/三表预测!J6,0) -> 0.098670245 | I13: =IFERROR((三表预测!K12+三表预测!K13+三表预测!K14)/三表预测!K6,0) -> 0.098318583 | J13: =IFERROR((三表预测!L12+三表预测!L13+三表预测!L14)/三表预测!L6,0) -> 0.099206129 | L13: =IFERROR((季度数据!G8+季度数据!G9+季度数据!G10)/季度数据!G5,0) -> 0.14230378 | M13: =IFERROR((季度数据!H8+季度数据!H9+季度数据!H10)/季度数据!H5,0) -> 0.11453269 | N13: =IFERROR((季度数据!I8+季度数据!I9+季度数据!I10)/季度数据!I5,0) -> 0.11937728 | O13: =IFERROR((季度数据!J8+季度数据!J9+季度数据!J10)/季度数据!J5,0) -> 0.16801189 | P13: =IFERROR((季度数据!K8+季度数据!K9+季度数据!K10)/季度数据!K5,0) -> 0.11229494 | Q13: =IFERROR((季度数据!L8+季度数据!L9+季度数据!L10)/季度数据!L5,0) -> 0.090570056
A14: Net finance cost (negative = income) | C14: =三表预测!E15 -> -161.5113 | D14: =三表预测!F15 -> -172.5019 | E14: =三表预测!G15 -> -127.772 | F14: =三表预测!H15 -> -194.51809 | G14: =三表预测!I15 -> -262.79018 | H14: =三表预测!J15 -> -268.93355 | I14: =三表预测!K15 -> -287.43841 | J14: =三表预测!L15 -> -338.85479 | L14: =季度数据!G11 -> -38.1213 | M14: =季度数据!H11 -> -25.072 | N14: =季度数据!I11 -> -38.7991 | O14: =季度数据!J11 -> -25.7796 | P14: =季度数据!K11 -> -28.973 | Q14: =季度数据!L11 -> -12.9393
A15: Other income | C15: =三表预测!E16 -> 348.6995 | D15: =三表预测!F16 -> 305.0967 | E15: =三表预测!G16 -> 390.1677 | F15: =三表预测!H16 -> 286.29204 | G15: =三表预测!I16 -> 317.12502 | H15: =三表预测!J16 -> 260.62087 | I15: =三表预测!K16 -> 263.78783 | J15: =三表预测!L16 -> 264.77556 | L15: =季度数据!G12 -> 87.1963 | M15: =季度数据!H12 -> 90.7529 | N15: =季度数据!I12 -> 87.9912 | O15: =季度数据!J12 -> 124.2274 | P15: =季度数据!K12 -> 85.4097 | Q15: =季度数据!L12 -> 53.7199
A16: Operating profit | C16: =三表预测!E20 -> 1777.6464 | D16: =三表预测!F20 -> 2522.7052 | E16: =三表预测!G20 -> 3008.4653 | F16: =三表预测!H20 -> 4914.0391 | G16: =三表预测!I20 -> 6545.3364 | H16: =三表预测!J20 -> 7245.2411 | I16: =三表预测!K20 -> 7738.255 | J16: =三表预测!L20 -> 8121.848 | L16: =季度数据!G13 -> 616.3601 | M16: =季度数据!H13 -> 810.5954 | N16: =季度数据!I13 -> 831.3498 | O16: =季度数据!J13 -> 750.1603 | P16: =季度数据!K13 -> 911.3291 | Q16: =季度数据!L13 -> 1315.4431
A17: Operating margin | C17: =IFERROR(三表预测!E20/三表预测!E6,0) -> 0.31041437 | D17: =IFERROR(三表预测!F20/三表预测!F6,0) -> 0.34206215 | E17: =IFERROR(三表预测!G20/三表预测!G6,0) -> 0.33400843 | F17: =IFERROR(三表预测!H20/三表预测!H6,0) -> 0.35446676 | G17: =IFERROR(三表预测!I20/三表预测!I6,0) -> 0.37293445 | H17: =IFERROR(三表预测!J20/三表预测!J6,0) -> 0.35947224 | I17: =IFERROR(三表预测!K20/三表预测!K6,0) -> 0.34861783 | J17: =IFERROR(三表预测!L20/三表预测!L6,0) -> 0.34278239 | L17: =IFERROR(季度数据!G13/季度数据!G5,0) -> 0.33623169 | M17: =IFERROR(季度数据!H13/季度数据!H5,0) -> 0.35005029 | N17: =IFERROR(季度数据!I13/季度数据!I5,0) -> 0.35233049 | O17: =IFERROR(季度数据!J13/季度数据!J5,0) -> 0.30021002 | P17: =IFERROR(季度数据!K13/季度数据!K5,0) -> 0.33992217 | Q17: =IFERROR(季度数据!L13/季度数据!L5,0) -> 0.35150298
A18: Profit before tax | C18: =三表预测!E22 -> 1782.8474 | D18: =三表预测!F22 -> 2518.9437 | E18: =三表预测!G22 -> 3008.1761 | F18: =三表预测!H22 -> 4911.2131 | G18: =三表预测!I22 -> 6545.3364 | H18: =三表预测!J22 -> 7245.2411 | I18: =三表预测!K22 -> 7738.255 | J18: =三表预测!L22 -> 8121.848 | L18: =季度数据!G14 -> 618.439 | M18: =季度数据!H14 -> 808.6791 | N18: =季度数据!I14 -> 834.7089 | O18: =季度数据!J14 -> 746.3495 | P18: =季度数据!K14 -> 907.7421 | Q18: =季度数据!L14 -> 1316.2041
A19: Effective tax rate | C19: =税务与其他损益!E28 -> 0.11201013 | D19: =税务与其他损益!F28 -> 0.1304952 | E19: =税务与其他损益!G28 -> 0.13004434 | F19: =税务与其他损益!H28 -> 0.13252461 | G19: =税务与其他损益!I28 -> 0.13951906 | H19: =税务与其他损益!J28 -> 0.13905344 | I19: =税务与其他损益!K28 -> 0.13843215 | J19: =税务与其他损益!L28 -> 0.13780101 | L19: =IFERROR(季度数据!G15/季度数据!G14,0) -> 0.13832229 | M19: =IFERROR(季度数据!H15/季度数据!H14,0) -> 0.12921021 | N19: =IFERROR(季度数据!I15/季度数据!I14,0) -> 0.13640073 | O19: =IFERROR(季度数据!J15/季度数据!J14,0) -> 0.11697991 | P19: =IFERROR(季度数据!K15/季度数据!K14,0) -> 0.12882183 | Q19: =IFERROR(季度数据!L15/季度数据!L14,0) -> 0.13296828
A20: Net profit attributable | C20: =三表预测!E26 -> 1580.9858 | D20: =三表预测!F26 -> 2190.4492 | E20: =三表预测!G26 -> 2618.3839 | F20: =三表预测!H26 -> 4260.3565 | G20: =三表预测!I26 -> 5632.1372 | H20: =三表预测!J26 -> 6237.7654 | I20: =三表预测!K26 -> 6667.0317 | J20: =三表预测!L26 -> 7002.6492 | L20: =季度数据!G17 -> 532.6514 | M20: =季度数据!H17 -> 704.4865 | N20: =季度数据!I17 -> 721.3812 | O20: =季度数据!J17 -> 659.8652 | P20: =季度数据!K17 -> 790.8996 | Q20: =季度数据!L17 -> 1141.2187
A21: YoY | C21: =三表预测!E27 -> 0.050694156 | D21: =三表预测!F27 -> 0.38549581 | E21: =三表预测!G27 -> 0.1953639 | F21: =三表预测!H27 -> 0.62709392 | G21: =三表预测!I27 -> 0.3219873 | H21: =三表预测!J27 -> 0.10753079 | I21: =三表预测!K27 -> 0.068817316 | J21: =三表预测!L27 -> 0.050339864 | L21: =IFERROR(季度数据!G17/季度数据!C17-1,0) -> 0.23020146 | M21: =IFERROR(季度数据!H17/季度数据!D17-1,0) -> 0.18887191 | N21: =IFERROR(季度数据!I17/季度数据!E17-1,0) -> 0.24862278 | O21: =IFERROR(季度数据!J17/季度数据!F17-1,0) -> 0.12382194 | P21: =IFERROR(季度数据!K17/季度数据!G17-1,0) -> 0.4848353 | Q21: =IFERROR(季度数据!L17/季度数据!H17-1,0) -> 0.61992984
A22: Net margin | C22: =三表预测!E28 -> 0.2760733 | D22: =三表预测!F28 -> 0.29701043 | E22: =三表预测!G28 -> 0.29070047 | F22: =三表预测!H28 -> 0.30731436 | G22: =三表预测!I28 -> 0.32090299 | H22: =三表预测!J28 -> 0.30948639 | I22: =三表预测!K28 -> 0.30035792 | J22: =三表预测!L28 -> 0.29554663 | L22: =IFERROR(季度数据!G17/季度数据!G5,0) -> 0.29056761 | M22: =IFERROR(季度数据!H17/季度数据!H5,0) -> 0.30422786 | N22: =IFERROR(季度数据!I17/季度数据!I5,0) -> 0.30572521 | O22: =IFERROR(季度数据!J17/季度数据!J5,0) -> 0.26407442 | P22: =IFERROR(季度数据!K17/季度数据!K5,0) -> 0.29500244 | Q22: =IFERROR(季度数据!L17/季度数据!L5,0) -> 0.30494802
A23: EPS (RMB, period-end shares) | C23: =三表预测!E29 -> 0.82493502 | D23: =三表预测!F29 -> 1.142944 | E23: =三表预测!G29 -> 1.3699036 | F23: =三表预测!H29 -> 2.1552782 | G23: =三表预测!I29 -> 2.8492505 | H23: =三表预测!J29 -> 3.1556326 | I23: =三表预测!K29 -> 3.3727948 | J23: =三表预测!L29 -> 3.5425808
A24: EBITDA | C24: =三表预测!E33 -> 2123.0677 | D24: =三表预测!F33 -> 2931.1984 | E24: =三表预测!G33 -> 3500.2428 | F24: =三表预测!H33 -> 5413.0418 | G24: =三表预测!I33 -> 7131.1635 | H24: =三表预测!J33 -> 7969.9608 | I24: =三表预测!K33 -> 8597.0867 | J24: =三表预测!L33 -> 9064.8342
A25: EBITDA margin | C25: =三表预测!E34 -> 0.37073218 | D25: =三表预测!F34 -> 0.39745113 | E25: =三表预测!G34 -> 0.38860697 | F25: =三表预测!H34 -> 0.39046156 | G25: =三表预测!I34 -> 0.4063132 | H25: =三表预测!J34 -> 0.39542917 | I25: =三表预测!K34 -> 0.38730925 | J25: =三表预测!L34 -> 0.3825811
A26: II. Operations
A27: Electronic components revenue | D27: =收入拆解!F17 -> 2298.159 | E27: =收入拆解!G17 -> 3308.0896 | F27: =收入拆解!H17 -> 5983.6724 | G27: =收入拆解!I17 -> 8077.9578 | H27: =收入拆解!J17 -> 9698.3961 | I27: =收入拆解!K17 -> 10862.204 | J27: =收入拆解!L17 -> 11709.456
A28: Communication components revenue | D28: =收入拆解!F26 -> 2305.9847 | E28: =收入拆解!G26 -> 2594.3099 | F28: =收入拆解!H26 -> 3955.5443 | G28: =收入拆解!I26 -> 4936.5193 | H28: =收入拆解!J26 -> 5686.8702 | I28: =收入拆解!K26 -> 6256.1259 | J28: =收入拆解!L26 -> 6735.9708
A29: Electronic & ceramic materials revenue | D29: =收入拆解!F41 -> 1677.2328 | E29: =收入拆解!G41 -> 1959.378 | F29: =收入拆解!H41 -> 2525.459 | G29: =收入拆解!I41 -> 3018.5474 | H29: =收入拆解!J41 -> 3136.9255 | I29: =收入拆解!K41 -> 3338.3736 | J29: =收入拆解!L41 -> 3412.4894
A30: of which SOFC separators (hist.: top-customer proxy) | C30: =收入拆解!E38 -> 449.31873 | D30: =收入拆解!F38 -> 323.86965 | E30: =收入拆解!G38 -> 330.718 | F30: =收入拆解!H38 -> 652.5 | G30: =收入拆解!I38 -> 920.83333 | H30: =收入拆解!J38 -> 829.44 | I30: =收入拆解!K38 -> 846.28923 | J30: =收入拆解!L38 -> 770.88
A31: Equipment components revenue | D31: =收入拆解!F43 -> 536.82473 | E31: =收入拆解!G43 -> 601.75341 | F31: =收入拆解!H43 -> 692.01642 | G31: =收入拆解!I43 -> 775.05839 | H31: =收入拆解!J43 -> 852.56423 | I31: =收入拆解!K43 -> 920.76937 | J31: =收入拆解!L43 -> 976.01553
A32: Other revenue | D32: =收入拆解!F44+收入拆解!F45 -> 556.78962 | E32: =收入拆解!G44+收入拆解!G45 -> 543.62299 | F32: =收入拆解!H44+收入拆解!H45 -> 706.49528 | G32: =收入拆解!I44+收入拆解!I45 -> 742.82005 | H32: =收入拆解!J44+收入拆解!J45 -> 780.46105 | I32: =收入拆解!K44+收入拆解!K45 -> 819.4841 | J32: =收入拆解!L44+收入拆解!L45 -> 859.95831
A33: Core components & materials (interim basis) | D33: =收入拆解!F17+收入拆解!F26+收入拆解!F41+收入拆解!F43 -> 6818.2012 | E33: =收入拆解!G17+收入拆解!G26+收入拆解!G41+收入拆解!G43 -> 8463.5309 | F33: =收入拆解!H17+收入拆解!H26+收入拆解!H41+收入拆解!H43 -> 13156.692 | G33: =收入拆解!I17+收入拆解!I26+收入拆解!I41+收入拆解!I43 -> 16808.083 | H33: =收入拆解!J17+收入拆解!J26+收入拆解!J41+收入拆解!J43 -> 19374.756 | I33: =收入拆解!K17+收入拆解!K26+收入拆解!K41+收入拆解!K43 -> 21377.473 | J33: =收入拆解!L17+收入拆解!L26+收入拆解!L41+收入拆解!L43 -> 22833.931
A34: Sales volume (100 mn units, company basis) | C34: =收入拆解!E6 -> 2872.5609 | D34: =收入拆解!F6 -> 3816.1069 | E34: =收入拆解!G6 -> 5329.9092
A35: Headcount (period-end) | C35: =人员与费用!E11 -> 13501 | D35: =人员与费用!F11 -> 15515 | E35: =人员与费用!G11 -> 17352 | F35: =人员与费用!H11 -> 19628.91 | G35: =人员与费用!I11 -> 21417.099 | H35: =人员与费用!J11 -> 22809.931 | I35: =人员与费用!K11 -> 23893.979 | J35: =人员与费用!L11 -> 24832.667
A36: Pay per employee (RMB 10k) | D36: =人员与费用!F22 -> 12.928528 | E36: =人员与费用!G22 -> 12.79326 | F36: =人员与费用!H22 -> 13.432923 | G36: =人员与费用!I22 -> 14.104569 | H36: =人员与费用!J22 -> 14.739274 | I36: =人员与费用!K22 -> 15.328845 | J36: =人员与费用!L22 -> 15.941999
A37: Capex | C37: =资本开支与折旧!E11 -> 545.8847 | D37: =资本开支与折旧!F11 -> 639.0352 | E37: =资本开支与折旧!G11 -> 580.092 | F37: =资本开支与折旧!H11 -> 1787.9753 | G37: =资本开支与折旧!I11 -> 2593.5925 | H37: =资本开支与折旧!J11 -> 2358.5137 | I37: =资本开支与折旧!K11 -> 1918.9354 | J37: =资本开支与折旧!L11 -> 1679.4592 | L37: =季度数据!G19 -> 98.8266 | M37: =季度数据!H19 -> 108.3401 | N37: =季度数据!I19 -> 166.7533 | O37: =季度数据!J19 -> 206.172 | P37: =季度数据!K19 -> 188.4361 | Q37: =季度数据!L19 -> 287.9349
A38: D&A | C38: =资本开支与折旧!E91 -> 609.43241 | D38: =资本开支与折旧!F91 -> 651.2802 | E38: =资本开支与折旧!G91 -> 740.43309 | F38: =资本开支与折旧!H91 -> 813.65692 | G38: =资本开支与折旧!I91 -> 914.99495 | H38: =资本开支与折旧!J91 -> 1060.0309 | I38: =资本开支与折旧!K91 -> 1212.6478 | J38: =资本开支与折旧!L91 -> 1348.2187
A39: Receivable days | C39: =营运资金!E33 -> 143.99838 | D39: =营运资金!F33 -> 132.95096 | E39: =营运资金!G33 -> 132.10293 | F39: =营运资金!H33 -> 128 | G39: =营运资金!I33 -> 128 | H39: =营运资金!J33 -> 128 | I39: =营运资金!K33 -> 128 | J39: =营运资金!L33 -> 128
A40: Inventory days | C40: =营运资金!E34 -> 185.76626 | D40: =营运资金!F34 -> 189.29501 | E40: =营运资金!G34 -> 167.50165 | F40: =营运资金!H34 -> 156.10015 | G40: =营运资金!I34 -> 157.07956 | H40: =营运资金!J34 -> 157.38008 | I40: =营运资金!K34 -> 157.47553 | J40: =营运资金!L34 -> 157.33805
...

Sheet 假设
A1: 核心假设（蓝字可改；黄底为关键假设；情景切换在C5）
A2: 单位：百万元人民币，另注明除外。逐年假设列与各明细表对齐（C:G=2021A-2025A历史参照，H:L=2026E-2030E）。“采用值”行=情景值+敏感性冲击，模型只引用采用值。
A4: 一、情景、市场与股本参数
A5: 情景选择（1=基准，2=乐观，3=悲观） | C5: 1 | D5: 修改此格切换全模型情景
A6: A股股价（元/股） | C6: 118.5 | D6: Wind一致预期表2026-09-30：2026E PE 56.42×EPS 2.10倒算；请按最新行情更新
A7: H股发行价（港元/股） | C7: 100.3 | D7: H股配售结果：发行价100.30港元（2026-07-09上市）
A8: 港元兑人民币（HKD/CNY） | C8: 0.8686 | D8: 2026年半年报外币折算汇率（2026-06-30）0.86855；H股于2026-07-09上市，请按实际结汇汇率更新
A9: H股发行股数（股，含部分行使超额配股权） | C9: 80221200 | D9: 2026年半年报：首次发行71,364,300股+超额配股8,856,900股=80,221,200股
A10: H股发行费用率 | C10: 0.025 | D10: 假设值（上市费用、承销佣金）；2025年及2026H1已付上市费用合计约18.2百万元
A11: H股2026年加权在外天数 | C11: 172 | D11: 71,364,300股自2026-07-09（175天）、8,856,900股自2026-08-05（148天）加权
A12: H股募资投向境外新建扩建项目比例 | C12: 0.412 | D12: H股招股章程：约41.2%投向泰国、德国新建扩建（燃料电池扩建、高精度压电微点胶、数据中心电子元件、通信器件）
A13: 2026年第一期回购股数（股） | C13: 8547300 | D13: 2026年半年报：董事会2026-07-20批准，截至2026-07-30实施完毕
A14: 2026年第一期回购金额 | C14: 894.66 | D14: 2026年半年报：成交总金额894,661,561.03元（不含交易费用）
A15: 2026年第二期回购金额（下限5亿、上限10亿，取中值） | C15: 750 | D15: 董事会2026-07-30批准，进行中；中值为假设
A16: 2026年第一期回购完成后至年末月数（加权股本用） | C16: 5 | D16: 2026-07-30完成，至12-31约5个月
... A20: 少数股东损益占净利润比例 | C20: 0 | D20: 历史接近0（2025年-1.4百万元）
A22: 二、估值参数
A23: 无风险利率 | C23: 0.019 | D23: 假设：中国10年期国债收益率约1.8%-1.9%
A24: Beta | C24: 1.1 | D24: 假设值
A25: 股权风险溢价 | C25: 0.065 | D25: 假设值
A26: 税前债务成本 | C26: 0.035 | D26: 2025年利息费用20.4/平均有息负债约507（约4.0%），取3.5%
A27: 目标债务占比 D/(D+E) | C27: 0.02 | D27: 公司净现金，取2%
A28: 永续增长率 | C28: 0.03 | D28: 假设值
A29: 第二阶段起点增速溢价（相对2030E收入增速） | C29: 0 | D29: 第二阶段（2031E-2035E）起点增速=MAX(永续增速, 2030E收入增速)+本溢价，线性递减至终点；FCFF=NOPAT×(1-增速÷RONIC)。默认0，即假设2030年后不再提速
A30: 第二阶段增速终点（2035E） | C30: 0.04 | D30: 不高于起点、不低于永续增速
A31: 新增投资资本回报率（RONIC，第二阶段与永续期） | C31: 0.25 | D31: 再投资率=增速÷RONIC（价值驱动公式）；2025A ROIC约25.9%（含H股前口径），2026E-2030E约37%-40%
A32: 相对估值：PE下限 | C32: 30 | D32: 可调
A33: 相对估值：PE上限 | C33: 55 | D33: 可调
A35: 三、税务与费用分摊参数
A36: 法定适用税率（高新技术企业） | C36: 0.15 | D36: 母公司及深圳、南充、德阳、苏州子公司为高新技术企业，成都、红河适用西部大开发，均为15%；母公司与南充的高新证书2025-12-31到期，2026H1暂按15%预缴，待复审（风险点）
A37: 研发费用加计扣除比例 | C37: 1 | D37: 财税〔2023〕7号：自2023年起按100%加计扣除
A38: 折旧摊销计入营业成本比例 | C38: 0.842 | D38: 2025A：折旧摊销740.4中，研发37.3（5.0%）、管理79.8（10.8%）、销售未单列；其余计入生产成本（倒挤）
A39: 折旧摊销计入研发费用比例 | C39: 0.05 | D39: 2025A研发费用折旧摊销37.3/740.4
A40: 折旧摊销计入销售费用比例 | C40: 0 | D40: 销售费用附注未单列折旧摊销
A42: 四、敏感性冲击（默认0；情景值之上叠加，用于龙卷风图与二维敏感性）
A43: 电子元件销量增速冲击（pp，逐年叠加） | C43: 0 | D43: 敏感性分析用；正常使用保持0
A44: 电子元件单价变动冲击（pp，逐年叠加） | C44: 0 | D44: 敏感性分析用；正常使用保持0
A45: 通信器件销量增速冲击（pp） | C45: 0 | D45: 敏感性分析用；正常使用保持0
A46: 通信器件单价变动冲击（pp） | C46: 0 | D46: 敏感性分析用；正常使用保持0
A47: 其他电子及陶瓷材料增速冲击（pp） | C47: 0 | D47: 敏感性分析用；正常使用保持0
...

Sheet 收入拆解
A1: 收入拆解：量价、分部与SOFC隔膜片子模型
A2: 分部口径：2024A-2025A为2025年年报新四分部口径（与H股招股章程一致）；量价拆分为假设驱动（公司未按分部披露销量）。
A4: 项目（百万元，另注明除外） | B4: 单位 | C4: 2021A | D4: 2022A | E4: 2023A | F4: 2024A | G4: 2025A | H4: 2026E | I4: 2027E | J4: 2028E | K4: 2029E | L4: 2030E | M4: 来源/说明
A5: A. 公司口径量价（年报“产销量”，万只/万片÷1万=亿只/片）
A6: 销售量 | B6: 亿只/片 | D6: 1593.2022 | E6: 2872.5609 | F6: 3816.1069 | G6: 5329.9092 | M6: 年报“产销量情况分析”（单位万只/万片）
A7: 生产量 | B7: 亿只/片 | D7: 1848.4198 | E7: 2827.2912 | F7: 4078.6015 | G7: 5623.279
A8: 库存量 | B8: 亿只/片 | D8: 808.39338 | E8: 763.12371 | F8: 1025.6183 | G8: 1318.988
A9: 综合单价（营业收入÷销售量） | B9: 元/千只 | D9: =IFERROR(三表预测!D6*10/D6,0) -> 32.320988 | E9: =IFERROR(三表预测!E6*10/E6,0) -> 19.93583 | F9: =IFERROR(三表预测!F6*10/F6,0) -> 19.325954 | G9: =IFERROR(三表预测!G6*10/G6,0) -> 16.899263 | M9: 综合单价受产品结构影响大（MLCC小尺寸占量大、单价低），仅作趋势参考
A10: 销售量同比 | B10: % | E10: =IFERROR(E6/D6-1,0) -> 0.8030109 | F10: =IFERROR(F6/E6-1,0) -> 0.32846859 | G10: =IFERROR(G6/F6-1,0) -> 0.39668761
A11: 综合单价同比 | B11: % | E11: =IFERROR(E9/D9-1,0) -> -0.38319244 | F11: =IFERROR(F9/E9-1,0) -> -0.030591925 | G11: =IFERROR(G9/F9-1,0) -> -0.12556644
A12: 电子元件（MLCC、陶瓷封装基座、电阻等）
A13: 销量增速（假设） | B13: % | H13: =假设!H68 -> 0.52 | I13: =假设!I68 -> 0.25 | J13: =假设!J68 -> 0.16 | K13: =假设!K68 -> 0.12 | L13: =假设!L68 -> 0.1
A14: 单价变动（假设） | B14: % | H14: =假设!H72 -> 0.19 | I14: =假设!I72 -> 0.08 | J14: =假设!J72 -> 0.035 | K14: =假设!K72 -> 0 | L14: =假设!L72 -> -0.02
A15: 销量指数（2025A=100） | G15: 100 | H15: =G15*(1+H13) -> 152 | I15: =H15*(1+I13) -> 190 | J15: =I15*(1+J13) -> 220.4 | K15: =J15*(1+K13) -> 246.848 | L15: =K15*(1+L13) -> 271.5328
A16: 单价指数（2025A=100） | G16: 100 | H16: =G16*(1+H14) -> 119 | I16: =H16*(1+I14) -> 128.52 | J16: =I16*(1+J14) -> 133.0182 | K16: =J16*(1+K14) -> 133.0182 | L16: =K16*(1+L14) -> 130.35784
A17: 电子元件（MLCC、陶瓷封装基座、电阻等）收入 | B17: 百万元 | F17: 2298.159 | G17: 3308.0896 | H17: =G17*(1+H13)*(1+H14) -> 5983.6724 | I17: =H17*(1+I13)*(1+I14) -> 8077.9578 | J17: =I17*(1+J13)*(1+J14) -> 9698.3961 | K17: =J17*(1+K13)*(1+K14) -> 10862.204 | L17: =K17*(1+L13)*(1+L14) -> 11709.456 | M17: 2025年年报：电子元件3,308,089,586.22元（2024年2,298,159,034.08元）
A18: 其中：量的贡献 | B18: 百万元 | H18: =G17*H13 -> 1720.2066 | I18: =H17*I13 -> 1495.9181 | J18: =I17*J13 -> 1292.4732 | K18: =J17*K13 -> 1163.8075 | L18: =K17*L13 -> 1086.2204
A19: 其中：价的贡献 | B19: 百万元 | H19: =G17*(1+H13)*H14 -> 955.37627 | I19: =H17*(1+I13)*I14 -> 598.36724 | J19: =I17*(1+J13)*J14 -> 327.96509 | K19: =J17*(1+K13)*K14 -> 0 | L19: =K17*(1+L13)*L14 -> -238.96848
A20: 同比 | B20: % | G20: =IFERROR(G17/F17-1,0) -> 0.43945199 | H20: =IFERROR(H17/G17-1,0) -> 0.8088 | I20: =IFERROR(I17/H17-1,0) -> 0.35 | J20: =IFERROR(J17/I17-1,0) -> 0.2006 | K20: =IFERROR(K17/J17-1,0) -> 0.12 | L20: =IFERROR(L17/K17-1,0) -> 0.078
A21: 通信器件（陶瓷插芯、套筒等光通信产品）
A22: 销量增速（假设） | B22: % | H22: =假设!H76 -> 0.58 | I22: =假设!I76 -> 0.3 | J22: =假设!J76 -> 0.2 | K22: =假设!K76 -> 0.14 | L22: =假设!L76 -> 0.11
A23: 单价变动（假设） | B23: % | H23: =假设!H80 -> -0.035 | I23: =假设!I80 -> -0.04 | J23: =假设!J80 -> -0.04 | K23: =假设!K80 -> -0.035 | L23: =假设!L80 -> -0.03
A24: 销量指数（2025A=100） | G24: 100 | H24: =G24*(1+H22) -> 158 | I24: =H24*(1+I22) -> 205.4 | J24: =I24*(1+J22) -> 246.48 | K24: =J24*(1+K22) -> 280.9872 | L24: =K24*(1+L22) -> 311.89579
A25: 单价指数（2025A=100） | G25: 100 | H25: =G25*(1+H23) -> 96.5 | I25: =H25*(1+I23) -> 92.64 | J25: =I25*(1+J23) -> 88.9344 | K25: =J25*(1+K23) -> 85.821696 | L25: =K25*(1+L23) -> 83.247045
A26: 通信器件（陶瓷插芯、套筒等光通信产品）收入 | B26: 百万元 | F26: 2305.9847 | G26: 2594.3099 | H26: =G26*(1+H22)*(1+H23) -> 3955.5443 | I26: =H26*(1+I22)*(1+I23) -> 4936.5193 | J26: =I26*(1+J22)*(1+J23) -> 5686.8702 | K26: =J26*(1+K22)*(1+K23) -> 6256.1259 | L26: =K26*(1+L22)*(1+L23) -> 6735.9708 | M26: 2025年年报：通信器件2,594,309,892.31元（2024年2,305,984,655.76元）
A27: 其中：量的贡献 | B27: 百万元 | H27: =G26*H22 -> 1504.6997 | I27: =H26*I22 -> 1186.6633 | J27: =I26*J22 -> 987.30386 | K27: =J26*K22 -> 796.16183 | L27: =K26*L22 -> 688.17385
A28: 其中：价的贡献 | B28: 百万元 | H28: =G26*(1+H22)*H23 -> -143.46534 | I28: =H26*(1+I22)*I23 -> -205.6883 | J28: =I26*(1+J22)*J23 -> -236.95293 | K28: =J26*(1+K22)*K23 -> -226.90612 | L28: =K26*(1+L22)*L23 -> -208.32899
A29: 同比 | B29: % | G29: =IFERROR(G26/F26-1,0) -> 0.12503346 | H29: =IFERROR(H26/G26-1,0) -> 0.5247 | I29: =IFERROR(I26/H26-1,0) -> 0.248 | J29: =IFERROR(J26/I26-1,0) -> 0.152 | K29: =IFERROR(K26/J26-1,0) -> 0.1001 | L29: =IFERROR(L26/K26-1,0) -> 0.0767
A30: 电子及陶瓷材料（陶瓷基片/基板、电子浆料、SOFC隔膜片等）
A31: Bloom电池片层需求 | B31: GW | G31: =假设!G102 -> 0.725 | H31: =假设!H102 -> 1.45 | I31: =假设!I102 -> 2.5 | J31: =假设!J102 -> 3.2 | K31: =假设!K102 -> 3.8 | L31: =假设!L102 -> 4.4 | M31: 见“假设”SOFC子模型
A32: 单片功率 | B32: W/片 | H32: =假设!H106 -> 30 | I32: =假设!I106 -> 30 | J32: =假设!J106 -> 32.5 | K32: =假设!K106 -> 32.5 | L32: =假设!L106 -> 35
A33: 每GW隔膜片需求 | B33: 百万片/GW | H33: =IFERROR(1000/H32,0) -> 33.333333 | I33: =IFERROR(1000/I32,0) -> 33.333333 | J33: =IFERROR(1000/J32,0) -> 30.769231 | K33: =IFERROR(1000/K32,0) -> 30.769231 | L33: =IFERROR(1000/L32,0) -> 28.571429
A34: Bloom隔膜片需求 | B34: 百万片 | H34: =H31*H33 -> 48.333333 | I34: =I31*I33 -> 83.333333 | J34: =J31*J33 -> 98.461538 | K34: =K31*K33 -> 116.92308 | L34: =L31*L33 -> 125.71429
A35: 三环份额 | B35: % | H35: =假设!H110 -> 0.75 | I35: =假设!I110 -> 0.65 | J35: =假设!J110 -> 0.52 | K35: =假设!K110 -> 0.47 | L35: =假设!L110 -> 0.42
A36: 三环隔膜片出货 | B36: 百万片 | H36: =H34*H35 -> 36.25 | I36: =I34*I35 -> 54.166667 | J36: =J34*J35 -> 51.2 | K36: =K34*K35 -> 54.953846 | L36: =L34*L35 -> 52.8
A37: 单价 | B37: 元/片 | H37: =假设!H114 -> 18 | I37: =假设!I114 -> 17 | J37: =假设!J114 -> 16.2 | K37: =假设!K114 -> 15.4 | L37: =假设!L114 -> 14.6
A38: SOFC隔膜片收入 | B38: 百万元 | E38: 449.31873 | F38: 323.86965 | G38: 330.718 | H38: =H36*H37 -> 652.5 | I38: =I36*I37 -> 920.83333 | J38: =J36*J37 -> 829.44 | K38: =K36*K37 -> 846.28923 | L38: =L36*L37 -> 770.88 | M38: 历史为年报前五大客户“客户1”销售额（2023A 449,318,727.96元；2024A 323,869,648.00元；2025A 330,717,999.78元），市场普遍对应Bloom
A39: 每GW隔膜片价值量（100%份额） | B39: 百万元/GW | H39: =H33*H37 -> 600 | I39: =I33*I37 -> 566.66667 | J39: =J33*J37 -> 498.46154 | K39: =K33*K37 -> 473.84615 | L39: =L33*L37 -> 417.14286
A40: 其他电子及陶瓷材料（不含SOFC） | B40: 百万元 | F40: =F41-F38 -> 1353.3631 | G40: =G41-G38 -> 1628.66 | H40: =G40*(1+假设!H84) -> 1872.959 | I40: =H40*(1+假设!I84) -> 2097.7141 | J40: =I40*(1+假设!J84) -> 2307.4855 | K40: =J40*(1+假设!K84) -> 2492.0844 | L40: =K40*(1+假设!L84) -> 2641.6094
A41: 电子及陶瓷材料收入 | B41: 百万元 | F41: 1677.2328 | G41: 1959.378 | H41: =H40+H38 -> 2525.459 | I41: =I40+I38 -> 3018.5474 | J41: =J40+J38 -> 3136.9255 | K41: =K40+K38 -> 3338.3736 | L41: =L40+L38 -> 3412.4894 | M41: 2025年年报：电子及陶瓷材料1,959,378,016.92元（2024年1,677,232,780.51元）
...

Sheet 成本拆解
A1: 成本拆解：分部毛利率与营业成本按性质
A2: 分部毛利率为主驱动（生产人工与生产折旧偏离标定值的部分另行计入）；按性质拆分时人工来自人员模型、折旧来自资本开支模型、其他制造费用按占收入比例假设，原材料为倒挤项。
A4: 项目（百万元，另注明除外） | B4: 单位 | C4: 2021A | D4: 2022A | E4: 2023A | F4: 2024A | G4: 2025A | H4: 2026E | I4: 2027E | J4: 2028E | K4: 2029E | L4: 2030E | M4: 来源/说明
A5: A. 分部毛利率（采用值，含敏感性冲击）
A6: 电子元件 毛利率 | B6: % | F6: 0.4437 | G6: 0.423 | H6: =假设!H119 -> 0.46 | I6: =假设!I119 -> 0.47 | J6: =假设!J119 -> 0.46 | K6: =假设!K119 -> 0.45 | L6: =假设!L119 -> 0.44 | M6: 2025年年报分产品毛利率及同比增减倒推；设备组件/其他主营/其他业务按Wind主营构成
A7: 通信器件 毛利率 | B7: % | F7: 0.4393 | G7: 0.4436 | H7: =假设!H123 -> 0.46 | I7: =假设!I123 -> 0.46 | J7: =假设!J123 -> 0.45 | K7: =假设!K123 -> 0.44 | L7: =假设!L123 -> 0.44 | M7: 2025年年报分产品毛利率及同比增减倒推；设备组件/其他主营/其他业务按Wind主营构成
A8: 其他电子及陶瓷材料 毛利率 | B8: % | H8: =假设!H127 -> 0.38 | I8: =假设!I127 -> 0.38 | J8: =假设!J127 -> 0.38 | K8: =假设!K127 -> 0.37 | L8: =假设!L127 -> 0.37
A9: SOFC隔膜片 毛利率 | B9: % | H9: =假设!H131 -> 0.4 | I9: =假设!I131 -> 0.4 | J9: =假设!J131 -> 0.39 | K9: =假设!K131 -> 0.38 | L9: =假设!L131 -> 0.38
A10: 设备组件 毛利率 | B10: % | G10: 0.5846 | H10: =假设!H135 -> 0.58 | I10: =假设!I135 -> 0.58 | J10: =假设!J135 -> 0.57 | K10: =假设!K135 -> 0.57 | L10: =假设!L135 -> 0.56 | M10: 2025年年报分产品毛利率及同比增减倒推；设备组件/其他主营/其他业务按Wind主营构成
A11: 其他主营 毛利率 | B11: % | G11: 0.0911 | H11: =假设!H137 -> 0.28 | I11: =假设!I137 -> 0.2 | J11: =假设!J137 -> 0.15 | K11: =假设!K137 -> 0.12 | L11: =假设!L137 -> 0.1
A12: 其他业务 毛利率 | B12: % | G12: 0.7957 | H12: =假设!H139 -> 0.75 | I12: =假设!I139 -> 0.75 | J12: =假设!J139 -> 0.75 | K12: =假设!K139 -> 0.75 | L12: =假设!L139 -> 0.75
A13: 电子及陶瓷材料（分部合计）毛利率 | B13: % | F13: 0.4057 | G13: 0.3809 | H13: =IFERROR(1-H22/收入拆解!H41,0) -> 0.38516738 | I13: =IFERROR(1-I22/收入拆解!I41,0) -> 0.38610117 | J13: =IFERROR(1-J22/收入拆解!J41,0) -> 0.38264412 | K13: =IFERROR(1-K22/收入拆解!K41,0) -> 0.37253503 | L13: =IFERROR(1-L22/收入拆解!L41,0) -> 0.372259
A14: B. 分部营业成本
A15: 电子元件 营业成本 | B15: 百万元 | G15: 1908.6416 | H15: =收入拆解!H17*(1-H6) -> 3231.1831 | I15: =收入拆解!I17*(1-I6) -> 4281.3176 | J15: =收入拆解!J17*(1-J6) -> 5237.1339 | K15: =收入拆解!K17*(1-K6) -> 5974.212 | L15: =收入拆解!L17*(1-L6) -> 6557.2951
A16: 通信器件 营业成本 | B16: 百万元 | G16: 1443.6034 | H16: =收入拆解!H26*(1-H7) -> 2135.9939 | I16: =收入拆解!I26*(1-I7) -> 2665.7204 | J16: =收入拆解!J26*(1-J7) -> 3127.7786 | K16: =收入拆解!K26*(1-K7) -> 3503.4305 | L16: =收入拆解!L26*(1-L7) -> 3772.1436
A17: 其他电子及陶瓷材料 营业成本 | B17: 百万元 | H17: =收入拆解!H40*(1-H8) -> 1161.2346 | I17: =收入拆解!I40*(1-I8) -> 1300.5827 | J17: =收入拆解!J40*(1-J8) -> 1430.641 | K17: =收入拆解!K40*(1-K8) -> 1570.0131 | L17: =收入拆解!L40*(1-L8) -> 1664.2139
A18: SOFC隔膜片 营业成本 | B18: 百万元 | H18: =收入拆解!H38*(1-H9) -> 391.5 | I18: =收入拆解!I38*(1-I9) -> 552.5 | J18: =收入拆解!J38*(1-J9) -> 505.9584 | K18: =收入拆解!K38*(1-K9) -> 524.69932 | L18: =收入拆解!L38*(1-L9) -> 477.9456
A19: 设备组件 营业成本 | B19: 百万元 | G19: 249.9511 | H19: =收入拆解!H43*(1-H10) -> 290.6469 | I19: =收入拆解!I43*(1-I10) -> 325.52452 | J19: =收入拆解!J43*(1-J10) -> 366.60262 | K19: =收入拆解!K43*(1-K10) -> 395.93083 | L19: =收入拆解!L43*(1-L10) -> 429.44683
A20: 其他主营 营业成本 | B20: 百万元 | G20: 368.116 | H20: =收入拆解!H44*(1-H11) -> 379.07661 | I20: =收入拆解!I44*(1-I11) -> 442.25604 | J20: =收入拆解!J44*(1-J11) -> 493.39189 | K20: =收入拆解!K44*(1-K11) -> 536.34601 | L20: =收入拆解!L44*(1-L11) -> 575.96248
A21: 其他业务 营业成本 | B21: 百万元 | G21: 28.3312 | H21: =收入拆解!H45*(1-H12) -> 45 | I21: =收入拆解!I45*(1-I12) -> 47.5 | J21: =收入拆解!J45*(1-J12) -> 50 | K21: =收入拆解!K45*(1-K12) -> 52.5 | L21: =收入拆解!L45*(1-L12) -> 55
A22: 电子及陶瓷材料 营业成本（合计） | B22: 百万元 | G22: 1213.1183 | H22: =H17+H18 -> 1552.7346 | I22: =I17+I18 -> 1853.0827 | J22: =J17+J18 -> 1936.5994 | K22: =K17+K18 -> 2094.7125 | L22: =L17+L18 -> 2142.1595
A23: 分部营业成本小计（按毛利率假设） | B23: 百万元 | G23: =G15+G16+G22+G19+G20+G21 -> 5211.7617 | H23: =H15+H16+H22+H19+H20+H21 -> 7634.6351 | I23: =I15+I16+I22+I19+I20+I21 -> 9615.4014 | J23: =J15+J16+J22+J19+J20+J21 -> 11211.506 | K23: =K15+K16+K22+K19+K20+K21 -> 12557.132 | L23: =L15+L16+L22+L19+L20+L21 -> 13532.008
A24: 加：生产人工偏离标定值 | B24: 百万元 | H24: =H33-假设!H141 -> -1.9376444e-07 | I24: =I33-假设!I141 -> 3.3300057e-07 | J24: =J33-假设!J141 -> -2.489669e-07 | K24: =K33-假设!K141 -> 4.1479325e-07 | L24: =L33-假设!L141 -> -1.6101376e-07 | M24: 人数或人均薪酬假设偏离标定值时，差额直接计入营业成本（基准情景为0）
A25: 加：生产折旧摊销偏离标定值 | B25: 百万元 | H25: =H35-假设!H142 -> 1.4353236e-07 | I25: =I35-假设!I142 -> -4.5915544e-07 | J25: =J35-假设!J142 -> 3.3833021e-07 | K25: =K35-假设!K142 -> 4.5630316e-07 | L25: =L35-假设!L142 -> -4.341307e-07 | M25: 资本开支、折旧率或情景变化引起的生产折旧差额直接计入营业成本（基准情景为0）
A26: 营业成本合计 | B26: 百万元 | C26: =历史利润表!E8 -> 3186.5095 | D26: =历史利润表!F8 -> 2878.3209 | E26: =历史利润表!G8 -> 3445.5299 | F26: =历史利润表!H8 -> 4204.8637 | G26: =历史利润表!I8 -> 5211.7617 | H26: =H23+H24+H25 -> 7634.6351 | I26: =I23+I24+I25 -> 9615.4014 | J26: =J23+J24+J25 -> 11211.506 | K26: =K23+K24+K25 -> 12557.132 | L26: =L23+L24+L25 -> 13532.008
A27: 毛利合计 | B27: 百万元 | C27: =历史利润表!E6-历史利润表!E8 -> 3031.5325 | D27: =历史利润表!F6-历史利润表!F8 -> 2271.066 | E27: =历史利润表!G6-历史利润表!G8 -> 2281.1586 | F27: =收入拆解!F47-F26 -> 3170.1271 | G27: =收入拆解!G47-G26 -> 3795.3922 | H27: =收入拆解!H47-H26 -> 6228.5523 | I27: =收入拆解!I47-I26 -> 7935.5016 | J27: =收入拆解!J47-J26 -> 8943.7107 | K27: =收入拆解!K47-K26 -> 9639.8248 | L27: =收入拆解!L47-L26 -> 10161.882
A28: 综合毛利率 | B28: % | C28: =IFERROR(C27/历史利润表!E6,0) -> 0.48753812 | D28: =IFERROR(D27/历史利润表!F6,0) -> 0.44103619 | E28: =IFERROR(E27/历史利润表!G6,0) -> 0.39833817 | F28: =IFERROR(F27/历史利润表!H6,0) -> 0.42984828 | G28: =IFERROR(G27/历史利润表!I6,0) -> 0.4213753 | H28: =IFERROR(H27/收入拆解!H47,0) -> 0.44928717 | I28: =IFERROR(I27/收入拆解!I47,0) -> 0.45214207 | J28: =IFERROR(J27/收入拆解!J47,0) -> 0.44374172 | K28: =IFERROR(K27/收入拆解!K47,0) -> 0.43428588 | L28: =IFERROR(L27/收入拆解!L47,0) -> 0.42888197
A29: SOFC隔膜片毛利 | B29: 百万元 | H29: =收入拆解!H38-H18 -> 261 | I29: =收入拆解!I38-I18 -> 368.33333 | J29: =收入拆解!J38-J18 -> 323.4816 | K29: =收入拆解!K38-K18 -> 321.58991 | L29: =收入拆解!L38-L18 -> 292.9344
A30: SOFC毛利占公司毛利 | B30: % | H30: =IFERROR(H29/H27,0) -> 0.041903798 | I30: =IFERROR(I29/I27,0) -> 0.046415885 | J30: =IFERROR(J29/J27,0) -> 0.036168612 | K30: =IFERROR(K29/K27,0) -> 0.033360555 | L30: =IFERROR(L29/L27,0) -> 0.028826786
A31: C. 营业成本按性质（人工来自人员模型、生产折旧来自资本开支模型、其他制造费用按假设，原材料为倒挤项）
A32: 原材料（预测为倒挤：营业成本-人工-生产折旧-其他制造费用） | B32: 百万元 | D32: 1542.6735 | E32: 1972.6116 | F32: 2489.6812 | G32: 3315.2286 | H32: =H26-H33-H34 -> 5307.8759 | I32: =I26-I33-I34 -> 6880.1563 | J32: =J26-J33-J34 -> 8092.0546 | K32: =K26-K33-K34 -> 9088.1169 | L32: =L26-L33-L34 -> 9755.1192 | M32: 年报“营业成本构成”（工业）
A33: 人工费用 | B33: 百万元 | D33: 657.55686 | E33: 673.31081 | F33: 879.76224 | G33: 955.38895 | H33: =人员与费用!H25 -> 1128.7221 | I33: =人员与费用!I25 -> 1315.4359 | J33: =人员与费用!J25 -> 1481.1629 | K33: =人员与费用!K25 -> 1626.6781 | L33: =人员与费用!L25 -> 1765.0143
A34: 制造费用 | B34: 百万元 | D34: 678.09057 | E34: 799.60748 | F34: 835.42027 | G34: 941.14411 | H34: =H35+H36 -> 1198.0371 | I34: =I35+I36 -> 1419.8092 | J34: =J35+J36 -> 1638.289 | K34: =K35+K36 -> 1842.3369 | L34: =L35+L36 -> 2011.8741
A35: 其中：生产用折旧摊销 | B35: 百万元 | E35: =资本开支与折旧!E91*假设!$C$38 -> 513.14209 | F35: =资本开支与折旧!F91*假设!$C$38 -> 548.37793 | G35: =资本开支与折旧!G91*假设!$C$38 -> 623.44466 | H35: =资本开支与折旧!H93 -> 685.09913 | I35: =资本开支与折旧!I93 -> 770.42575 | J35: =资本开支与折旧!J93 -> 892.54598 | K35: =资本开支与折旧!K93 -> 1021.0495 | L35: =资本开支与折旧!L93 -> 1135.2002 | M35: 历史按折旧摊销总额×生产分摊比例估算
A36: 其中：能源、辅料及其他制造费用 | B36: 百万元 | E36: =E34-E35 -> 286.46539 | F36: =F34-F35 -> 287.04235 | G36: =G34-G35 -> 317.69945 | H36: =收入拆解!H47*假设!H140 -> 512.93794 | I36: =收入拆解!I47*假设!I140 -> 649.38341 | J36: =收入拆解!J47*假设!J140 -> 745.74303 | K36: =收入拆解!K47*假设!K140 -> 821.2874 | L36: =收入拆解!L47*假设!L140 -> 876.67391
A37: 校验：性质合计-营业成本 | B37: 百万元 | E37: =ROUND(E32+E33+E34-E26,1) -> 0 | F37: =ROUND(F32+F33+F34-F26,1) -> 0 | G37: =ROUND(G32+G33+G34-G26,1) -> 0 | H37: =ROUND(H32+H33+H34-H26,4) -> 0 | I37: =ROUND(I32+I33+I34-I26,4) -> 0 | J37: =ROUND(J32+J33+J34-J26,4) -> 0 | K37: =ROUND(K32+K33+K34-K26,4) -> 0 | L37: =ROUND(L32+L33+L34-L26,4) -> 0
A38: 原材料占营业成本（预测为结果，对照历史53.6%-63.6%） | B38: % | E38: =IFERROR(E32/E26,0) -> 0.57251327 | F38: =IFERROR(F32/F26,0) -> 0.59209558 | G38: =IFERROR(G32/G26,0) -> 0.63610517 | H38: =IFERROR(H32/H26,0) -> 0.69523636 | I38: =IFERROR(I32/I26,0) -> 0.71553501 | J38: =IFERROR(J32/J26,0) -> 0.72176336 | K38: =IFERROR(K32/K26,0) -> 0.72374146 | L38: =IFERROR(L32/L26,0) -> 0.72089224
A39: 人工占营业成本 | B39: % | E39: =IFERROR(E33/E26,0) -> 0.19541575 | F39: =IFERROR(F33/F26,0) -> 0.20922491 | G39: =IFERROR(G33/G26,0) -> 0.18331401 | H39: =IFERROR(H33/H26,0) -> 0.14784232 | I39: =IFERROR(I33/I26,0) -> 0.13680509 | J39: =IFERROR(J33/J26,0) -> 0.13211096 | K39: =IFERROR(K33/K26,0) -> 0.12954217 | L39: =IFERROR(L33/L26,0) -> 0.13043255
A40: 制造费用占营业成本 | B40: % | E40: =IFERROR(E34/E26,0) -> 0.23207097 | F40: =IFERROR(F34/F26,0) -> 0.19867951 | G40: =IFERROR(G34/G26,0) -> 0.1805808 | H40: =IFERROR(H34/H26,0) -> 0.15692133 | I40: =IFERROR(I34/I26,0) -> 0.1476599 | J40: =IFERROR(J34/J26,0) -> 0.14612568 | K40: =IFERROR(K34/K26,0) -> 0.14671638 | L40: =IFERROR(L34/L26,0) -> 0.14867521
A41: 其他制造费用占收入 | B41: % | E41: =IFERROR(E36/历史利润表!G6,0) -> 0.05002287 | F41: =IFERROR(F36/历史利润表!H6,0) -> 0.038921045 | G41: =IFERROR(G36/历史利润表!I6,0) -> 0.035271903 | H41: =IFERROR(H36/收入拆解!H47,0) -> 0.037 | I41: =IFERROR(I36/收入拆解!I47,0) -> 0.037 | J41: =IFERROR(J36/收入拆解!J47,0) -> 0.037 | K41: =IFERROR(K36/收入拆解!K47,0) -> 0.037 | L41: =IFERROR(L36/收入拆解!L47,0) -> 0.037 | M41: 预测为假设驱动（见“假设”）
...

Sheet 人员与费用
A1: 人员与期间费用：人数×人均薪酬驱动
A2: 员工人数与专业构成来自年报“公司员工情况”；职工薪酬总额取“应付职工薪酬”本期增加；费用按性质拆分来自财务报表附注。
A4: 项目（百万元，另注明除外） | B4: 单位 | C4: 2021A | D4: 2022A | E4: 2023A | F4: 2024A | G4: 2025A | H4: 2026E | I4: 2027E | J4: 2028E | K4: 2029E | L4: 2030E | M4: 来源/说明
A5: A. 员工人数（期末，人）
A6: 生产人员 | B6: 人 | E6: 9657 | F6: 10438 | G6: 13906 | H6: =G6*(1+假设!H145) -> 15991.9 | I6: =H6*(1+假设!I145) -> 17591.09 | J6: =I6*(1+假设!J145) -> 18822.466 | K6: =J6*(1+假设!K145) -> 19763.59 | L6: =K6*(1+假设!L145) -> 20554.133
A7: 销售人员 | B7: 人 | E7: 211 | F7: 188 | G7: 208 | H7: =G7*(1+假设!H147) -> 218.4 | I7: =H7*(1+假设!I147) -> 229.32 | J7: =I7*(1+假设!J147) -> 238.4928 | K7: =J7*(1+假设!K147) -> 245.64758 | L7: =K7*(1+假设!L147) -> 253.01701
A8: 技术人员 | B8: 人 | E8: 2675 | F8: 3918 | G8: 1975 | H8: =G8*(1+假设!H149) -> 2093.5 | I8: =H8*(1+假设!I149) -> 2219.11 | J8: =I8*(1+假设!J149) -> 2330.0655 | K8: =J8*(1+假设!K149) -> 2423.2681 | L8: =K8*(1+假设!L149) -> 2520.1988
A9: 财务人员 | B9: 人 | E9: 50 | F9: 44 | G9: 52 | H9: =G9*(1+假设!H151) -> 53.56 | I9: =H9*(1+假设!I151) -> 55.1668 | J9: =I9*(1+假设!J151) -> 56.821804 | K9: =J9*(1+假设!K151) -> 58.526458 | L9: =K9*(1+假设!L151) -> 60.282252
A10: 行政人员 | B10: 人 | E10: 908 | F10: 927 | G10: 1211 | H10: =G10*(1+假设!H153) -> 1271.55 | I10: =H10*(1+假设!I153) -> 1322.412 | J10: =I10*(1+假设!J153) -> 1362.0844 | K10: =J10*(1+假设!K153) -> 1402.9469 | L10: =K10*(1+假设!L153) -> 1445.0353
A11: 员工合计 | B11: 人 | E11: =SUM(E6:E10) -> 13501 | F11: =SUM(F6:F10) -> 15515 | G11: =SUM(G6:G10) -> 17352 | H11: =SUM(H6:H10) -> 19628.91 | I11: =SUM(I6:I10) -> 21417.099 | J11: =SUM(J6:J10) -> 22809.931 | K11: =SUM(K6:K10) -> 23893.979 | L11: =SUM(L6:L10) -> 24832.667
A12: 员工合计同比 | B12: % | F12: =IFERROR(F11/E11-1,0) -> 0.14917414 | G12: =IFERROR(G11/F11-1,0) -> 0.11840155 | H12: =IFERROR(H11/G11-1,0) -> 0.13121888 | I12: =IFERROR(I11/H11-1,0) -> 0.09109975 | J12: =IFERROR(J11/I11-1,0) -> 0.065033643 | K12: =IFERROR(K11/J11-1,0) -> 0.047525261 | L12: =IFERROR(L11/K11-1,0) -> 0.039285543
A13: 人均营业收入 | B13: 万元/人 | F13: =IFERROR(历史利润表!H6*100/AVERAGE(E11,F11),0) -> 50.833959 | G13: =IFERROR(历史利润表!I6*100/AVERAGE(F11,G11),0) -> 54.809711 | H13: =IFERROR(收入拆解!H47*100/AVERAGE(G11,H11),0) -> 74.974831 | I13: =IFERROR(收入拆解!I47*100/AVERAGE(H11,I11),0) -> 85.518195 | J13: =IFERROR(收入拆解!J47*100/AVERAGE(I11,J11),0) -> 91.14434 | K13: =IFERROR(收入拆解!K47*100/AVERAGE(J11,K11),0) -> 95.053955 | L13: =IFERROR(收入拆解!L47*100/AVERAGE(K11,L11),0) -> 97.252292
A14: 生产人员（平均） | B14: 人 | F14: =AVERAGE(E6,F6) -> 10047.5 | G14: =AVERAGE(F6,G6) -> 12172 | H14: =AVERAGE(G6,H6) -> 14948.95 | I14: =AVERAGE(H6,I6) -> 16791.495 | J14: =AVERAGE(I6,J6) -> 18206.778 | K14: =AVERAGE(J6,K6) -> 19293.028 | L14: =AVERAGE(K6,L6) -> 20158.861
A15: 销售人员（平均） | B15: 人 | F15: =AVERAGE(E7,F7) -> 199.5 | G15: =AVERAGE(F7,G7) -> 198 | H15: =AVERAGE(G7,H7) -> 213.2 | I15: =AVERAGE(H7,I7) -> 223.86 | J15: =AVERAGE(I7,J7) -> 233.9064 | K15: =AVERAGE(J7,K7) -> 242.07019 | L15: =AVERAGE(K7,L7) -> 249.3323
A16: 技术人员（平均） | B16: 人 | F16: =AVERAGE(E8,F8) -> 3296.5 | G16: =AVERAGE(F8,G8) -> 2946.5 | H16: =AVERAGE(G8,H8) -> 2034.25 | I16: =AVERAGE(H8,I8) -> 2156.305 | J16: =AVERAGE(I8,J8) -> 2274.5878 | K16: =AVERAGE(J8,K8) -> 2376.6668 | L16: =AVERAGE(K8,L8) -> 2471.7335
A17: 财务人员（平均） | B17: 人 | F17: =AVERAGE(E9,F9) -> 47 | G17: =AVERAGE(F9,G9) -> 48 | H17: =AVERAGE(G9,H9) -> 52.78 | I17: =AVERAGE(H9,I9) -> 54.3634 | J17: =AVERAGE(I9,J9) -> 55.994302 | K17: =AVERAGE(J9,K9) -> 57.674131 | L17: =AVERAGE(K9,L9) -> 59.404355
A18: 行政人员（平均） | B18: 人 | F18: =AVERAGE(E10,F10) -> 917.5 | G18: =AVERAGE(F10,G10) -> 1069 | H18: =AVERAGE(G10,H10) -> 1241.275 | I18: =AVERAGE(H10,I10) -> 1296.981 | J18: =AVERAGE(I10,J10) -> 1342.2482 | K18: =AVERAGE(J10,K10) -> 1382.5156 | L18: =AVERAGE(K10,L10) -> 1423.9911
A19: 平均员工合计 | B19: 人 | F19: =SUM(F14:F18) -> 14508 | G19: =SUM(G14:G18) -> 16433.5 | H19: =SUM(H14:H18) -> 18490.455 | I19: =SUM(I14:I18) -> 20523.004 | J19: =SUM(J14:J18) -> 22113.515 | K19: =SUM(K14:K18) -> 23351.955 | L19: =SUM(L14:L18) -> 24363.323
A20: B. 职工薪酬总额与人均
A21: 职工薪酬总额 | B21: 百万元 | E21: 1427.965 | F21: 1875.6708 | G21: 2102.3803 | H21: =H22*H19/100 -> 2483.8085 | I21: =I22*I19/100 -> 2894.6812 | J21: =J22*J19/100 -> 3259.3716 | K21: =K22*K19/100 -> 3579.585 | L21: =L22*L19/100 -> 3884.0007 | M21: 应付职工薪酬“本期增加”（短期薪酬+离职后福利）
A22: 人均薪酬 | B22: 万元/人 | F22: =IFERROR(F21*100/F19,0) -> 12.928528 | G22: =IFERROR(G21*100/G19,0) -> 12.79326 | H22: =G22*(1+假设!H155) -> 13.432923 | I22: =H22*(1+假设!I155) -> 14.104569 | J22: =I22*(1+假设!J155) -> 14.739274 | K22: =J22*(1+假设!K155) -> 15.328845 | L22: =K22*(1+假设!L155) -> 15.941999
A23: 人均薪酬同比 | B23: % | G23: =IFERROR(G22/F22-1,0) -> -0.01046275 | H23: =假设!H155 -> 0.05 | I23: =假设!I155 -> 0.05 | J23: =假设!J155 -> 0.045 | K23: =假设!K155 -> 0.04 | L23: =假设!L155 -> 0.04
A24: C. 职工薪酬按功能归集（上年×平均总人数变动×(1+人均薪酬增速)；2025年技术人员由3,918人降至1,975人、生产人员增加3,468人，为口径调整）
A25: 计入营业成本的人工 | B25: 百万元 | D25: 657.55686 | E25: 673.31081 | F25: 879.76224 | G25: 955.38895 | H25: =G25*IFERROR((H14+H15+H16+H17+H18)/(G14+G15+G16+G17+G18),1)*(1+假设!H155) -> 1128.7221 | I25: =H25*IFERROR((I14+I15+I16+I17+I18)/(H14+H15+H16+H17+H18),1)*(1+假设!I155) -> 1315.4359 | J25: =I25*IFERROR((J14+J15+J16+J17+J18)/(I14+I15+I16+I17+I18),1)*(1+假设!J155) -> 1481.1629 | K25: =J25*IFERROR((K14+K15+K16+K17+K18)/(J14+J15+J16+J17+J18),1)*(1+假设!K155) -> 1626.6781 | L25: =K25*IFERROR((L14+L15+L16+L17+L18)/(K14+K15+K16+K17+K18),1)*(1+假设!L155) -> 1765.0143
A26: 研发费用-职工薪酬 | B26: 百万元 | D26: 291.7834 | E26: 365.28506 | F26: 451.13867 | G26: 474.30486 | H26: =G26*IFERROR((H14+H15+H16+H17+H18)/(G14+G15+G16+G17+G18),1)*(1+假设!H155) -> 560.35649 | I26: =H26*IFERROR((I14+I15+I16+I17+I18)/(H14+H15+H16+H17+H18),1)*(1+假设!I155) -> 653.05092 | J26: =I26*IFERROR((J14+J15+J16+J17+J18)/(I14+I15+I16+I17+I18),1)*(1+假设!J155) -> 735.32642 | K26: =J26*IFERROR((K14+K15+K16+K17+K18)/(J14+J15+J16+J17+J18),1)*(1+假设!K155) -> 807.56776 | L26: =K26*IFERROR((L14+L15+L16+L17+L18)/(K14+K15+K16+K17+K18),1)*(1+假设!L155) -> 876.24508
A27: 管理费用-职工薪酬 | B27: 百万元 | D27: 318.43783 | E27: 267.22089 | F27: 218.7219 | G27: 271.23044 | H27: =G27*IFERROR((H14+H15+H16+H17+H18)/(G14+G15+G16+G17+G18),1)*(1+假设!H155) -> 320.43892 | I27: =H27*IFERROR((I14+I15+I16+I17+I18)/(H14+H15+H16+H17+H18),1)*(1+假设!I155) -> 373.44608 | J27: =I27*IFERROR((J14+J15+J16+J17+J18)/(I14+I15+I16+I17+I18),1)*(1+假设!J155) -> 420.49519 | K27: =J27*IFERROR((K14+K15+K16+K17+K18)/(J14+J15+J16+J17+J18),1)*(1+假设!K155) -> 461.80628 | L27: =K27*IFERROR((L14+L15+L16+L17+L18)/(K14+K15+K16+K17+K18),1)*(1+假设!L155) -> 501.07929
A28: 销售费用-职工薪酬 | B28: 百万元 | D28: 46.110385 | E28: 54.158358 | F28: 59.992823 | G28: 67.791417 | H28: =G28*IFERROR((H14+H15+H16+H17+H18)/(G14+G15+G16+G17+G18),1)*(1+假设!H155) -> 80.090599 | I28: =H28*IFERROR((I14+I15+I16+I17+I18)/(H14+H15+H16+H17+H18),1)*(1+假设!I155) -> 93.339223 | J28: =I28*IFERROR((J14+J15+J16+J17+J18)/(I14+I15+I16+I17+I18),1)*(1+假设!J155) -> 105.09869 | K28: =J28*IFERROR((K14+K15+K16+K17+K18)/(J14+J15+J16+J17+J18),1)*(1+假设!K155) -> 115.424 | L28: =K28*IFERROR((L14+L15+L16+L17+L18)/(K14+K15+K16+K17+K18),1)*(1+假设!L155) -> 125.2399
A29: 其他职工薪酬（计入在建工程、存货等，倒挤） | B29: 百万元 | E29: =E21-E25-E26-E27-E28 -> 67.989882 | F29: =F21-F25-F26-F27-F28 -> 266.05513 | G29: =G21-G25-G26-G27-G28 -> 333.66463 | H29: =H21-H25-H26-H27-H28 -> 394.20035 | I29: =I21-I25-I26-I27-I28 -> 459.40915 | J29: =J21-J25-J26-J27-J28 -> 517.28844 | K29: =K21-K25-K26-K27-K28 -> 568.10888 | L29: =L21-L25-L26-L27-L28 -> 616.42209 | M29: 倒挤项，反映薪酬在成本与费用之间的归集差异及存货中尚未结转的人工
A30: D. 销售费用
A31: 职工薪酬 | B31: 百万元 | D31: =D28 -> 46.110385 | E31: =E28 -> 54.158358 | F31: =F28 -> 59.992823 | G31: =G28 -> 67.791417 | H31: =H28 -> 80.090599 | I31: =I28 -> 93.339223 | J31: =J28 -> 105.09869 | K31: =K28 -> 115.424 | L31: =L28 -> 125.2399
A32: 折旧与摊销 | B32: 百万元 | H32: =资本开支与折旧!H95 -> 0 | I32: =资本开支与折旧!I95 -> 0 | J32: =资本开支与折旧!J95 -> 0 | K32: =资本开支与折旧!K95 -> 0 | L32: =资本开支与折旧!L95 -> 0
A33: 其他 | B33: 百万元 | D33: =历史利润表!F10-D31-D32 -> 11.197615 | E33: =历史利润表!G10-E31-E32 -> 20.184742 | F33: =历史利润表!H10-F31-F32 -> 19.398977 | G33: =历史利润表!I10-G31-G32 -> 25.407883 | H33: =收入拆解!H47*假设!H157 -> 24.953737 | I33: =收入拆解!I47*假设!I157 -> 31.591625 | J33: =收入拆解!J47*假设!J157 -> 36.279391 | K33: =收入拆解!K47*假设!K157 -> 39.954522 | L33: =收入拆解!L47*假设!L157 -> 42.649001
A34: 销售费用合计 | B34: 百万元 | C34: =历史利润表!E10 -> 51.3154 | D34: =历史利润表!F10 -> 57.308 | E34: =历史利润表!G10 -> 74.3431 | F34: =历史利润表!H10 -> 79.3918 | G34: =历史利润表!I10 -> 93.1993 | H34: =H31+H32+H33 -> 105.04434 | I34: =I31+I32+I33 -> 124.93085 | J34: =J31+J32+J33 -> 141.37808 | K34: =K31+K32+K33 -> 155.37852 | L34: =L31+L32+L33 -> 167.88891
