Workbook

Sheet 封面
A1: 烽火通信（600498.SH）财务与估值模型
A2: 单位：人民币百万元（除特别注明）｜模型日期：2026-10-06｜数据：2021–2026H1定期报告、Wind
A5: 市场数据
A6: 股价（元） | C6: =假设!$C$8 -> 35.7
A7: 总股本（百万股，2025年末） | C7: =融资!G35 -> 1358.1675
A8: 总市值（百万元） | C8: =C6*C7 -> 48486.58
A9: 净负债（2026H1末） | C9: =融资!N19 -> 7606.4549
A10: 当前情景 | C10: =假设!$D$5 -> 基准
A11: 模型核对 | C11: =核对!$C$18 -> OK
A13: 核心财务摘要
A14: 百万元 | C14: 2023A | D14: 2024A | E14: 2025A | F14: 2026E | G14: 2027E | H14: 2028E
A15: 营业收入 | C15: =利润表!E6 -> 31129.574 | D15: =利润表!F6 -> 28548.831 | E15: =利润表!G6 -> 24918.554 | F15: =利润表!H6 -> 27563.516 | G15: =利润表!I6 -> 29404.632 | H15: =利润表!J6 -> 30868.269
A16: 增速 | C16: =利润表!E39 -> 0.0068476148 | D16: =利润表!F39 -> -0.082903267 | E16: =利润表!G39 -> -0.12716024 | F16: =利润表!H39 -> 0.10614427 | G16: =利润表!I39 -> 0.066795386 | H16: =利润表!J39 -> 0.049775731
A17: 毛利率 | C17: =利润表!E41 -> 0.20563882 | D17: =利润表!F41 -> 0.2124839 | E17: =利润表!G41 -> 0.21098038 | F17: =利润表!H41 -> 0.21047025 | G17: =利润表!I41 -> 0.20761988 | H17: =利润表!J41 -> 0.20216644
A18: 其中：光纤及线缆毛利 | C18: =分业务!E20 -> 1144.0746 | D18: =分业务!F20 -> 1191.1576 | E18: =分业务!G20 -> 1171.2275 | F18: =分业务!H20 -> 2559.7537 | G18: =分业务!I20 -> 2363.6765 | H18: =分业务!J20 -> 2003.6361
A19: 通信系统设备毛利率 | C19: =分业务!E11 -> 0.19240917 | D19: =分业务!F11 -> 0.19455531 | E19: =分业务!G11 -> 0.18813578 | F19: =分业务!H11 -> 0.138 | G19: =分业务!I11 -> 0.148 | H19: =分业务!J11 -> 0.158
A20: 归母净利润 | C20: =利润表!E29 -> 505.3671 | D20: =利润表!F29 -> 702.7062 | E20: =利润表!G29 -> 435.8343 | F20: =利润表!H29 -> 751.93618 | G20: =利润表!I29 -> 1075.8572 | H20: =利润表!J29 -> 1153.3271
A21: 增速 | C21: =利润表!E40 -> 0.24538059 | D21: =利润表!F40 -> 0.39048664 | E21: =利润表!G40 -> -0.37977735 | F21: =利润表!H40 -> 0.72527995 | G21: =利润表!I40 -> 0.43078253 | H21: =利润表!J40 -> 0.072007641
A22: 其中：广发基金权益法收益 | C22: =费用!E31 -> 276.60252 | D22: =费用!F31 -> 283.69318 | E22: =费用!G31 -> 390.63195 | F22: =费用!H31 -> 636.73008 | G22: =费用!I31 -> 668.56658 | H22: =费用!J31 -> 701.99491
A23: 扣除广发基金后归母净利润 | C23: =费用!E47 -> 228.76458 | D23: =费用!F47 -> 419.01302 | E23: =费用!G47 -> 45.202348 | F23: =费用!H47 -> 115.2061 | G23: =费用!I47 -> 407.29057 | H23: =费用!J47 -> 451.33217
A24: EPS（元） | C24: =利润表!E33 -> 0.42629339 | D24: =利润表!F33 -> 0.59326911 | E24: =利润表!G33 -> 0.32089878 | F24: =利润表!H33 -> 0.55364024 | G24: =利润表!I33 -> 0.73928836 | H24: =利润表!J33 -> 0.79252277
A25: PE（现价） | C25: =假设!$C$8/利润表!E33 -> 83.745142 | D25: =假设!$C$8/利润表!F33 -> 60.175053 | E25: =假设!$C$8/利润表!G33 -> 111.25003 | F25: =假设!$C$8/利润表!H33 -> 64.482307 | G25: =假设!$C$8/利润表!I33 -> 48.289682 | H25: =假设!$C$8/利润表!J33 -> 45.046024
A26: ROE | C26: =利润表!E48 -> 0.03994201 | D26: =利润表!F48 -> 0.05181508 | E26: =利润表!G48 -> 0.027681914 | F26: =利润表!H48 -> 0.042129914 | G26: =利润表!I48 -> 0.053729334 | H26: =利润表!J48 -> 0.0517084
A27: 经营活动现金流 | C27: =现金流量表!E14 -> 59.1655 | D27: =现金流量表!F14 -> 4638.1759 | E27: =现金流量表!G14 -> 4772.5558 | F27: =现金流量表!H14 -> 1854.9649 | G27: =现金流量表!I14 -> 2483.0044 | H27: =现金流量表!J14 -> 2948.6133
A28: 资本开支（含资本化研发） | C28: =资本开支折旧!E72 -> 1202.9214 | D28: =资本开支折旧!F72 -> 1600.9212 | E28: =资本开支折旧!G72 -> 1710.5607 | F28: =资本开支折旧!H72 -> 1964.5516 | G28: =资本开支折旧!I72 -> 2349.626 | H28: =资本开支折旧!J72 -> 2228.9986
A29: 应收账款周转天数 | C29: =营运资本!E12 -> 145.53059 | D29: =营运资本!F12 -> 195.11176 | E29: =营运资本!G12 -> 216.94813 | F29: =营运资本!H12 -> 200 | G29: =营运资本!I12 -> 190 | H29: =营运资本!J12 -> 180
A30: 净负债 | C30: =融资!E19 -> 1791.1842 | D30: =融资!F19 -> 5034.7064 | E30: =融资!G19 -> 5247.5823 | F30: =融资!H19 -> 5739.031 | G30: =融资!I19 -> 3052.8433 | H30: =融资!J19 -> 2676.4591
A32: 估值汇总（元/股）
A33: 方法 | C33: 每股价值 | D33: 空间
A34: DCF（FCFF） | C34: =估值_DCF!$D$37 -> 15.647377 | D34: =IF(ISNUMBER(C34),C34/假设!$C$8-1,"n.m.") -> -0.56169812 | I34: WACC/永续增长见估值_DCF；对营运资本高度敏感
A35: SOTP（2027E分部PE+广发基金股权） | C35: =估值_SOTP!$E$44 -> 37.79882 | D35: =IF(ISNUMBER(C35),C35/假设!$C$8-1,"n.m.") -> 0.058790466 | I35: 光纤按周期折价PE；广发基金按15x PE
A36: 目标PE（2027E） | C36: =估值_相对!$C$39 -> 22.178651 | D36: =IF(ISNUMBER(C36),C36/假设!$C$8-1,"n.m.") -> -0.37874927 | I36: 目标PE见假设表
A37: 三种方法简单平均 | C37: =AVERAGE(C34:C36) -> 25.208283 | D37: =C37/假设!$C$8-1 -> -0.29388564
A39: 模型结构（工作表导航）
A40: 假设 | C40: 情景开关（1基准/2乐观/3悲观）、市场与估值参数、全部经营驱动假设（三情景）
A41: 分业务 | C41: 通信系统设备/光纤及线缆（量×价）/数据网络产品/其他：收入、成本、毛利；分地区；H1对比；成本构成
A42: 费用 | C42: 期间费用、研发投入与资本化、其他收益、减值、广发基金投资收益、盈利质量分析
A43: 资本开支折旧 | C43: 固定资产原值/累计折旧滚动、在建工程、无形资产、开发支出、D&A与资本开支汇总
A44: 营运资本 | C44: 应收/存货/预付/应付/合同负债等驱动与周转天数、净营运资本变动
A45: 融资 | C45: 现金、短期借款平衡项、长期借款、利息、股本与定增、分红、少数股东、偿债指标
...

Sheet 假设
A1: 核心假设与情景（百万元）
A2: 黄色单元格=情景开关/关键输入；蓝色=硬编码假设；“▶采用”行为模型实际引用的数值（随情景切换）；历史列为实际值（链接自各明细表）
A5: 情景选择（1=基准，2=乐观，3=悲观） | C5: 1 | D5: =CHOOSE($C$5,"基准","乐观","悲观") -> 基准 | O5: 切换后全模型重算；“情景分析”表为三种情景的快照对比
A7: 市场与估值参数
A8: 当前股价（元/股） | C8: 35.7 | O8: 2026-10-06 Wind一致预期页倒推：PE(2026E)37.50x × EPS 0.952 = 35.70；9/29收盘37.00（跌停）。可手动更新
A9: 估值基准日 | C9: 46301 | O9: 国庆休市，最后交易日约9/30
A10: DCF折现基准（2026年末） | C10: 46387 | O10: 先求2026年末价值，再按股权成本折回估值基准日
A11: 无风险利率 | C11: 0.019 | O11: 10年期国债收益率（假设，约1.8%–2.0%）
A12: 股权风险溢价 | C12: 0.065 | O12: A股常用5.5%–7%
A13: Beta | C13: 1.2 | O13: 通信设备/光纤高波动；52周区间21.34–87.58元
A14: 税前债务成本 | C14: 0.03 | O14: 2025年利息支出3.28亿/平均有息借款约108.7亿≈3.0%
A15: 目标债务占比 D/(D+E) | C15: 0.2 | O15: 按市值计约19%（2025年末有息负债116亿/(市值485亿+116亿)）
A16: WACC所用税率 | C16: 0.15 | O16: 高新技术企业15%
A17: 永续增长率 | C17: 0.02
A18: 广发基金持股比例 | C18: 0.14187 | O18: 2025年年报 附注十、3：14.187%，权益法
A19: 广发基金股权估值PE（x） | C19: 15 | O19: 公募基金公司股权交易常见10–20x PE；可调
A20: SOTP PE：通信系统设备（x） | C20: 25 | O20: 参考中兴通讯PE(TTM)36.7x（2026-08-10），考虑毛利率较低打折
A21: SOTP PE：光纤及线缆（x） | C21: 18 | O21: 景气高点盈利给周期性折价；亨通43x/中天34x/长飞109x（TTM，2026-09）
A22: SOTP PE：数据网络产品（x） | C22: 25 | O22: 烽火星空等软件/数据业务
A23: SOTP PE：其他业务（x） | C23: 10
A24: 费用分摊系数：通信系统设备 | C24: 1.15 | O24: 期间费用（含研发、财务费用）按“收入×系数”分摊至各分部
A25: 费用分摊系数：光纤及线缆 | C25: 0.5 | O25: 光纤光缆研发/销售强度低
A26: 费用分摊系数：数据网络产品 | C26: 1.2
A27: 费用分摊系数：其他业务 | C27: 0.5
A28: SOTP P/S下限：通信系统设备（x） | C28: 0.4 | O28: 分部亏损时按市销率兜底（运营商设备/服务器资产的重置与战略价值）
A29: SOTP P/S下限：光纤及线缆（x） | C29: 1
A30: SOTP P/S下限：数据网络产品（x） | C30: 1
A31: SOTP P/S下限：其他业务（x） | C31: 0.2
A32: 少数股东权益估值倍数（P/B） | C32: 1
A33: 相对估值目标PE（2027E，x） | C33: 30 | O33: 参考光通信/通信设备可比公司PE(TTM)中位数约40x，考虑盈利质量折价
A34: 最低现金余额（百万元） | C34: 4500 | O34: 低于此值以短期借款补足；高于此值优先偿还短期借款
A35: 短期借款下限（百万元） | C35: 3000 | O35: 维持银行授信与票据业务
A36: 长期借款中一年内到期比例 | C36: 0.1 | O36: 2025年末4.64/47.04亿≈9.9%
A37: 一年内到期的租赁负债（百万元） | C37: 59.958738 | O37: 2025年末一年内到期非流动负债524.37−长期借款一年内到期464.41
A38: 广发基金分红/上年权益法收益 | C38: 0.4 | O38: 2025年收到1.20亿/2024年收益2.84亿=42%；2026H1已收1.44亿
A39: 无形资产摊销中内部研发形成部分占比 | C39: 0.6 | O39: 2025年非专利技术摊销1.87亿/总摊销3.05亿=61%
A40: 2026年定增发行价（元/股） | C40: 30 | O40: 预案：不低于定价基准日前20日均价80%；假设值
A41: 定增发行费用率 | C41: 0.011 | O41: 参考2025年定增：费用690万/募资11.0亿≈0.6%；取1.1%保守
A43: 项目 | B43: 单位 | C43: 2021A | D43: 2022A | E43: 2023A | F43: 2024A | G43: 2025A | H43: 2026E | I43: 2027E | J43: 2028E | K43: 2029E | L43: 2030E | O43: 说明 / 来源
A44: 一、分业务驱动
...

Sheet 分业务
A1: 分业务收入与毛利拆分（百万元）
A2: 历史：年报“主营业务分产品情况”/Wind主营构成；预测：收入=上年×(1+增速)，光纤及线缆=上年×(1+销量)×(1+价格)；成本=收入×(1−毛利率)
A5: 项目 | B5: 百万元 | C5: 2021A | D5: 2022A | E5: 2023A | F5: 2024A | G5: 2025A | H5: 2026E | I5: 2027E | J5: 2028E | K5: 2029E | L5: 2030E | N5: 2026H1A | O5: 说明 / 来源
A6: 通信系统设备
A7: 通信系统设备 收入 | C7: 17086.233 | D7: 20915.791 | E7: 23785.164 | F7: 22313.409 | G7: 18654.767 | H7: =G7*(1+假设!H45) -> 19400.958 | I7: =H7*(1+假设!I45) -> 20953.035 | J7: =I7*(1+假设!J45) -> 22419.747 | K7: =J7*(1+假设!K45) -> 23764.932 | L7: =K7*(1+假设!L45) -> 24953.179 | N7: 8959.4508 | O7: 历史=年报分产品收入（Wind主营构成，万元÷100）
A8: 同比 | C8: 0.31695121 | D8: =D7/C7-1 -> 0.22413118 | E8: =E7/D7-1 -> 0.1371869 | F8: =F7/E7-1 -> -0.061877014 | G8: =G7/F7-1 -> -0.16396604 | H8: =H7/G7-1 -> 0.04 | I8: =I7/H7-1 -> 0.08 | J8: =J7/I7-1 -> 0.07 | K8: =K7/J7-1 -> 0.06 | L8: =L7/K7-1 -> 0.05 | N8: 0.026559395 | O8: 2021A同比按2020A收入计算；2026H1A为同比
A9: 通信系统设备 成本 | C9: 13798.047 | D9: 16635.676 | E9: 19208.68 | F9: 17972.216 | G9: 15145.138 | H9: =H7*(1-H11) -> 16723.626 | I9: =I7*(1-I11) -> 17851.986 | J9: =J7*(1-J11) -> 18877.427 | K9: =K7*(1-K11) -> 19843.718 | L9: =L7*(1-L11) -> 20835.904 | N9: 7617.8717
A10: 通信系统设备 毛利 | C10: =C7-C9 -> 3288.1865 | D10: =D7-D9 -> 4280.115 | E10: =E7-E9 -> 4576.4835 | F10: =F7-F9 -> 4341.1922 | G10: =G7-G9 -> 3509.6293 | H10: =H7-H9 -> 2677.3322 | I10: =I7-I9 -> 3101.0491 | J10: =J7-J9 -> 3542.3201 | ... L10: =L7-L9 -> 4117.2745 | N10: =N7-N9 -> 1341.5791
A11: 通信系统设备 毛利率 | C11: =IF(C7=0,0,C10/C7) -> 0.19244654 | D11: =IF(D7=0,0,D10/D7) -> 0.20463558 | E11: =IF(E7=0,0,E10/E7) -> 0.19240917 | F11: =IF(F7=0,0,F10/F7) -> 0.19455531 | G11: =IF(G7=0,0,G10/G7) -> 0.18813578 | H11: =假设!H49 -> 0.138 | I11: =假设!I49 -> 0.148 | J11: =假设!J49 -> 0.158 | K11: =假设!K49 -> 0.165 | L11: =假设!L49 -> 0.165 | N11: =IF(N7=0,0,N10/N7) -> 0.14973899
A12: 光纤及线缆
A13: 销量增速 | H13: =假设!H53 -> 0.1 | I13: =假设!I53 -> 0.08 | J13: =假设!J53 -> 0.07 | K13: =假设!K53 -> 0.05 | L13: =假设!L53 -> 0.04
A14: 均价变动 | H14: =假设!H57 -> 0.25 | I14: =假设!I57 -> -0.05 | J14: =假设!J57 -> -0.08 | K14: =假设!K57 -> -0.03 | L14: =假设!L57 -> 0
A15: 销量指数（2025A=100） | G15: 100 | H15: =G15*(1+H13) -> 110 | I15: =H15*(1+I13) -> 118.8 | J15: =I15*(1+J13) -> 127.116 | K15: =J15*(1+K13) -> 133.4718 | L15: =K15*(1+L13) -> 138.81067
A16: 价格指数（2025A=100） | G16: 100 | H16: =G16*(1+H14) -> 125 | I16: =H16*(1+I14) -> 118.75 | J16: =I16*(1+J14) -> 109.25 | K16: =J16*(1+K14) -> 105.9725 | L16: =K16*(1+L14) -> 105.9725
A17: 光纤及线缆 收入 | C17: 5849.9396 | D17: 6508.5623 | E17: 5386.6935 | F17: 4698.6346 | G17: 4654.0976 | H17: =G17*(1+H13)*(1+H14) -> 6399.3842 | I17: =H17*(1+I13)*(1+I14) -> 6565.7682 | J17: =I17*(1+J13)*(1+J14) -> 6463.3422 | K17: =J17*(1+K13)*(1+K14) -> 6582.914 | L17: =K17*(1+L13)*(1+L14) -> 6846.2306 | N17: 2964.6573 | O17: 历史=年报分产品收入（Wind主营构成，万元÷100）
A18: 同比 | C18: 0.11633456 | D18: =D17/C17-1 -> 0.11258624 | E18: =E17/D17-1 -> -0.17236814 | F18: =F17/E17-1 -> -0.12773307 | G18: =G17/F17-1 -> -0.0094787111 | H18: =H17/G17-1 -> 0.375 | I18: =I17/H17-1 -> 0.026 | J18: =J17/I17-1 -> -0.0156 | K18: =K17/J17-1 -> 0.0185 | L18: =L17/K17-1 -> 0.04 | N18: 0.47953322 | O18: 2021A同比按2020A收入计算；2026H1A为同比
A19: 光纤及线缆 成本 | C19: 4814.6501 | D19: 5373.902 | E19: 4242.6189 | F19: 3507.477 | G19: 3482.8701 | H19: =H17*(1-H21) -> 3839.6305 | I19: =I17*(1-I21) -> 4202.0916 | J19: =J17*(1-J21) -> 4459.7061 | K19: =K17*(1-K21) -> 4673.869 | L19: =L17*(1-L21) -> 4929.286 | N19: 1711.9269
A20: 光纤及线缆 毛利 | C20: =C17-C19 -> 1035.2895 | D20: =D17-D19 -> 1134.6603 | E20: =E17-E19 -> 1144.0746 | F20: =F17-F19 -> 1191.1576 | G20: =G17-G19 -> 1171.2275 | H20: =H17-H19 -> 2559.7537 | I20: =I17-I19 -> 2363.6765 | J20: =J17-J19 -> 2003.6361 | ... L20: =L17-L19 -> 1916.9446 | N20: =N17-N19 -> 1252.7304
A21: 光纤及线缆 毛利率 | C21: =IF(C17=0,0,C20/C17) -> 0.17697439 | D21: =IF(D17=0,0,D20/D17) -> 0.17433348 | E21: =IF(E17=0,0,E20/E17) -> 0.21238903 | F21: =IF(F17=0,0,F20/F17) -> 0.25351144 | G21: =IF(G17=0,0,G20/G17) -> 0.25165512 | H21: =假设!H61 -> 0.4 | I21: =假设!I61 -> 0.36 | J21: =假设!J61 -> 0.31 | K21: =假设!K61 -> 0.29 | L21: =假设!L61 -> 0.28 | N21: =IF(N17=0,0,N20/N17) -> 0.42255488
A22: 数据网络产品
A23: 数据网络产品 收入 | C23: 3038.8249 | D23: 3130.9817 | E23: 1577.1866 | F23: 1144.3846 | G23: 1419.619 | H23: =G23*(1+假设!H65) -> 1533.1885 | I23: =H23*(1+假设!I65) -> 1655.8436 | J23: =I23*(1+假设!J65) -> 1755.1942 | K23: =J23*(1+假设!K65) -> 1842.9539 | L23: =K23*(1+假设!L65) -> 1935.1016 | N23: 248.8312 | O23: 历史=年报分产品收入（Wind主营构成，万元÷100）
A24: 同比 | C24: 0.20496268 | D24: =D23/C23-1 -> 0.030326459 | E24: =E23/D23-1 -> -0.49626451 | F24: =F23/E23-1 -> -0.27441395 | G24: =G23/F23-1 -> 0.24050865 | H24: =H23/G23-1 -> 0.08 | I24: =I23/H23-1 -> 0.08 | J24: =J23/I23-1 -> 0.06 | K24: =K23/J23-1 -> 0.05 | L24: =L23/K23-1 -> 0.05 | N24: 0.12995331 | O24: 2021A同比按2020A收入计算；2026H1A为同比
A25: 数据网络产品 成本 | C25: 1724.5361 | D25: 1828.1968 | E25: 924.9509 | F25: 641.8028 | G25: 861.9252 | H25: =H23*(1-H27) -> 996.57254 | I25: =I23*(1-I27) -> 1043.1815 | J25: =J23*(1-J27) -> 1088.2204 | K25: =K23*(1-K27) -> 1142.6314 | L25: =L23*(1-L27) -> 1199.763 | N25: 233.8039
A26: 数据网络产品 毛利 | C26: =C23-C25 -> 1314.2888 | D26: =D23-D25 -> 1302.7849 | E26: =E23-E25 -> 652.2357 | F26: =F23-F25 -> 502.5818 | G26: =G23-G25 -> 557.6938 | H26: =H23-H25 -> 536.61598 | I26: =I23-I25 -> 612.66213 | J26: =J23-J25 -> 666.9738 | ... L26: =L23-L25 -> 735.33862 | N26: =N23-N25 -> 15.0273
A27: 数据网络产品 毛利率 | C27: =IF(C23=0,0,C26/C23) -> 0.43249902 | D27: =IF(D23=0,0,D26/D23) -> 0.4160947 | E27: =IF(E23=0,0,E26/E23) -> 0.41354377 | F27: =IF(F23=0,0,F26/F23) -> 0.43917211 | G27: =IF(G23=0,0,G26/G23) -> 0.39284752 | H27: =假设!H69 -> 0.35 | I27: =假设!I69 -> 0.37 | J27: =假设!J69 -> 0.38 | K27: =假设!K69 -> 0.38 | L27: =假设!L69 -> 0.38 | N27: =IF(N23=0,0,N26/N23) -> 0.060391543
A28: 其他业务
A29: 其他业务 收入 | C29: 339.9824 | D29: 362.5256 | E29: 380.5305 | F29: 392.4029 | G29: 190.0706 | H29: =G29*(1+假设!H73) -> 229.98543 | I29: =H29*(1+假设!I73) -> 229.98543 | J29: =I29*(1+假设!J73) -> 229.98543 | K29: =J29*(1+假设!K73) -> 229.98543 | L29: =K29*(1+假设!L73) -> 229.98543 | N29: 203.4191 | O29: 历史=年报分产品收入（Wind主营构成，万元÷100）
A30: 同比 | C30: 0.0055075089 | D30: =D29/C29-1 -> 0.066306962 | E30: =E29/D29-1 -> 0.049665182 | F30: =F29/E29-1 -> 0.031199602 | G30: =G29/F29-1 -> -0.51562387 | H30: =H29/G29-1 -> 0.21 | I30: =I29/H29-1 -> 0 | J30: =J29/I29-1 -> 0 | K30: =K29/J29-1 -> 0 | L30: =L29/K29-1 -> 0 | N30: 0.23150852 | O30: 2021A同比按2020A收入计算；2026H1A为同比
A31: 其他业务 成本 | C31: 267.8126 | D31: 288.9058 | E31: 351.8755 | F31: 361.1676 | G31: 171.2948 | H31: =H29*(1-H33) -> 202.38717 | I31: =I29*(1-I33) -> 202.38717 | J31: =J29*(1-J33) -> 202.38717 | K31: =K29*(1-K33) -> 202.38717 | L31: =L29*(1-L33) -> 202.38717 | N31: 164.2589
A32: 其他业务 毛利 | C32: =C29-C31 -> 72.1698 | D32: =D29-D31 -> 73.6198 | E32: =E29-E31 -> 28.655 | F32: =F29-F31 -> 31.2353 | G32: =G29-G31 -> 18.7758 | H32: =H29-H31 -> 27.598251 | I32: =I29-I31 -> 27.598251 | J32: =J29-J31 -> 27.598251 | ... L32: =L29-L31 -> 27.598251 | N32: =N29-N31 -> 39.1602
A33: 其他业务 毛利率 | C33: =IF(C29=0,0,C32/C29) -> 0.21227511 | D33: =IF(D29=0,0,D32/D29) -> 0.20307476 | E33: =IF(E29=0,0,E32/E29) -> 0.075302768 | F33: =IF(F29=0,0,F32/F29) -> 0.079600074 | G33: =IF(G29=0,0,G32/G29) -> 0.098783294 | H33: =假设!H77 -> 0.12 | I33: =假设!I77 -> 0.12 | J33: =假设!J77 -> 0.12 | K33: =假设!K77 -> 0.12 | L33: =假设!L77 -> 0.12 | N33: =IF(N29=0,0,N32/N29) -> 0.19250995
A34: 合计
A35: 营业收入合计 | C35: =C7+C17+C23+C29 -> 26314.98 | D35: =D7+D17+D23+D29 -> 30917.861 | E35: =E7+E17+E23+E29 -> 31129.574 | F35: =F7+F17+F23+F29 -> 28548.831 | G35: =G7+G17+G23+G29 -> 24918.555 | H35: =H7+H17+H23+H29 -> 27563.516 | I35: =I7+I17+I23+I29 -> 29404.632 | J35: =J7+J17+J23+J29 -> 30868.269 | ... L35: =L7+L17+L23+L29 -> 33964.496 | N35: =N7+N17+N23+N29 -> 12376.358
A36: 同比 | C36: 0.24866823 | D36: =D35/C35-1 -> 0.17491483 | E36: =E35/D35-1 -> 0.0068476148 | F36: =F35/E35-1 -> -0.082903267 | G36: =G35/F35-1 -> -0.12716024 | H36: =H35/G35-1 -> 0.10614426 | I36: =I35/H35-1 -> 0.066795386 | J36: =J35/I35-1 -> 0.049775731 | K36: =K35/J35-1 -> 0.050294896 | L36: =L35/K35-1 -> 0.047614851 | N36: 0.11330014
A37: 营业成本合计 | C37: =C9+C19+C25+C31 -> 20605.046 | D37: =D9+D19+D25+D31 -> 24126.681 | E37: =E9+E19+E25+E31 -> 24728.125 | F37: =F9+F19+F25+F31 -> 22482.664 | G37: =G9+G19+G25+G31 -> 19661.228 | H37: =H9+H19+H25+H31 -> 21762.216 | I37: =I9+I19+I25+I31 -> 23299.646 | J37: =J9+J19+J25+J31 -> 24627.741 | ... L37: =L9+L19+L25+L31 -> 27167.34 | N37: =N9+N19+N25+N31 -> 9727.8614
A38: 毛利合计 | C38: =C35-C37 -> 5709.9346 | D38: =D35-D37 -> 6791.18 | E38: =E35-E37 -> 6401.4488 | F38: =F35-F37 -> 6066.1669 | G38: =G35-G37 -> 5257.3264 | H38: =H35-H37 -> 5801.3001 | I38: =I35-I37 -> 6104.9861 | J38: =J35-J37 -> 6240.5282 | ... L38: =L35-L37 -> 6797.1559 | N38: =N35-N37 -> 2648.497
A39: 综合毛利率 | C39: =C38/C35 -> 0.21698419 | D39: =D38/D35 -> 0.21965233 | E39: =E38/E35 -> 0.20563882 | F39: =F38/F35 -> 0.2124839 | G39: =G38/G35 -> 0.21098039 | H39: =H38/H35 -> 0.21047025 | I39: =I38/I35 -> 0.20761988 | J39: =J38/J35 -> 0.20216644 | ... L39: =L38/L35 -> 0.20012533 | N39: =N38/N35 -> 0.21399647
A40: 核对：分部合计−报表营业收入 | C40: =C35-历史报表!E8 -> -0.0001 | D40: =D35-历史报表!F8 -> 0 | E40: =E35-历史报表!G8 -> -9.9999997e-05 | F40: =F35-历史报表!H8 -> -9.9999997e-05 | G40: =G35-历史报表!I8 -> 0.0001 | N40: =N35-历史报表!K8 -> 0 | O40: 应为0
A41: 收入结构与毛利贡献
A42: 通信系统设备 收入占比 | C42: =C7/C35 -> 0.64929683 | D42: =D7/D35 -> 0.67649542 | E42: =E7/E35 -> 0.76406967 | F42: =F7/F35 -> 0.78158748 | G42: =G7/G35 -> 0.74862959 | H42: =H7/H35 -> 0.70386368 | I42: =I7/I35 -> 0.71257599 | J42: =J7/J35 -> 0.726304 | ... L42: =L7/L35 -> 0.7346842 | N42: =N7/N35 -> 0.72391656
...

Sheet 费用
A1: 费用、其他损益与盈利质量（百万元）
A2: 费用以正数列示；减值损失以负数列示；预测=收入×比率（比率链接“假设”）
A5: 项目 | B5: 百万元 | C5: 2021A | D5: 2022A | E5: 2023A | F5: 2024A | G5: 2025A | H5: 2026E | I5: 2027E | J5: 2028E | K5: 2029E | L5: 2030E | N5: 2026H1A | O5: 说明 / 来源
A6: 营业收入 | C6: =利润表!C6 -> 26314.98 | D6: =利润表!D6 -> 30917.861 | E6: =利润表!E6 -> 31129.574 | F6: =利润表!F6 -> 28548.831 | G6: =利润表!G6 -> 24918.554 | H6: =利润表!H6 -> 27563.516 | I6: =利润表!I6 -> 29404.632 | J6: =利润表!J6 -> 30868.269 | ... L6: =利润表!L6 -> 33964.496 | N6: =利润表!N6 -> 12376.358
A7: 期间费用
A8: 税金及附加 | C8: =历史报表!E11 -> 88.2078 | D8: =历史报表!F11 -> 102.0822 | E8: =历史报表!G11 -> 109.2552 | F8: =历史报表!H11 -> 116.2267 | G8: =历史报表!I11 -> 109.8429 | H8: =H6*H9 -> 137.81758 | I8: =I6*I9 -> 147.02316 | J8: =J6*J9 -> 154.34135 | K8: =K6*K9 -> 162.10393 | L8: =L6*L9 -> 169.82248 | N8: =历史报表!K11 -> 79.0084
A9: 占收入比 | C9: =C8/C6 -> 0.0033519995 | D9: =D8/D6 -> 0.0033017226 | E9: =E8/E6 -> 0.0035096914 | F9: =F8/F6 -> 0.0040711545 | G9: =G8/G6 -> 0.0044080767 | H9: =假设!H82 -> 0.005 | I9: =假设!I82 -> 0.005 | J9: =假设!J82 -> 0.005 | K9: =假设!K82 -> 0.005 | L9: =假设!L82 -> 0.005 | N9: =N8/N6 -> 0.0063838164
A10: 销售费用 | C10: =历史报表!E12 -> 1417.9454 | D10: =历史报表!F12 -> 1645.9351 | E10: =历史报表!G12 -> 1786.6738 | F10: =历史报表!H12 -> 1881.3582 | G10: =历史报表!I12 -> 1975.6587 | H10: =H6*H11 -> 2094.8272 | I10: =I6*I11 -> 2146.5381 | J10: =J6*J11 -> 2160.7788 | K10: =K6*K11 -> 2204.6134 | L10: =L6*L11 -> 2241.6568 | N10: =历史报表!K12 -> 1061.5176
A11: 占收入比 | C11: =C10/C6 -> 0.053883582 | D11: =D10/D6 -> 0.053235737 | E11: =E10/E6 -> 0.057394739 | F11: =F10/F6 -> 0.065899658 | G11: =G10/G6 -> 0.079284643 | H11: =假设!H86 -> 0.076 | I11: =假设!I86 -> 0.073 | J11: =假设!J86 -> 0.07 | K11: =假设!K86 -> 0.068 | L11: =假设!L86 -> 0.066 | N11: =N10/N6 -> 0.085769785
A12: 管理费用 | C12: =历史报表!E13 -> 294.4026 | D12: =历史报表!F13 -> 328.6322 | E12: =历史报表!G13 -> 341.013 | F12: =历史报表!H13 -> 439.5538 | G12: =历史报表!I13 -> 484.3899 | H12: =H6*H13 -> 523.70681 | I12: =I6*I13 -> 543.98569 | J12: =J6*J13 -> 555.62884 | K12: =K6*K13 -> 583.57414 | L12: =L6*L13 -> 611.36093 | N12: =历史报表!K13 -> 190.1205
A13: 占收入比 | C13: =C12/C6 -> 0.011187643 | D13: =D12/D6 -> 0.010629202 | E13: =E12/E6 -> 0.010954631 | F13: =F12/F6 -> 0.01539656 | G13: =G12/G6 -> 0.019438925 | H13: =假设!H90 -> 0.019 | I13: =假设!I90 -> 0.0185 | J13: =假设!J90 -> 0.018 | K13: =假设!K90 -> 0.018 | L13: =假设!L90 -> 0.018 | N13: =N12/N6 -> 0.015361586
A14: 研发投入与资本化
A15: 研发投入总额 | C15: 3725.7363 | D15: 4393.6838 | E15: 3856.4953 | F15: 3578.1044 | G15: 3157.9247 | H15: =H6*H16 -> 3087.1138 | I15: =I6*I16 -> 3175.7003 | J15: =J6*J16 -> 3241.1682 | K15: =K6*K16 -> 3339.3409 | L15: =L6*L16 -> 3464.3786 | O15: 年报“研发投入情况表”
A16: 研发投入/收入 | C16: =C15/C6 -> 0.14158233 | D16: =D15/D6 -> 0.14210827 | E16: =E15/E6 -> 0.12388526 | F16: =F15/F6 -> 0.12533278 | G16: =G15/G6 -> 0.12672985 | H16: =假设!H94 -> 0.112 | I16: =假设!I94 -> 0.108 | J16: =假设!J94 -> 0.105 | K16: =假设!K94 -> 0.103 | L16: =假设!L94 -> 0.102
A17: 其中：资本化研发投入（计入开发支出） | C17: 265.30533 | D17: 291.90181 | E17: 278.16409 | F17: 696.85401 | G17: 587.82641 | H17: =H15*H18 -> 586.55163 | I17: =I15*I18 -> 571.62605 | J17: =J15*J18 -> 550.9986 | K17: =K15*K18 -> 534.29454 | L17: =L15*L18 -> 519.65679
A18: 研发资本化率 | C18: =C17/C15 -> 0.071208832 | D18: =D17/D15 -> 0.06643669 | E18: =E17/E15 -> 0.072128726 | F18: =F17/F15 -> 0.19475508 | G18: =G17/G15 -> 0.18614326 | H18: =假设!H98 -> 0.19 | I18: =假设!I98 -> 0.18 | J18: =假设!J98 -> 0.17 | K18: =假设!K98 -> 0.16 | L18: =假设!L98 -> 0.15 | O18: 2021–2023年约7%，2024年起升至19%左右
A19: 研发费用（费用化部分，计入利润表） | C19: =历史报表!E14 -> 3460.4309 | D19: =历史报表!F14 -> 4101.782 | E19: =历史报表!G14 -> 3578.3312 | F19: =历史报表!H14 -> 2881.2504 | G19: =历史报表!I14 -> 2570.0983 | H19: =H15-H17 -> 2500.5622 | I19: =I15-I17 -> 2604.0742 | J19: =J15-J17 -> 2690.1696 | K19: =K15-K17 -> 2805.0464 | L19: =L15-L17 -> 2944.7218 | N19: =历史报表!K14 -> 1269.9684
A20: 核对：投入−资本化−费用化 | C20: =C15-C17-C19 -> 3.9e-05 | D20: =D15-D17-D19 -> -5e-05 | E20: =E15-E17-E19 -> -2e-05 | F20: =F15-F17-F19 -> 1.6e-05 | G20: =G15-G17-G19 -> -4.6e-05 | O20: 应≈0
A21: 其他收益与减值
A22: 其他收益（政府补助、增值税退税等） | C22: =历史报表!E18 -> 260.0848 | D22: =历史报表!F18 -> 275.016 | E22: =历史报表!G18 -> 447.9878 | F22: =历史报表!H18 -> 771.2192 | G22: =历史报表!I18 -> 722.6505 | H22: =H6*H23 -> 606.39736 | I22: =I6*I23 -> 588.09264 | J22: =J6*J23 -> 586.49711 | K22: =K6*K23 -> 583.57414 | L22: =L6*L23 -> 611.36093 | N22: =历史报表!K18 -> 219.0644 | O22: 2025年：政府补助5.71亿+税收返还1.52亿
A23: 占收入比 | C23: =C22/C6 -> 0.0098835263 | D23: =D22/D6 -> 0.0088950527 | E23: =E22/E6 -> 0.014391067 | F23: =F22/F6 -> 0.027014038 | G23: =G22/G6 -> 0.029000498 | H23: =假设!H102 -> 0.022 | I23: =假设!I102 -> 0.02 | J23: =假设!J102 -> 0.019 | K23: =假设!K102 -> 0.018 | L23: =假设!L102 -> 0.018 | N23: =N22/N6 -> 0.017700231
A24: 信用减值损失 | C24: =历史报表!E24 -> -17.4286 | D24: =历史报表!F24 -> -232.8913 | E24: =历史报表!G24 -> -291.6802 | F24: =历史报表!H24 -> -345.4449 | G24: =历史报表!I24 -> -81.4387 | H24: =H6*H25 -> -192.94461 | I24: =I6*I25 -> -176.42779 | J24: =J6*J25 -> -185.20961 | K24: =K6*K25 -> -194.52471 | L24: =L6*L25 -> -203.78698 | N24: =历史报表!K24 -> 4.1395
A25: 占收入比 | C25: =C24/C6 -> -0.00066230717 | D25: =D24/D6 -> -0.0075325813 | E25: =E24/E6 -> -0.0093698744 | F25: =F24/F6 -> -0.012100142 | G25: =G24/G6 -> -0.0032681952 | H25: =假设!H106 -> -0.007 | I25: =假设!I106 -> -0.006 | J25: =假设!J106 -> -0.006 | K25: =假设!K106 -> -0.006 | L25: =假设!L106 -> -0.006
A26: 资产减值损失 | C26: =历史报表!E23 -> -239.801 | D26: =历史报表!F23 -> -122.3486 | E26: =历史报表!G23 -> -147.8754 | F26: =历史报表!H23 -> -107.2242 | G26: =历史报表!I23 -> -294.1611 | H26: =H6*H27 -> -192.94461 | I26: =I6*I27 -> -176.42779 | J26: =J6*J27 -> -185.20961 | K26: =K6*K27 -> -194.52471 | L26: =L6*L27 -> -203.78698 | N26: =历史报表!K23 -> -44.045
A27: 占收入比 | C27: =C26/C6 -> -0.0091127182 | D27: =D26/D6 -> -0.0039572143 | E27: =E26/E6 -> -0.0047503187 | F27: =F26/F6 -> -0.0037558175 | G27: =G26/G6 -> -0.011804902 | H27: =假设!H110 -> -0.007 | I27: =假设!I110 -> -0.006 | J27: =假设!J110 -> -0.006 | K27: =假设!K110 -> -0.006 | L27: =假设!L110 -> -0.006
A28: 投资收益：广发基金（14.187%，权益法）
A29: 广发基金净利润 | C29: 2586.93 | D29: 2133.57 | E29: 1949.69 | F29: 1999.67 | G29: 2753.45 | H29: =G29*(1+H30) -> 4488.1235 | I29: =H29*(1+I30) -> 4712.5297 | J29: =I29*(1+J30) -> 4948.1562 | K29: =J29*(1+K30) -> 5195.564 | L29: =K29*(1+L30) -> 5455.3422 | N29: 2458.57 | O29: 烽火通信年报附注“重要联营企业的主要财务信息”；2026H1A为半年数
A30: 同比 | C30: 0.41831968 | D30: =D29/C29-1 -> -0.1752502 | E30: =E29/D29-1 -> -0.086184189 | F30: =F29/E29-1 -> 0.025634845 | G30: =G29/F29-1 -> 0.3769522 | H30: =假设!H114 -> 0.63 | I30: =假设!I114 -> 0.05 | J30: =假设!J114 -> 0.05 | K30: =假设!K114 -> 0.05 | L30: =假设!L114 -> 0.05 | N30: 1.0838341
A31: 烽火应享权益法收益（=净利润×持股比例） | C31: =C29*假设!$C$18 -> 367.00776 | D31: =D29*假设!$C$18 -> 302.68958 | E31: =E29*假设!$C$18 -> 276.60252 | F31: =F29*假设!$C$18 -> 283.69318 | G31: =G29*假设!$C$18 -> 390.63195 | H31: =H29*假设!$C$18 -> 636.73008 | I31: =I29*假设!$C$18 -> 668.56658 | J31: =J29*假设!$C$18 -> 701.99491 | ... L31: =L29*假设!$C$18 -> 773.94939 | N31: =N29*假设!$C$18 -> 348.79733
A32: 收到广发基金现金分红 | D32: 160 | E32: 180 | F32: 120 | G32: 120 | H32: 144 | I32: =H31*假设!$C$38 -> 254.69203 | J32: =I31*假设!$C$38 -> 267.42663 | K32: =J31*假设!$C$38 -> 280.79797 | L32: =K31*假设!$C$38 -> 294.83786 | N32: 144 | O32: 2026E=2026H1已收1.44亿
A33: 长期股权投资—广发基金账面价值 | E33: 1519.73 | F33: 1684.08 | G33: 1953.76 | H33: =G33+H31-H32 -> 2446.4901 | I33: =H33+I31-I32 -> 2860.3646 | J33: =I33+J31-J32 -> 3294.9329 | K33: =J33+K31-K32 -> 3751.2296 | L33: =K33+L31-L32 -> 4230.3411 | N33: 2156.75
A34: 投资收益合计及其他损益
A35: 权益法投资收益合计 | C35: =历史报表!E20 -> 402.1722 | D35: =历史报表!F20 -> 378.8812 | E35: =历史报表!G20 -> 325.9203 | F35: =历史报表!H20 -> 285.6265 | G35: =历史报表!I20 -> 442.3 | H35: =H31+H36 -> 686.73008 | I35: =I31+I36 -> 718.56658 | J35: =J31+J36 -> 751.99491 | K35: =K31+K36 -> 787.09466 | L35: =L31+L36 -> 823.94939 | N35: =历史报表!K20 -> 400.0886
A36: 其中：其他联营企业 | C36: =C35-C31 -> 35.164441 | D36: =D35-D31 -> 76.191624 | E36: =E35-E31 -> 49.31778 | F36: =F35-F31 -> 1.9333171 | G36: =G35-G31 -> 51.668049 | H36: =假设!H118 -> 50 | I36: =假设!I118 -> 50 | J36: =假设!J118 -> 50 | K36: =假设!K118 -> 50 | L36: =假设!L118 -> 50 | N36: =N35-N31 -> 51.291274
A37: 其他投资收益（含票据终止确认损失） | C37: =历史报表!E19-C35 -> 0.3954 | D37: =历史报表!F19-D35 -> 10.7646 | E37: =历史报表!G19-E35 -> -24.0725 | F37: =历史报表!H19-F35 -> 2.1588 | G37: =历史报表!I19-G35 -> 2.8525 | H37: =假设!H122 -> -25 | I37: =假设!I122 -> -25 | J37: =假设!J122 -> -25 | K37: =假设!K122 -> -25 | L37: =假设!L122 -> -25 | N37: =历史报表!K19-N35 -> -11.1528
A38: 投资收益合计 | C38: =C35+C37 -> 402.5676 | D38: =D35+D37 -> 389.6458 | E38: =E35+E37 -> 301.8478 | F38: =F35+F37 -> 287.7853 | G38: =G35+G37 -> 445.1525 | H38: =H35+H37 -> 661.73008 | I38: =I35+I37 -> 693.56658 | J38: =J35+J37 -> 726.99491 | ... L38: =L35+L37 -> 798.94939 | N38: =N35+N37 -> 388.9358
A39: 公允价值变动收益 | C39: =历史报表!E22 -> 2.7352 | D39: =历史报表!F22 -> -2.4842 | E39: =历史报表!G22 -> 0.3342 | F39: =历史报表!H22 -> 0.269 | G39: =历史报表!I22 -> -12.6198 | H39: 0 | I39: 0 | J39: 0 | K39: 0 | L39: 0 | N39: =历史报表!K22 -> 0
A40: 资产处置收益 | C40: =历史报表!E25 -> 1.838 | D40: =历史报表!F25 -> 4.1996 | E40: =历史报表!G25 -> -14.9768 | F40: =历史报表!H25 -> 6.6168 | G40: =历史报表!I25 -> 0.4398 | H40: 0 | I40: 0 | J40: 0 | K40: 0 | L40: 0 | N40: =历史报表!K25 -> -0.3458
A41: 营业外收支净额 | C41: =历史报表!E27-历史报表!E28 -> -2.6277 | D41: =历史报表!F27-历史报表!F28 -> -0.9538 | E41: =历史报表!G27-历史报表!G28 -> 15.0161 | F41: =历史报表!H27-历史报表!H28 -> -11.2164 | G41: =历史报表!I27-历史报表!I28 -> -11.1238 | H41: =假设!H126 -> -10 | I41: =假设!I126 -> -10 | J41: =假设!J126 -> -10 | K41: =假设!K126 -> -10 | L41: =假设!L126 -> -10 | N41: =历史报表!K27-历史报表!K28 -> 1.4673
A42: 实际所得税率 | C42: =历史报表!E30/历史报表!E29 -> 0.27575799 | D42: =历史报表!F30/历史报表!F29 -> 0.24273553 | E42: =历史报表!G30/历史报表!G29 -> 0.15905757 | F42: =历史报表!H30/历史报表!H29 -> 0.10343917 | G42: =历史报表!I30/历史报表!I29 -> 0.18610153 | H42: =假设!H130 -> 0.13 | I42: =假设!I130 -> 0.13 | J42: =假设!J130 -> 0.13 | K42: =假设!K130 -> 0.13 | L42: =假设!L130 -> 0.13 | N42: =历史报表!K30/历史报表!K29 -> 0.2325974
...

Sheet 资本开支折旧
A1: 投资、固定资产与折旧摊销（百万元）
A2: 历史：年报附注固定资产/无形资产/开发支出变动表；预测：在建工程→转固→按原值计提折旧；资本化研发→开发支出→无形资产→摊销
A5: 项目 | B5: 百万元 | C5: 2021A | D5: 2022A | E5: 2023A | F5: 2024A | G5: 2025A | H5: 2026E | I5: 2027E | J5: 2028E | K5: 2029E | L5: 2030E | N5: 2026H1A | O5: 说明 / 来源
A6: 固定资产原值
A7: 期初原值 | C7: 6244.3305 | D7: =C12 -> 6739.3251 | E7: =D12 -> 7360.7014 | F7: =E12 -> 8208.4852 | G7: =F12 -> 8109.039 | H7: =G12 -> 8535.4324 | I7: =H12 -> 9580.9576 | J7: =I12 -> 10833.04 | K7: =J12 -> 12141.542 | L7: =K12 -> 13244.918 | N7: 8535.4324
A8: + 直接购置 | C8: 391.41101 | D8: 418.78004 | E8: 391.74527 | F8: 248.55301 | G8: 224.39685 | H8: 0 | I8: 0 | J8: 0 | K8: 0 | L8: 0 | N8: 323.77315 | O8: 预测期假设全部经在建工程转入
A9: + 在建工程转入 | C9: 256.72105 | D9: 406.12671 | E9: 801.90355 | F9: 93.839617 | G9: 356.72407 | H9: =H28 -> 1199.1631 | I9: =I28 -> 1424.5397 | J9: =J28 -> 1503.4968 | K9: =K28 -> 1321.9233 | L9: =L28 -> 1132.0578 | N9: 451.40111
A10: + 其他（企业合并/汇率/重分类，轧差） | C10: -2.2737368e-13 | D10: 2.6614868 | E10: 6.4101029 | F10: 87.662271 | G10: -3.4346921 | H10: 0 | I10: 0 | J10: 0 | K10: 0 | L10: 0
A11: − 处置/报废 | C11: 153.13744 | D11: 206.19192 | E11: 352.27517 | F11: 529.50114 | G11: 151.29281 | H11: =H7*H23 -> 153.63778 | I11: =I7*I23 -> 172.45724 | J11: =J7*J23 -> 194.99472 | K11: =K7*K23 -> 218.54776 | L11: =L7*L23 -> 238.40852 | N11: 72.159974
A12: 期末原值 | C12: =C7+C8+C9+C10-C11 -> 6739.3251 | D12: =D7+D8+D9+D10-D11 -> 7360.7014 | E12: =E7+E8+E9+E10-E11 -> 8208.4852 | F12: =F7+F8+F9+F10-F11 -> 8109.039 | G12: =G7+G8+G9+G10-G11 -> 8535.4324 | H12: =H7+H8+H9+H10-H11 -> 9580.9576 | I12: =I7+I8+I9+I10-I11 -> 10833.04 | J12: =J7+J8+J9+J10-J11 -> 12141.542 | ... L12: =L7+L8+L9+L10-L11 -> 14138.567 | N12: 9238.4467
A13: 累计折旧
A14: 期初累计折旧 | C14: 2882.0809 | D14: =C18 -> 3273.8431 | E14: =D18 -> 3680.8563 | F14: =E18 -> 4013.2494 | G14: =F18 -> 4345.515 | H14: =G18 -> 4926.1414 | I14: =H18 -> 5558.1148 | J14: =I18 -> 6270.8751 | K14: =J18 -> 7072.1722 | L14: =K18 -> 7954.6398 | N14: 4926.1414
A15: + 本期计提折旧 | C15: 537.45957 | D15: 482.38679 | E15: 657.70459 | F15: 689.9163 | G15: 704.60417 | H15: =H22*(H7+0.5*(H8+H9)) -> 785.6112 | I15: =I22*(I7+0.5*(I8+I9)) -> 885.21756 | J15: =J22*(J7+0.5*(J8+J9)) -> 996.29181 | K15: =K22*(K7+0.5*(K8+K9)) -> 1101.0153 | L15: =L22*(L7+0.5*(L8+L9)) -> 1187.7414 | N15: 403.5562
A16: + 其他（轧差） | C16: -2.2737368e-13 | D16: 0.29455668 | E16: 3.6729557 | F16: 160.68636 | G16: -2.2478351 | H16: 0 | I16: 0 | J16: 0 | K16: 0 | L16: 0
A17: − 处置/报废转出 | C17: 145.69746 | D17: 75.668146 | E17: 328.98436 | F17: 518.33706 | G17: 121.72997 | H17: =H11 -> 153.63778 | I17: =I11 -> 172.45724 | J17: =J11 -> 194.99472 | K17: =K11 -> 218.54776 | L17: =L11 -> 238.40852 | N17: 64.900082 | O17: 预测假设报废资产已提足折旧
A18: 期末累计折旧 | C18: =C14+C15+C16-C17 -> 3273.8431 | D18: =D14+D15+D16-D17 -> 3680.8563 | E18: =E14+E15+E16-E17 -> 4013.2494 | F18: =F14+F15+F16-F17 -> 4345.515 | G18: =G14+G15+G16-G17 -> 4926.1414 | H18: =H14+H15+H16-H17 -> 5558.1148 | I18: =I14+I15+I16-I17 -> 6270.8751 | J18: =J14+J15+J16-J17 -> 7072.1722 | ... L18: =L14+L15+L16-L17 -> 8903.9727 | N18: 5264.7975
A19: 减值准备（历史含尾差） | C19: =C12-C18-历史报表!E59 -> 6.5134798 | D19: =D12-D18-历史报表!F59 -> 6.5134857 | E19: =E12-E18-历史报表!G59 -> 0.98285974 | F19: =F12-F18-历史报表!H59 -> 0.84972134 | G19: =G12-G18-历史报表!I59 -> 0.84977073 | H19: =G19 -> 0.84977073 | I19: =H19 -> 0.84977073 | J19: =I19 -> 0.84977073 | K19: =J19 -> 0.84977073 | L19: =K19 -> 0.84977073 | N19: 0.84973506 | O19: 历史=原值−累计折旧−报表净值（附注减值准备0.8亿元级，差额为四舍五入）
A20: 固定资产净值 | C20: =C12-C18-C19 -> 3458.9686 | D20: =D12-D18-D19 -> 3673.3317 | E20: =E12-E18-E19 -> 4194.2529 | F20: =F12-F18-F19 -> 3762.6742 | G20: =G12-G18-G19 -> 3608.4412 | H20: =H12-H18-H19 -> 4021.9931 | I20: =I12-I18-I19 -> 4561.3152 | J20: =J12-J18-J19 -> 5068.5202 | ... L20: =L12-L18-L19 -> 5233.7445 | N20: =N12-N18-N19 -> 3972.7994
A21: 核对：净值−资产负债表 | C21: =C20-历史报表!E59 -> 0 | D21: =D20-历史报表!F59 -> 0 | E21: =E20-历史报表!G59 -> 0 | F21: =F20-历史报表!H59 -> 0 | G21: =G20-历史报表!I59 -> 0 | N21: =N20-历史报表!K59 -> -2.3299999e-06
A22: 折旧率（折旧/(期初原值+½新增)） | C22: =C15/(C7+0.5*(C8+C9)) -> 0.08182508 | D22: =D15/(D7+0.5*(D8+D9)) -> 0.067449907 | E22: =E15/(E7+0.5*(E8+E9)) -> 0.082651895 | F22: =F15/(F7+0.5*(F8+F9)) -> 0.082332043 | G22: =G15/(G7+0.5*(G8+G9)) -> 0.08388545 | H22: =假设!H151 -> 0.086 | I22: =假设!I151 -> 0.086 | J22: =假设!J151 -> 0.086 | K22: =假设!K151 -> 0.086 | L22: =假设!L151 -> 0.086
A23: 报废率（报废原值/期初原值） | C23: =C11/C7 -> 0.024524236 | D23: =D11/D7 -> 0.030595337 | E23: =E11/E7 -> 0.047858913 | F23: =F11/F7 -> 0.06450656 | G23: =G11/G7 -> 0.018657305 | H23: =假设!H155 -> 0.018 | I23: =假设!I155 -> 0.018 | J23: =假设!J155 -> 0.018 | K23: =假设!K155 -> 0.018 | L23: =假设!L155 -> 0.018
A24: 已提折旧比例（成新率反向指标） | C24: =C18/C12 -> 0.48578203 | D24: =D18/D12 -> 0.50006868 | E24: =E18/E12 -> 0.48891474 | F24: =F18/F12 -> 0.53588533 | G24: =G18/G12 -> 0.57714023 | H24: =H18/H12 -> 0.58012101 | I24: =I18/I12 -> 0.57886568 | J24: =J18/J12 -> 0.58247726 | ... L24: =L18/L12 -> 0.62976486
A25: 在建工程
A26: 期初余额 | C26: 877.2857 | D26: =C30 -> 1191.0416 | E26: =D30 -> 916.072 | F26: =E30 -> 429.2772 | G26: =F30 -> 889.8926 | H26: =G30 -> 1364.8068 | I26: =H30 -> 1465.6437 | J26: =I30 -> 1741.1041 | K26: =J30 -> 1837.6072 | L26: =K30 -> 1615.684
A27: + 本期投入 | C27: =C30-C26+C28+C29 -> 570.47695 | D27: =D30-D26+D28+D29 -> 296.40205 | E27: =E30-E26+E28+E29 -> 315.10875 | F27: =F30-F26+F28+F29 -> 554.45502 | G27: =G30-G26+G28+G29 -> 831.63827 | H27: =假设!H139 -> 1300 | I27: =假设!I139 -> 1700 | J27: =假设!J139 -> 1600 | K27: =假设!K139 -> 1100 | L27: =假设!L139 -> 900 | O27: 历史为轧差推算
A28: − 转入固定资产 | C28: =C9 -> 256.72105 | D28: =D9 -> 406.12671 | E28: =E9 -> 801.90355 | F28: =F9 -> 93.839617 | G28: =G9 -> 356.72407 | H28: =(H26+H27)*H31 -> 1199.1631 | I28: =(I26+I27)*I31 -> 1424.5397 | J28: =(J26+J27)*J31 -> 1503.4968 | K28: =(K26+K27)*K31 -> 1321.9233 | L28: =(L26+L27)*L31 -> 1132.0578
A29: − 转入无形资产等 | C29: 0 | D29: 165.24494 | E29: 0 | F29: 0 | G29: 0 | H29: 0 | I29: 0 | J29: 0 | K29: 0 | L29: 0
A30: 期末余额 | C30: =历史报表!E61 -> 1191.0416 | D30: =历史报表!F61 -> 916.072 | E30: =历史报表!G61 -> 429.2772 | F30: =历史报表!H61 -> 889.8926 | G30: =历史报表!I61 -> 1364.8068 | H30: =H26+H27-H28-H29 -> 1465.6437 | I30: =I26+I27-I28-I29 -> 1741.1041 | J30: =J26+J27-J28-J29 -> 1837.6072 | K30: =K26+K27-K28-K29 -> 1615.684 | L30: =L26+L27-L28-L29 -> 1383.6262 | N30: =历史报表!K61 -> 1155.3614
A31: 转固比例 | C31: =C28/(C26+C27) -> 0.17732261 | D31: =D28/(D26+D27) -> 0.2730367 | E31: =E28/(E26+E27) -> 0.65132886 | F31: =F28/(F26+F27) -> 0.095391424 | G31: =G28/(G26+G27) -> 0.20721329 | H31: =假设!H147 -> 0.45 | I31: =假设!I147 -> 0.45 | J31: =假设!J147 -> 0.45 | K31: =假设!K147 -> 0.45 | L31: =假设!L147 -> 0.45
A32: 无形资产
A33: 期初原值 | C33: 1427.5411 | D33: =C38 -> 1487.1611 | E33: =D38 -> 1874.7888 | F33: =E38 -> 2376.7389 | G33: =F38 -> 2804.2838 | H33: =G38 -> 3753.4302 | I33: =H38 -> 4439.5527 | J33: =I38 -> 5107.8766 | K33: =J38 -> 5757.2704 | L33: =K38 -> 6388.6245 | N33: 3753.4302
A34: + 外购（土地、软件等） | C34: 61.420921 | D34: 115.89485 | E34: 217.90332 | F34: 101.05921 | G34: 66.699171 | H34: =假设!H143 -> 70 | I34: =假设!I143 -> 70 | J34: =假设!J143 -> 70 | K34: =假设!K143 -> 70 | L34: =假设!L143 -> 70 | N34: 7.9348225
A35: + 开发支出转入（内部研发） | C35: 1.78 | D35: 124.28471 | E35: 351.50396 | F35: 361.35008 | G35: 906.8602 | H35: =H51 -> 616.12253 | I35: =I51 -> 598.32394 | J35: =J51 -> 579.3938 | K35: =K51 -> 561.3541 | L35: =L51 -> 544.67518 | N35: 25.834634
A36: + 其他（在建工程转入/重分类，轧差） | C36: 3.952394e-14 | D36: 180.30612 | E36: 0.05379566 | F36: 56.5794 | G36: 2.0298546 | H36: =H29 -> 0 | I36: =I29 -> 0 | J36: =J29 -> 0 | K36: =K29 -> 0 | L36: =L29 -> 0
A37: − 处置 | C37: 3.5809342 | D37: 32.857928 | E37: 67.51104 | F37: 91.443788 | G37: 26.442815 | H37: 0 | I37: 0 | J37: 0 | K37: 0 | L37: 0 | N37: 2.7340477
A38: 期末原值 | C38: =C33+C34+C35+C36-C37 -> 1487.1611 | D38: =D33+D34+D35+D36-D37 -> 1874.7888 | E38: =E33+E34+E35+E36-E37 -> 2376.7389 | F38: =F33+F34+F35+F36-F37 -> 2804.2838 | G38: =G33+G34+G35+G36-G37 -> 3753.4302 | H38: =H33+H34+H35+H36-H37 -> 4439.5527 | I38: =I33+I34+I35+I36-I37 -> 5107.8766 | J38: =J33+J34+J35+J36-J37 -> 5757.2704 | ... L38: =L33+L34+L35+L36-L37 -> 7003.2997 | N38: 3784.4656
A39: 期初累计摊销 | C39: 427.55604 | D39: =C43 -> 529.84178 | E39: =D43 -> 666.52787 | F39: =E43 -> 817.31539 | G39: =F43 -> 1056.1686 | H39: =G43 -> 1339.5017 | I39: =H43 -> 1749.1508 | J39: =I43 -> 2226.5223 | K39: =J43 -> 2769.7797 | L39: =K43 -> 3377.0744 | N39: 1339.5017
A40: + 本期摊销 | C40: 105.73311 | D40: 153.71147 | E40: 209.5221 | F40: 257.19722 | G40: 304.67628 | H40: =H47*(H33+0.5*(H34+H35+H36)) -> 409.64914 | I40: =I47*(I33+0.5*(I34+I35+I36)) -> 477.37147 | J40: =J47*(J33+0.5*(J34+J35+J36)) -> 543.25735 | K40: =K47*(K33+0.5*(K34+K35+K36)) -> 607.29475 | L40: =L47*(L33+0.5*(L34+L35+L36)) -> 669.59621 | N40: 191.21776
A41: + 其他（轧差） | C41: -4.7961635e-14 | D41: 11.612211 | E41: 0.00596508 | F41: 1.0658141e-14 | G41: 0.001342 | H41: 0 | I41: 0 | J41: 0 | K41: 0 | L41: 0
A42: − 处置转出 | C42: 3.4473738 | D42: 28.637587 | E42: 58.740546 | F42: 18.343975 | G42: 21.344565 | H42: 0 | I42: 0 | J42: 0 | K42: 0 | L42: 0 | N42: 1.6930227
...

Sheet 营运资本
A1: 营运资本（百万元）
A2: 周转天数按期末余额/全年收入（或营业成本）×365；预测余额=驱动×基数
A5: 项目 | B5: 百万元 | C5: 2021A | D5: 2022A | E5: 2023A | F5: 2024A | G5: 2025A | H5: 2026E | I5: 2027E | J5: 2028E | K5: 2029E | L5: 2030E | N5: 2026H1A | O5: 说明 / 来源
A6: 营业收入 | C6: =利润表!C6 -> 26314.98 | D6: =利润表!D6 -> 30917.861 | E6: =利润表!E6 -> 31129.574 | F6: =利润表!F6 -> 28548.831 | G6: =利润表!G6 -> 24918.554 | H6: =利润表!H6 -> 27563.516 | I6: =利润表!I6 -> 29404.632 | J6: =利润表!J6 -> 30868.269 | ... L6: =利润表!L6 -> 33964.496
A7: 营业成本 | C7: =利润表!C7 -> 20605.046 | D7: =利润表!D7 -> 24126.68 | E7: =利润表!E7 -> 24728.125 | F7: =利润表!F7 -> 22482.664 | G7: =利润表!G7 -> 19661.228 | H7: =利润表!H7 -> 21762.216 | I7: =利润表!I7 -> 23299.646 | J7: =利润表!J7 -> 24627.741 | ... L7: =利润表!L7 -> 27167.34
A8: 经营性流动资产
A9: 应收票据及应收款项融资 | C9: =历史报表!E44+历史报表!E46 -> 791.3691 | D9: =历史报表!F44+历史报表!F46 -> 722.2022 | E9: =历史报表!G44+历史报表!G46 -> 1387.9972 | F9: =历史报表!H44+历史报表!H46 -> 1704.2001 | G9: =历史报表!I44+历史报表!I46 -> 967.2344 | H9: =H6*H10 -> 1102.5406 | I9: =I6*I10 -> 1176.1853 | J9: =J6*J10 -> 1234.7308 | K9: =K6*K10 -> 1296.8314 | L9: =L6*L10 -> 1358.5799 | N9: =历史报表!K44+历史报表!K46 -> 1214.8501
A10: 占比 | C10: =C9/C6 -> 0.030072951 | D10: =D9/D6 -> 0.023358738 | E10: =E9/E6 -> 0.044587735 | F10: =F9/F6 -> 0.059694217 | G10: =G9/G6 -> 0.038815831 | H10: =假设!H180 -> 0.04 | I10: =假设!I180 -> 0.04 | J10: =假设!J180 -> 0.04 | K10: =假设!K180 -> 0.04 | L10: =假设!L180 -> 0.04
A11: 应收账款 | C11: =历史报表!E45 -> 4219.3462 | D11: =历史报表!F45 -> 6830.3427 | E11: =历史报表!G45 -> 12411.795 | F11: =历史报表!H45 -> 15260.857 | G11: =历史报表!I45 -> 14811.052 | H11: =H6*H12/365 -> 15103.297 | I11: =I6*I12/365 -> 15306.521 | J11: =J6*J12/365 -> 15222.708 | K11: =K6*K12/365 -> 15544.212 | L11: =L6*L12/365 -> 15819.08 | N11: =历史报表!K45 -> 13100.291 | O11: 2021年42亿→2025年148亿
A12: 周转天数 | C12: =C11/C6*365 -> 58.524131 | D12: =D11/D6*365 -> 80.635433 | E12: =E11/E6*365 -> 145.53059 | F12: =F11/F6*365 -> 195.11176 | G12: =G11/G6*365 -> 216.94813 | H12: =假设!H176 -> 200 | I12: =假设!I176 -> 190 | J12: =假设!J176 -> 180 | K12: =假设!K176 -> 175 | L12: =假设!L176 -> 170
A13: 预付款项 | C13: =历史报表!E47 -> 345.0894 | D13: =历史报表!F47 -> 744.5724 | E13: =历史报表!G47 -> 1204.0073 | F13: =历史报表!H47 -> 659.2119 | G13: =历史报表!I47 -> 1461.3915 | H13: =H7*H14 -> 1632.1662 | I13: =I7*I14 -> 1630.9752 | J13: =J7*J14 -> 1600.8032 | K13: =K7*K14 -> 1681.0694 | L13: =L7*L14 -> 1765.8771 | N13: =历史报表!K47 -> 2516.0374
A14: 占比 | C14: =C13/C7 -> 0.016747811 | D14: =D13/D7 -> 0.030860955 | E14: =E13/E7 -> 0.048689793 | F14: =F13/F7 -> 0.029320898 | G14: =G13/G7 -> 0.074328596 | H14: =假设!H184 -> 0.075 | I14: =假设!I184 -> 0.07 | J14: =假设!J184 -> 0.065 | K14: =假设!K184 -> 0.065 | L14: =假设!L184 -> 0.065
A15: 其他应收款 | C15: =历史报表!E48 -> 680.7874 | D15: =历史报表!F48 -> 484.3906 | E15: =历史报表!G48 -> 646.0326 | F15: =历史报表!H48 -> 496.4689 | G15: =历史报表!I48 -> 367.0848 | H15: =G15 -> 367.0848 | I15: =H15 -> 367.0848 | J15: =I15 -> 367.0848 | K15: =J15 -> 367.0848 | L15: =K15 -> 367.0848 | N15: =历史报表!K48 -> 315.1794
A16: 存货 | C16: =历史报表!E52 -> 14605.128 | D16: =历史报表!F52 -> 14390.162 | E16: =历史报表!G52 -> 9718.9319 | F16: =历史报表!H52 -> 9329.2257 | G16: =历史报表!I52 -> 10575.039 | H16: =H7*H17/365 -> 11030.164 | I16: =I7*I17/365 -> 11490.236 | J16: =J7*J17/365 -> 11807.821 | K16: =K7*K17/365 -> 12045.597 | L16: =L7*L17/365 -> 12653.282 | N16: =历史报表!K52 -> 13560.093
A17: 周转天数 | C17: =C16/C7*365 -> 258.71681 | D17: =D16/D7*365 -> 217.70127 | E17: =E16/E7*365 -> 143.45649 | F17: =F16/F7*365 -> 151.45747 | G17: =G16/G7*365 -> 196.31984 | H17: =假设!H188 -> 185 | I17: =假设!I188 -> 180 | J17: =假设!J188 -> 175 | K17: =假设!K188 -> 170 | L17: =假设!L188 -> 170
A18: 其他流动资产（含合同资产等，轧差） | C18: =历史报表!E54-历史报表!E42-C9-C11-C13-C15-C16 -> 543.3164 | D18: =历史报表!F54-历史报表!F42-D9-D11-D13-D15-D16 -> 633.5327 | E18: =历史报表!G54-历史报表!G42-E9-E11-E13-E15-E16 -> 725.1378 | F18: =历史报表!H54-历史报表!H42-F9-F11-F13-F15-F16 -> 917.7123 | G18: =历史报表!I54-历史报表!I42-G9-G11-G13-G15-G16 -> 539.4725 | H18: =H6*H19 -> 606.39736 | I18: =I6*I19 -> 646.9019 | J18: =J6*J19 -> 679.10192 | K18: =K6*K19 -> 713.25728 | L18: =L6*L19 -> 747.21892 | N18: =历史报表!K54-历史报表!K42-N9-N11-N13-N15-N16 -> 706.3645
A19: 占比 | C19: =C18/C6 -> 0.020646658 | D19: =D18/D6 -> 0.020490832 | E19: =E18/E6 -> 0.023294177 | F19: =F18/F6 -> 0.032145355 | G19: =G18/G6 -> 0.02164943 | H19: =假设!H192 -> 0.022 | I19: =假设!I192 -> 0.022 | J19: =假设!J192 -> 0.022 | K19: =假设!K192 -> 0.022 | L19: =假设!L192 -> 0.022
A20: 经营性流动资产合计 | C20: =C9+C11+C13+C15+C16+C18 -> 21185.036 | D20: =D9+D11+D13+D15+D16+D18 -> 23805.202 | E20: =E9+E11+E13+E15+E16+E18 -> 26093.902 | F20: =F9+F11+F13+F15+F16+F18 -> 28367.676 | G20: =G9+G11+G13+G15+G16+G18 -> 28721.274 | H20: =H9+H11+H13+H15+H16+H18 -> 29841.65 | I20: =I9+I11+I13+I15+I16+I18 -> 30617.904 | J20: =J9+J11+J13+J15+J16+J18 -> 30912.25 | ... L20: =L9+L11+L13+L15+L16+L18 -> 32711.123 | N20: =N9+N11+N13+N15+N16+N18 -> 31412.816
A21: 经营性流动负债
A22: 应付票据及应付账款 | C22: =C24+C25 -> 11601.425 | D22: =D24+D25 -> 14019.216 | E22: =E24+E25 -> 14566.488 | F22: =F24+F25 -> 14506.032 | G22: =G24+G25 -> 12627.496 | H22: =H7*H23/365 -> 13713.177 | I22: =I7*I23/365 -> 14681.969 | J22: =J7*J23/365 -> 15518.85 | K22: =K7*K23/365 -> 16296.984 | L22: =L7*L23/365 -> 17119.146 | N22: =N24+N25 -> 13548.851
A23: 周转天数 | C23: =C22/C7*365 -> 205.50889 | D23: =D22/D7*365 -> 212.08943 | E23: =E22/E7*365 -> 215.00895 | F23: =F22/F7*365 -> 235.50153 | G23: =G22/G7*365 -> 234.42258 | H23: =假设!H196 -> 230 | I23: =假设!I196 -> 230 | J23: =假设!J196 -> 230 | K23: =假设!K196 -> 230 | L23: =假设!L196 -> 230
A24: 其中：应付票据 | C24: =历史报表!E76 -> 5945.8226 | D24: =历史报表!F76 -> 7526.9418 | E24: =历史报表!G76 -> 7752.2333 | F24: =历史报表!H76 -> 8512.7803 | G24: =历史报表!I76 -> 6071.3562 | H24: =H22*H26 -> 6582.3251 | I24: =I22*I26 -> 7047.3449 | J24: =J22*J26 -> 7449.0482 | K24: =K22*K26 -> 7822.5525 | L24: =L22*L26 -> 8217.1901 | N24: =历史报表!K76 -> 7293.6379
A25: 其中：应付账款 | C25: =历史报表!E77 -> 5655.6024 | D25: =历史报表!F77 -> 6492.2746 | E25: =历史报表!G77 -> 6814.2548 | F25: =历史报表!H77 -> 5993.2517 | G25: =历史报表!I77 -> 6556.1394 | H25: =H22-H24 -> 7130.8522 | I25: =I22-I24 -> 7634.6237 | J25: =J22-J24 -> 8069.8022 | K25: =K22-K24 -> 8474.4319 | L25: =L22-L24 -> 8901.9559 | N25: =历史报表!K77 -> 6255.2128
A26: 应付票据占比 | C26: =C24/C22 -> 0.51250795 | D26: =D24/D22 -> 0.53690175 | E26: =E24/E22 -> 0.53219645 | F26: =F24/F22 -> 0.58684417 | G26: =G24/G22 -> 0.48080446 | H26: =假设!H200 -> 0.48 | I26: =假设!I200 -> 0.48 | J26: =假设!J200 -> 0.48 | K26: =假设!K200 -> 0.48 | L26: =假设!L200 -> 0.48
A27: 合同负债及预收款项 | C27: =历史报表!E79+历史报表!E78 -> 3168.6748 | D27: =历史报表!F79+历史报表!F78 -> 1320.7421 | E27: =历史报表!G79+历史报表!G78 -> 1337.322 | F27: =历史报表!H79+历史报表!H78 -> 776.1394 | G27: =历史报表!I79+历史报表!I78 -> 977.6682 | H27: =H6*H28 -> 1074.9771 | I27: =I6*I28 -> 1146.7806 | J27: =J6*J28 -> 1203.8625 | K27: =K6*K28 -> 1264.4106 | L27: =L6*L28 -> 1324.6154 | N27: =历史报表!K79+历史报表!K78 -> 1107.5807 | O27: 2021年31.7亿→2025年9.8亿，预收订单显著减少
A28: 占比 | C28: =C27/C6 -> 0.12041334 | D28: =D27/D6 -> 0.042717771 | E28: =E27/E6 -> 0.042959855 | F28: =F27/F6 -> 0.027186381 | G28: =G27/G6 -> 0.039234547 | H28: =假设!H204 -> 0.039 | I28: =假设!I204 -> 0.039 | J28: =假设!J204 -> 0.039 | K28: =假设!K204 -> 0.039 | L28: =假设!L204 -> 0.039
A29: 应付职工薪酬 | C29: =历史报表!E80 -> 235.4881 | D29: =历史报表!F80 -> 231.3288 | E29: =历史报表!G80 -> 283.6855 | F29: =历史报表!H80 -> 256.2975 | G29: =历史报表!I80 -> 270.1812 | H29: =H6*H30 -> 303.19868 | I29: =I6*I30 -> 323.45095 | J29: =J6*J30 -> 339.55096 | K29: =K6*K30 -> 356.62864 | L29: =L6*L30 -> 373.60946 | N29: =历史报表!K80 -> 183.8769
A30: 占比 | C30: =C29/C6 -> 0.008948823 | D30: =D29/D6 -> 0.0074820442 | E30: =E29/E6 -> 0.0091130543 | F30: =F29/F6 -> 0.008977513 | G30: =G29/G6 -> 0.010842571 | H30: =假设!H208 -> 0.011 | I30: =假设!I208 -> 0.011 | J30: =假设!J208 -> 0.011 | K30: =假设!K208 -> 0.011 | L30: =假设!L208 -> 0.011
A31: 应交税费 | C31: =历史报表!E81 -> 244.7092 | D31: =历史报表!F81 -> 524.5033 | E31: =历史报表!G81 -> 905.9197 | F31: =历史报表!H81 -> 754.1246 | G31: =历史报表!I81 -> 402.134 | H31: =H6*H32 -> 441.01626 | I31: =I6*I32 -> 470.47411 | J31: =J6*J32 -> 493.8923 | K31: =K6*K32 -> 518.73257 | L31: =L6*L32 -> 543.43194 | N31: =历史报表!K81 -> 248.2249
A32: 占比 | C32: =C31/C6 -> 0.0092992355 | D32: =D31/D6 -> 0.016964411 | E32: =E31/E6 -> 0.029101577 | F32: =F31/F6 -> 0.026415253 | G32: =G31/G6 -> 0.016137934 | H32: =假设!H212 -> 0.016 | I32: =假设!I212 -> 0.016 | J32: =假设!J212 -> 0.016 | K32: =假设!K212 -> 0.016 | L32: =假设!L212 -> 0.016
A33: 其他应付款（含应付股利/利息） | C33: =历史报表!E82 -> 1700.9199 | D33: =历史报表!F82 -> 2131.7705 | E33: =历史报表!G82 -> 2036.3337 | F33: =历史报表!H82 -> 1765.2361 | G33: =历史报表!I82 -> 1304.7764 | H33: =H6*H34 -> 1378.1758 | I33: =I6*I34 -> 1470.2316 | J33: =J6*J34 -> 1543.4135 | K33: =K6*K34 -> 1621.0393 | L33: =L6*L34 -> 1698.2248 | N33: =历史报表!K82 -> 1579.4903
A34: 占比 | C34: =C33/C6 -> 0.064636944 | D34: =D33/D6 -> 0.068949483 | E34: =E33/E6 -> 0.065414762 | F34: =F33/F6 -> 0.061832168 | G34: =G33/G6 -> 0.052361641 | H34: =假设!H216 -> 0.05 | I34: =假设!I216 -> 0.05 | J34: =假设!J216 -> 0.05 | K34: =假设!K216 -> 0.05 | L34: =假设!L216 -> 0.05
A35: 其他流动负债（轧差） | C35: =历史报表!E88-历史报表!E73-历史报表!E74-C22-C27-C29-C31-C33-历史报表!E86 -> 458.7291 | D35: =历史报表!F88-历史报表!F73-历史报表!F74-D22-D27-D29-D31-D33-历史报表!F86 -> 269.3734 | E35: =历史报表!G88-历史报表!G73-历史报表!G74-E22-E27-E29-E31-E33-历史报表!G86 -> 246.4759 | F35: =历史报表!H88-历史报表!H73-历史报表!H74-F22-F27-F29-F31-F33-历史报表!H86 -> 186.5249 | G35: =历史报表!I88-历史报表!I73-历史报表!I74-G22-G27-G29-G31-G33-历史报表!I86 -> 159.7008 | H35: =H6*H36 -> 179.16286 | I35: =I6*I36 -> 191.13011 | J35: =J6*J36 -> 200.64375 | K35: =K6*K36 -> 210.73511 | L35: =L6*L36 -> 220.76923 | N35: =历史报表!K88-历史报表!K73-历史报表!K74-N22-N27-N29-N31-N33-历史报表!K86 -> 142.5412
A36: 占比 | C36: =C35/C6 -> 0.017432242 | D36: =D35/D6 -> 0.0087125498 | E36: =E35/E6 -> 0.0079177408 | F36: =F35/F6 -> 0.006533539 | G36: =G35/G6 -> 0.0064089111 | H36: =假设!H220 -> 0.0065 | I36: =假设!I220 -> 0.0065 | J36: =假设!J220 -> 0.0065 | K36: =假设!K220 -> 0.0065 | L36: =假设!L220 -> 0.0065
A37: 交易性金融负债 | C37: =历史报表!E74 -> 0 | D37: =历史报表!F74 -> 0 | E37: =历史报表!G74 -> 0 | F37: =历史报表!H74 -> 0 | G37: =历史报表!I74 -> 18.9335 | H37: =G37 -> 18.9335 | I37: =H37 -> 18.9335 | J37: =I37 -> 18.9335 | K37: =J37 -> 18.9335 | L37: =K37 -> 18.9335 | N37: =历史报表!K74 -> 18.9335
A38: 经营性流动负债合计 | C38: =C22+C27+C29+C31+C33+C35+C37 -> 17409.946 | D38: =D22+D27+D29+D31+D33+D35+D37 -> 18496.934 | E38: =E22+E27+E29+E31+E33+E35+E37 -> 19376.225 | F38: =F22+F27+F29+F31+F33+F35+F37 -> 18244.355 | G38: =G22+G27+G29+G31+G33+G35+G37 -> 15760.89 | H38: =H22+H27+H29+H31+H33+H35+H37 -> 17108.642 | I38: =I22+I27+I29+I31+I33+I35+I37 -> 18302.97 | J38: =J22+J27+J29+J31+J33+J35+J37 -> 19319.147 | ... L38: =L22+L27+L29+L31+L33+L35+L37 -> 21298.73 | N38: =N22+N27+N29+N31+N33+N35+N37 -> 16829.498
A39: 净营运资本
A40: 净营运资本 | C40: =C20-C38 -> 3775.0902 | D40: =D20-D38 -> 5308.2678 | E40: =E20-E38 -> 6717.677 | F40: =F20-F38 -> 10123.321 | G40: =G20-G38 -> 12960.384 | H40: =H20-H38 -> 12733.008 | I40: =I20-I38 -> 12314.935 | J40: =J20-J38 -> 11593.103 | ... L40: =L20-L38 -> 11412.393 | N40: =N20-N38 -> 14583.317
A41: 净营运资本增加（现金流出为正） | D41: =D40-C40 -> 1533.1776 | E41: =E40-D40 -> 1409.4092 | F41: =F40-E40 -> 3405.6442 | G41: =G40-F40 -> 2837.0629 | H41: =H40-G40 -> -227.3757 | I41: =I40-H40 -> -418.07369 | J41: =J40-I40 -> -721.83196 | K41: =K40-J40 -> -232.51467 | L41: =L40-K40 -> 51.804598 | N41: =N40-G40 -> 1622.9334 | O41: 2026H1A为较2025年末变动
A42: 净营运资本/收入 | C42: =C40/C6 -> 0.14345784 | D42: =D40/D6 -> 0.17168936 | E42: =E40/E6 -> 0.21579727 | F42: =F40/F6 -> 0.3545967 | G42: =G40/G6 -> 0.52010979 | H42: =H40/H6 -> 0.46195153 | I42: =I40/I6 -> 0.41880935 | J42: =J40/J6 -> 0.37556699 | ... L42: =L40/L6 -> 0.33600948
...

Sheet 融资
A1: 融资、股本与股东回报（百万元）
A2: 短期借款为平衡项：期末现金低于“最低现金”时增借，高于时偿还（不低于下限）；利息按期初余额计提，避免循环引用
A5: 项目 | B5: 百万元 | C5: 2021A | D5: 2022A | E5: 2023A | F5: 2024A | G5: 2025A | H5: 2026E | I5: 2027E | J5: 2028E | K5: 2029E | L5: 2030E | N5: 2026H1A | O5: 说明 / 来源
A6: 现金
A7: 现金及现金等价物（现金流量表口径） | C7: =历史报表!E145 -> 4533.5814 | D7: =历史报表!F145 -> 4085.1596 | E7: =历史报表!G145 -> 4848.3305 | F7: =历史报表!H145 -> 4810.2668 | G7: =历史报表!I145 -> 6364.4738 | H7: =现金流量表!H36 -> 4500 | I7: =现金流量表!I36 -> 4625.0356 | J7: =现金流量表!J36 -> 5001.4198 | K7: =现金流量表!K36 -> 5650.2721 | L7: =现金流量表!L36 -> 6388.1162 | N7: =历史报表!K145 -> 4816.5155
A8: 受限货币资金 | C8: =历史报表!E42-历史报表!E145 -> 188.7475 | D8: =历史报表!F42-历史报表!F145 -> 303.8136 | E8: =历史报表!G42-历史报表!G145 -> 359.3982 | F8: =历史报表!H42-历史报表!H145 -> 433.4901 | G8: =历史报表!I42-历史报表!I145 -> 122.0201 | H8: =G8 -> 122.0201 | I8: =H8 -> 122.0201 | J8: =I8 -> 122.0201 | K8: =J8 -> 122.0201 | L8: =K8 -> 122.0201 | N8: =历史报表!K42-历史报表!K145 -> 148.6104 | O8: 主要为保证金质押
A9: 货币资金（资产负债表） | C9: =历史报表!E42 -> 4722.3289 | D9: =历史报表!F42 -> 4388.9732 | E9: =历史报表!G42 -> 5207.7287 | F9: =历史报表!H42 -> 5243.7569 | G9: =历史报表!I42 -> 6486.4939 | H9: =H7+H8 -> 4622.0201 | I9: =I7+I8 -> 4747.0557 | J9: =J7+J8 -> 5123.4399 | K9: =K7+K8 -> 5772.2922 | L9: =L7+L8 -> 6510.1363 | N9: =历史报表!K42 -> 4965.1259
A10: 有息负债
A11: 短期借款—期初 | H11: =G12 -> 6930.4263 | I11: =H12 -> 5561.1521 | J11: =I12 -> 3000 | K11: =J12 -> 3000 | L11: =K12 -> 3000
A12: 短期借款—期末（平衡项） | C12: =历史报表!E73 -> 288.5518 | D12: =历史报表!F73 -> 638.6606 | E12: =历史报表!G73 -> 2026.2359 | F12: =历史报表!H73 -> 5079.8579 | G12: =历史报表!I73 -> 6930.4263 | H12: =MAX(假设!$C$35,H11+假设!$C$34-现金流量表!H27) -> 5561.1521 | I12: =MAX(假设!$C$35,I11+假设!$C$34-现金流量表!I27) -> 3000 | J12: =MAX(假设!$C$35,J11+假设!$C$34-现金流量表!J27) -> 3000 | K12: =MAX(假设!$C$35,K11+假设!$C$34-现金流量表!K27) -> 3000 | L12: =MAX(假设!$C$35,L11+假设!$C$34-现金流量表!L27) -> 3000 | N12: =历史报表!K73 -> 7776.7969
A13: 长期借款合计（含一年内到期） | C13: =历史报表!E89+历史报表!E86 -> 2471.9005 | D13: =历史报表!F89+历史报表!F86 -> 2569.3013 | E13: =历史报表!G89+历史报表!G86 -> 2079.0444 | F13: 2075.71 | G13: 4703.75 | H13: =假设!H225 -> 4700 | I13: =假设!I225 -> 4700 | J13: =假设!J225 -> 4700 | K13: =假设!K225 -> 4700 | L13: =假设!L225 -> 4700 | O13: 2024–2025为附注口径；2021–2023为长期借款+一年内到期非流动负债（近似）
A14: 长期借款（非流动） | C14: =历史报表!E89 -> 2455.8 | D14: =历史报表!F89 -> 1672.1 | E14: =历史报表!G89 -> 717.2 | F14: =历史报表!H89 -> 1937.29 | G14: =历史报表!I89 -> 4239.3389 | H14: =H13*(1-假设!$C$36) -> 4230 | I14: =I13*(1-假设!$C$36) -> 4230 | J14: =J13*(1-假设!$C$36) -> 4230 | K14: =K13*(1-假设!$C$36) -> 4230 | L14: =L13*(1-假设!$C$36) -> 4230 | N14: =历史报表!K89 -> 1781.3981
A15: 一年内到期的非流动负债 | C15: =历史报表!E86 -> 16.1005 | D15: =历史报表!F86 -> 897.2013 | E15: =历史报表!G86 -> 1361.8444 | F15: =历史报表!H86 -> 3162.1433 | G15: =历史报表!I86 -> 524.3707 | H15: =H13*假设!$C$36+假设!$C$37 -> 529.95874 | I15: =I13*假设!$C$36+假设!$C$37 -> 529.95874 | J15: =J13*假设!$C$36+假设!$C$37 -> 529.95874 | K15: =K13*假设!$C$36+假设!$C$37 -> 529.95874 | L15: =L13*假设!$C$36+假设!$C$37 -> 529.95874 | N15: =历史报表!K86 -> 2996.6449 | O15: 2024年末含烽火转债29.6亿（2025年12月到期，大部分转股）
A16: 应付债券（烽火转债） | C16: =历史报表!E90 -> 2598.1583 | D16: =历史报表!F90 -> 2722.4942 | E16: =历史报表!G90 -> 2843.957 | F16: =历史报表!H90 -> 0 | G16: =历史报表!I90 -> 0 | H16: 0 | I16: 0 | J16: 0 | K16: 0 | L16: 0 | N16: =历史报表!K90 -> 0
A17: 租赁负债（非流动） | C17: =历史报表!E91 -> 72.0342 | D17: =历史报表!F91 -> 84.52 | E17: =历史报表!G91 -> 49.6756 | F17: =历史报表!H91 -> 99.1721 | G17: =历史报表!I91 -> 39.9403 | H17: =G17 -> 39.9403 | I17: =H17 -> 39.9403 | J17: =I17 -> 39.9403 | K17: =J17 -> 39.9403 | L17: =K17 -> 39.9403 | N17: =历史报表!K91 -> 16.7409
A18: 有息负债合计 | C18: =C12+C14+C15+C16+C17 -> 5430.6448 | D18: =D12+D14+D15+D16+D17 -> 6014.9761 | E18: =E12+E14+E15+E16+E17 -> 6998.9129 | F18: =F12+F14+F15+F16+F17 -> 10278.463 | G18: =G12+G14+G15+G16+G17 -> 11734.076 | H18: =H12+H14+H15+H16+H17 -> 10361.051 | I18: =I12+I14+I15+I16+I17 -> 7799.899 | J18: =J12+J14+J15+J16+J17 -> 7799.899 | ... L18: =L12+L14+L15+L16+L17 -> 7799.899 | N18: =N12+N14+N15+N16+N17 -> 12571.581
A19: 净负债（有息负债−货币资金） | C19: =C18-C9 -> 708.3159 | D19: =D18-D9 -> 1626.0029 | E19: =E18-E9 -> 1791.1842 | F19: =F18-F9 -> 5034.7064 | G19: =G18-G9 -> 5247.5823 | H19: =H18-H9 -> 5739.031 | I19: =I18-I9 -> 3052.8433 | J19: =J18-J9 -> 2676.4591 | ... L19: =L18-L9 -> 1289.7627 | N19: =N18-N9 -> 7606.4549
A20: 财务费用
A21: 计息借款期初余额（短借+长借合计+债券） | H21: =G12+G13+G16 -> 11634.176 | I21: =H12+H13+H16 -> 10261.152 | J21: =I12+I13+I16 -> 7700 | K21: =J12+J13+J16 -> 7700 | L21: =K12+K13+K16 -> 7700
A22: 利息支出 | C22: =历史报表!E16 -> 215.601 | D22: =历史报表!F16 -> 313.6005 | E22: =历史报表!G16 -> 338.3448 | F22: =历史报表!H16 -> 460.6155 | G22: =历史报表!I16 -> 327.7565 | H22: =H21*H23 -> 314.12276 | I22: =I21*I23 -> 277.05111 | J22: =J21*J23 -> 207.9 | K22: =K21*K23 -> 207.9 | L22: =L21*L23 -> 207.9 | N22: =历史报表!K16 -> 149.8608 | O22: 2024年含可转债利息调整（实际利率法）
A23: 借款利率 | D23: =D22/AVERAGE(C18,D18) -> 0.054798338 | E23: =E22/AVERAGE(D18,E18) -> 0.051997493 | F23: =F22/AVERAGE(E18,F18) -> 0.053320075 | G23: =G22/AVERAGE(F18,G18) -> 0.029779072 | H23: =假设!H229 -> 0.027 | I23: =假设!I229 -> 0.027 | J23: =假设!J229 -> 0.027 | K23: =假设!K229 -> 0.027 | L23: =假设!L229 -> 0.027 | O23: 历史=利息支出/平均有息负债
A24: 利息收入 | C24: =历史报表!E17 -> 31.8052 | D24: =历史报表!F17 -> 45.4798 | E24: =历史报表!G17 -> 42.8973 | F24: =历史报表!H17 -> 46.4411 | G24: =历史报表!I17 -> 41.9207 | H24: =G7*H25 -> 44.551317 | I24: =H7*I25 -> 31.5 | J24: =I7*J25 -> 32.375249 | K24: =J7*K25 -> 35.009939 | L24: =K7*L25 -> 39.551904 | N24: =历史报表!K17 -> 17.8741
A25: 存款收益率 | D25: =D24/AVERAGE(C9,D9) -> 0.0099831615 | E25: =E24/AVERAGE(D9,E9) -> 0.0089400089 | F25: =F24/AVERAGE(E9,F9) -> 0.0088869854 | G25: =G24/AVERAGE(F9,G9) -> 0.0071474516 | H25: =假设!H233 -> 0.007 | I25: =假设!I233 -> 0.007 | J25: =假设!J233 -> 0.007 | K25: =假设!K233 -> 0.007 | L25: =假设!L233 -> 0.007
A26: 汇兑损益及手续费等 | C26: =历史报表!E15-C22+C24 -> 181.4787 | D26: =历史报表!F15-D22+D24 -> 114.4138 | E26: =历史报表!G15-E22+E24 -> 20.1453 | F26: =历史报表!H15-F22+F24 -> 143.4701 | G26: =历史报表!I15-G22+G24 -> 138.3653 | H26: =假设!H237 -> 300 | I26: =假设!I237 -> 100 | J26: =假设!J237 -> 100 | K26: =假设!K237 -> 100 | L26: =假设!L237 -> 100 | N26: =历史报表!K15-N22+N24 -> 243.6936
A27: 财务费用合计 | C27: =C22-C24+C26 -> 365.2745 | D27: =D22-D24+D26 -> 382.5345 | E27: =E22-E24+E26 -> 315.5928 | F27: =F22-F24+F26 -> 557.6445 | G27: =G22-G24+G26 -> 424.2011 | H27: =H22-H24+H26 -> 569.57144 | I27: =I22-I24+I26 -> 345.55111 | J27: =J22-J24+J26 -> 275.52475 | ... L27: =L22-L24+L26 -> 268.3481 | N27: =N22-N24+N26 -> 375.6803
A28: 股本与股权融资（百万股/百万元）
A29: 期初股本（百万股） | C29: 1170.154 | D29: =C35 -> 1187.8277 | E29: =D35 -> 1186.5645 | F29: =E35 -> 1185.4913 | G29: =F35 -> 1184.4645 | H29: =G35 -> 1358.1675 | I29: =H35 -> 1358.1675 | J29: =I35 -> 1455.2605 | K29: =J35 -> 1455.2605 | L29: =K35 -> 1455.2605
A30: 定增募资总额 | G30: 1100 | H30: =假设!H249 -> 0 | I30: =假设!I249 -> 2912.79 | J30: =假设!J249 -> 0 | K30: =假设!K249 -> 0 | L30: =假设!L249 -> 0 | O30: 2025A：向中国信科定增8,654.6万股@12.71元
A31: 定增募资净额 | G31: 1093.1 | H31: =H30*(1-假设!$C$41) -> 0 | I31: =I30*(1-假设!$C$41) -> 2880.7493 | J31: =J30*(1-假设!$C$41) -> 0 | K31: =K30*(1-假设!$C$41) -> 0 | L31: =L30*(1-假设!$C$41) -> 0
A32: + 新增股份（定增/可转债转股等） | C32: =C35-C29+C34 -> 17.6737 | D32: =D35-D29+D34 -> -1.2632 | E32: =E35-E29+E34 -> -1.0732 | F32: =F35-F29+F34 -> -1.0268 | G32: =G35-G29+G34 -> 176.803 | H32: =H30/假设!$C$40 -> 0 | I32: =I30/假设!$C$40 -> 97.093 | J32: =J30/假设!$C$40 -> 0 | K32: =K30/假设!$C$40 -> 0 | L32: =L30/假设!$C$40 -> 0 | O32: 2025A含可转债转股9,089万股+定增8,655万股
A33: 股份回购金额 | C33: 0 | D33: 0 | E33: 0 | F33: 0 | G33: 75 | H33: =假设!H245 -> 0 | I33: =假设!I245 -> 0 | J33: =假设!J245 -> 0 | K33: =假设!K245 -> 0 | L33: =假设!L245 -> 0 | O33: 2025年回购309.97万股并注销
A34: − 回购注销股份 | C34: 0 | D34: 0 | E34: 0 | F34: 0 | G34: 3.1 | H34: =H33/假设!$C$8 -> 0 | I34: =I33/假设!$C$8 -> 0 | J34: =J33/假设!$C$8 -> 0 | K34: =K33/假设!$C$8 -> 0 | L34: =L33/假设!$C$8 -> 0
A35: 期末股本（百万股） | C35: =历史报表!E97 -> 1187.8277 | D35: =历史报表!F97 -> 1186.5645 | E35: =历史报表!G97 -> 1185.4913 | F35: =历史报表!H97 -> 1184.4645 | G35: =历史报表!I97 -> 1358.1675 | H35: =H29+H32-H34 -> 1358.1675 | I35: =I29+I32-I34 -> 1455.2605 | J35: =J29+J32-J34 -> 1455.2605 | K35: =K29+K32-K34 -> 1455.2605 | L35: =L29+L32-L34 -> 1455.2605 | N35: =历史报表!K97 -> 1358.1675
A36: 加权平均股本（简化：期初期末平均） | C36: =AVERAGE(C29,C35) -> 1178.9908 | D36: =AVERAGE(D29,D35) -> 1187.1961 | E36: =AVERAGE(E29,E35) -> 1186.0279 | F36: =AVERAGE(F29,F35) -> 1184.9779 | G36: =AVERAGE(G29,G35) -> 1271.316 | H36: =AVERAGE(H29,H35) -> 1358.1675 | I36: =AVERAGE(I29,I35) -> 1406.714 | J36: =AVERAGE(J29,J35) -> 1455.2605 | ... L36: =AVERAGE(L29,L35) -> 1455.2605
A37: 分红
A38: 归属本年度的现金分红（次年派发） | C38: 95.03 | D38: 130.52 | E38: 151.74 | F38: 212.02 | G38: 131.74 | H38: =利润表!H29*假设!H241 -> 225.58085 | I38: =利润表!I29*假设!I241 -> 322.75715 | J38: =利润表!J29*假设!J241 -> 345.99813 | K38: =利润表!K29*假设!K241 -> 380.88505 | L38: =利润表!L29*假设!L241 -> 399.58935 | O38: 历史为年报利润分配方案；2021年=每股0.08元×期末股本
A39: 分红率 | C39: =C38/利润表!C29 -> 0.32999335 | D39: =D38/利润表!D29 -> 0.32164158 | E39: =E38/利润表!E29 -> 0.30025698 | F39: =F38/利润表!F29 -> 0.30171927 | G39: =G38/利润表!G29 -> 0.30227084 | H39: =假设!H241 -> 0.3 | I39: =假设!I241 -> 0.3 | J39: =假设!J241 -> 0.3 | K39: =假设!K241 -> 0.3 | L39: =假设!L241 -> 0.3
A40: 每股股利（元） | C40: 0.08 | D40: 0.11 | E40: 0.128 | F40: 0.179 | G40: 0.097 | H40: =H38/H35 -> 0.16609207 | I40: =I38/I35 -> 0.22178651 | J40: =J38/J35 -> 0.23775683 | K40: =K38/K35 -> 0.26172981 | L40: =L38/L35 -> 0.2745827
A41: 本年支付的现金分红 | D41: =C38 -> 95.03 | E41: =D38 -> 130.52 | F41: =E38 -> 151.74 | G41: =F38 -> 212.02 | H41: =G38 -> 131.74 | I41: =H38 -> 225.58085 | J41: =I38 -> 322.75715 | K41: =J38 -> 345.99813 | L41: =K38 -> 380.88505
A42: 少数股东权益
...

Sheet 利润表
A1: 利润表（百万元）
A2: 历史链接“历史报表”；预测由分业务/费用/融资明细驱动。费用以正数列示，减值损失以负数列示
A5: 项目 | B5: 百万元 | C5: 2021A | D5: 2022A | E5: 2023A | F5: 2024A | G5: 2025A | H5: 2026E | I5: 2027E | J5: 2028E | K5: 2029E | L5: 2030E | N5: 2026H1A | O5: 说明 / 来源
A6: 营业收入 | C6: =历史报表!E8 -> 26314.98 | D6: =历史报表!F8 -> 30917.861 | E6: =历史报表!G8 -> 31129.574 | F6: =历史报表!H8 -> 28548.831 | G6: =历史报表!I8 -> 24918.554 | H6: =分业务!H35 -> 27563.516 | I6: =分业务!I35 -> 29404.632 | J6: =分业务!J35 -> 30868.269 | K6: =分业务!K35 -> 32420.785 | L6: =分业务!L35 -> 33964.496 | N6: =历史报表!K8 -> 12376.358
A7: 营业成本 | C7: =历史报表!E10 -> 20605.046 | D7: =历史报表!F10 -> 24126.68 | E7: =历史报表!G10 -> 24728.125 | F7: =历史报表!H10 -> 22482.664 | G7: =历史报表!I10 -> 19661.228 | H7: =分业务!H37 -> 21762.216 | I7: =分业务!I37 -> 23299.646 | J7: =分业务!J37 -> 24627.741 | K7: =分业务!K37 -> 25862.606 | L7: =分业务!L37 -> 27167.34 | N7: =历史报表!K10 -> 9727.8614
A8: 毛利 | C8: =C6-C7 -> 5709.9348 | D8: =D6-D7 -> 6791.1801 | E8: =E6-E7 -> 6401.449 | F8: =F6-F7 -> 6066.167 | G8: =G6-G7 -> 5257.3262 | H8: =H6-H7 -> 5801.3001 | I8: =I6-I7 -> 6104.9861 | J8: =J6-J7 -> 6240.5282 | ... L8: =L6-L7 -> 6797.1559 | N8: =N6-N7 -> 2648.497
A9: 税金及附加 | C9: =历史报表!E11 -> 88.2078 | D9: =历史报表!F11 -> 102.0822 | E9: =历史报表!G11 -> 109.2552 | F9: =历史报表!H11 -> 116.2267 | G9: =历史报表!I11 -> 109.8429 | H9: =费用!H8 -> 137.81758 | I9: =费用!I8 -> 147.02316 | J9: =费用!J8 -> 154.34135 | K9: =费用!K8 -> 162.10393 | L9: =费用!L8 -> 169.82248 | N9: =历史报表!K11 -> 79.0084
A10: 销售费用 | C10: =历史报表!E12 -> 1417.9454 | D10: =历史报表!F12 -> 1645.9351 | E10: =历史报表!G12 -> 1786.6738 | F10: =历史报表!H12 -> 1881.3582 | G10: =历史报表!I12 -> 1975.6587 | H10: =费用!H10 -> 2094.8272 | I10: =费用!I10 -> 2146.5381 | J10: =费用!J10 -> 2160.7788 | K10: =费用!K10 -> 2204.6134 | L10: =费用!L10 -> 2241.6568 | N10: =历史报表!K12 -> 1061.5176
A11: 管理费用 | C11: =历史报表!E13 -> 294.4026 | D11: =历史报表!F13 -> 328.6322 | E11: =历史报表!G13 -> 341.013 | F11: =历史报表!H13 -> 439.5538 | G11: =历史报表!I13 -> 484.3899 | H11: =费用!H12 -> 523.70681 | I11: =费用!I12 -> 543.98569 | J11: =费用!J12 -> 555.62884 | K11: =费用!K12 -> 583.57414 | L11: =费用!L12 -> 611.36093 | N11: =历史报表!K13 -> 190.1205
A12: 研发费用 | C12: =历史报表!E14 -> 3460.4309 | D12: =历史报表!F14 -> 4101.782 | E12: =历史报表!G14 -> 3578.3312 | F12: =历史报表!H14 -> 2881.2504 | G12: =历史报表!I14 -> 2570.0983 | H12: =费用!H19 -> 2500.5622 | I12: =费用!I19 -> 2604.0742 | J12: =费用!J19 -> 2690.1696 | K12: =费用!K19 -> 2805.0464 | L12: =费用!L19 -> 2944.7218 | N12: =历史报表!K14 -> 1269.9684
A13: 财务费用 | C13: =历史报表!E15 -> 365.2745 | D13: =历史报表!F15 -> 382.5345 | E13: =历史报表!G15 -> 315.5928 | F13: =历史报表!H15 -> 557.6445 | G13: =历史报表!I15 -> 424.2011 | H13: =融资!H27 -> 569.57144 | I13: =融资!I27 -> 345.55111 | J13: =融资!J27 -> 275.52475 | K13: =融资!K27 -> 272.89006 | L13: =融资!L27 -> 268.3481 | N13: =历史报表!K15 -> 375.6803
A14: 其中：利息费用 | C14: =历史报表!E16 -> 215.601 | D14: =历史报表!F16 -> 313.6005 | E14: =历史报表!G16 -> 338.3448 | F14: =历史报表!H16 -> 460.6155 | G14: =历史报表!I16 -> 327.7565 | H14: =融资!H22 -> 314.12276 | I14: =融资!I22 -> 277.05111 | J14: =融资!J22 -> 207.9 | K14: =融资!K22 -> 207.9 | L14: =融资!L22 -> 207.9 | N14: =历史报表!K16 -> 149.8608
