Workbook

Sheet 封面
B2: 菲利华（300395.SZ）财务与估值模型
B3: 笃研究 | 2026年10月6日 | 新材料·石英 | 数据截至2026年半年报，股价截至2026年9月30日
B5: 关键输出 | C5: 2025A | D5: 2026E | E5: 2027E | F5: 2028E
B6: 营业收入（百万元） | C6: =利润表!H5 -> 2016.3489 | D6: =利润表!I5 -> 2741.007 | E6: =利润表!J5 -> 3510.4561 | F6: =利润表!K5 -> 4419.9684
B7: 同比 | C7: =利润表!H6 -> 0.15761609 | D7: =利润表!I6 -> 0.35939122 | E7: =利润表!J6 -> 0.28071769 | F7: =利润表!K6 -> 0.25908663
B8: 综合毛利率 | C8: =利润表!H9 -> 0.47376553 | D8: =利润表!I9 -> 0.50234003 | E8: =利润表!J9 -> 0.50210968 | F8: =利润表!K9 -> 0.49254316
B9: 归母净利润（百万元） | C9: =利润表!H27 -> 443.1847 | D9: =利润表!I27 -> 617.92312 | E9: =利润表!J27 -> 751.23552 | F9: =利润表!K27 -> 964.73358
B10: 同比 | C10: =利润表!H28 -> 0.41047518 | D10: =利润表!I28 -> 0.394279 | E10: =利润表!J28 -> 0.2157427 | F10: =利润表!K28 -> 0.28419591
B11: EPS（元） | C11: =利润表!H29 -> 0.84857392 | D11: =利润表!I29 -> 1.1753621 | E11: =利润表!J29 -> 1.4265473 | F11: =利润表!K29 -> 1.8289066
B12: ROE | C12: =利润表!H37 -> 0.09577148 | D12: =利润表!I37 -> 0.11202174 | E12: =利润表!J37 -> 0.1195494 | F12: =利润表!K37 -> 0.13436674
B13: PE（当前股价） | C13: =DCF!$C$5/利润表!H29 -> 114.81616 | D13: =DCF!$C$5/利润表!I29 -> 82.893603 | E13: =DCF!$C$5/利润表!J29 -> 68.297768 | F13: =DCF!$C$5/利润表!K29 -> 53.272268
B14: 一致预期归母净利润（百万元） | C14: 443.18 | D14: 739.39 | E14: 1105.27 | F14: 1553.36
B15: 模型 / 一致预期 − 1 | D15: =D9/D14-1 -> -0.16427985 | E15: =E9/E14-1 -> -0.32031493 | F15: =F9/F14-1 -> -0.37893754
B17: 估值（元/股） | C17: 下限 | D17: 基准 | E17: 上限 | F17: 相对股价
B18: =相对估值!A74 -> DCF（WACC ±0.5%） | C18: =相对估值!B74 -> 27.344501 | D18: =相对估值!C74 -> 29.685689 | E18: =相对估值!D74 -> 32.425837 | F18: =IFERROR(D18/DCF!$C$5-1,0) -> -0.69531264
B19: =相对估值!A75 -> PE（2027E） | C19: =相对估值!B75 -> 49.929157 | D19: =相对估值!C75 -> 64.19463 | E19: =相对估值!D75 -> 78.460104 | F19: =IFERROR(D19/DCF!$C$5-1,0) -> -0.34112049
B20: =相对估值!A76 -> SOTP（2027E / 2028E折现） | C20: =相对估值!B76 -> 49.546571 | D20: =相对估值!C76 -> 51.3497 | E20: =相对估值!D76 -> 53.152828 | F20: =IFERROR(D20/DCF!$C$5-1,0) -> -0.47295802
B21: =相对估值!A77 -> 卖方目标价（近3个月） | C21: =相对估值!B77 -> 107.05 | D21: =相对估值!C77 -> 124.7 | E21: =相对估值!D77 -> 142.59 | F21: =IFERROR(D21/DCF!$C$5-1,0) -> 0.27989326
B22: =相对估值!A78 -> 52周股价区间 | C22: =相对估值!B78 -> 75.36 | D22: =相对估值!C78 -> 97.43 | E22: =相对估值!D78 -> 150 | F22: =IFERROR(D22/DCF!$C$5-1,0) -> 0
B24: 当前情景 / 当前价格 | C24: =假设!C5 -> 基准 | D24: =DCF!C5 -> 97.43 | E24: =DCF!C7/100 -> 512.21591 | F24: 模型检查： | G24: =检查!B19 -> 通过
B26: 三情景结果快照（静态值，由模型分别切换情景计算后写入）
B27: 情景 | C27: 2026E 归母净利 | D27: 2027E 归母净利 | E27: 2028E 归母净利 | F27: DCF每股价值 | G27: SOTP(2027E)每股 | H27: 2028E电子布收入
B28: 悲观 | C28: 566.19 | D28: 506.01 | E28: 568.58 | F28: 17.49 | G28: 33.48 | H28: 595
B29: 基准 | C29: 617.92 | D29: 751.24 | E29: 964.73 | F29: 29.69 | G29: 49.55 | H29: 1365
B30: 乐观 | C30: 699.05 | D30: 1053.39 | E30: 1544.96 | F30: 43.64 | G30: 69.43 | H30: 3055
B32: 图例与约定
B33: 蓝色字体 | C33: 硬编码输入（历史报告值、假设、外部数据）
B34: 黑色字体 | C34: 公式计算
B35: 绿色字体 | C35: 跨表引用
B36: 浅黄底色 | C36: 预测期可调输入
B37: 亮黄底色 | C37: 关键假设 / 关键输出（含情景选择单元格“假设!C4”）
B38: 单位 | C38: 除注明外均为人民币百万元；股本为百万股；电子布销量为万米、均价为元/米
B39: 时间 | C39: 历史 2020A–2025A（年报）；2026E–2030E 为全年预测，“季度”表以全年预测减上半年实际推算2026Q3E/Q4E
B41: 表单导航
B42: 假设 | C42: 情景切换（C4）与分业务情景驱动：增速、毛利率、电子布产能/销量/价格
B43: 业务拆分 | C43: 七大应用的收入、毛利、经营利润、少数股东比例与归母利润
B44: 资本开支 | C44: 项目级资本开支、在建工程转固、分年度折旧（年中法）
B45: 营运资本 | C45: 应收、存货、应付等周转天数驱动
B46: 费用税率 | C46: 费用率、其他收益、减值、税率、少数股东损益
B47: 融资 | C47: 借款、利息、金融资产、股本、股份支付、分红、少数股东
...

Sheet 假设
A1: 核心假设与情景切换（黄色底色=可调输入；蓝字=硬编码输入；黑字=公式；绿字=跨表引用）
A2: 切换 C4 情景编号（1=悲观 2=基准 3=乐观），全模型随之重算。每个驱动项下方三行为三种情景输入，“选用”行为 CHOOSE 结果。
A4: 情景选择（1=悲观, 2=基准, 3=乐观） | C4: 2 | D4: 改变此单元格即可切换全模型情景
A5: 当前情景 | C5: =CHOOSE(C4,"悲观","基准","乐观") -> 基准
A7: 情景驱动（百万元 / 指标） | B7: 单位 | C7: 2020A | D7: 2021A | E7: 2022A | F7: 2023A | G7: 2024A | H7: 2025A | I7: 2026E | J7: 2027E | K7: 2028E | L7: 2029E | M7: 2030E | N7: 说明 / 来源
A8: 半导体 收入增速
A9: 悲观 | B9: % | I9: 0.24 | J9: 0.1 | K9: 0.08 | L9: 0.06 | M9: 0.05
A10: 基准 | B10: % | I10: 0.28 | J10: 0.18 | K10: 0.14 | L10: 0.11 | M10: 0.09
A11: 乐观 | B11: % | I11: 0.33 | J11: 0.26 | K11: 0.2 | L11: 0.15 | M11: 0.12
A12: 选用（半导体 收入增速） | B12: % | I12: =CHOOSE($C$4,I9,I10,I11) -> 0.28 | J12: =CHOOSE($C$4,J9,J10,J11) -> 0.18 | K12: =CHOOSE($C$4,K9,K10,K11) -> 0.14 | L12: =CHOOSE($C$4,L9,L10,L11) -> 0.11 | M12: =CHOOSE($C$4,M9,M10,M11) -> 0.09 | N12: 2026H1半导体用石英材料+35%（半年报）；石创器件受光伏/研发拖累，合计按+28%；之后随国产替代与存储/先进制程扩产放缓
A13: 半导体 毛利率
A14: 悲观 | B14: % | I14: 0.5 | J14: 0.46 | K14: 0.45 | L14: 0.45 | M14: 0.44
A15: 基准 | B15: % | I15: 0.51 | J15: 0.51 | K15: 0.51 | L15: 0.5 | M15: 0.5
A16: 乐观 | B16: % | I16: 0.53 | J16: 0.54 | K16: 0.54 | L16: 0.54 | M16: 0.53
A17: 选用（半导体 毛利率） | B17: % | I17: =CHOOSE($C$4,I14,I15,I16) -> 0.51 | J17: =CHOOSE($C$4,J14,J15,J16) -> 0.51 | K17: =CHOOSE($C$4,K14,K15,K16) -> 0.51 | L17: =CHOOSE($C$4,L14,L15,L16) -> 0.5 | M17: =CHOOSE($C$4,M14,M15,M16) -> 0.5 | N17: 估算2025年51%、2026H1约51%（材料毛利率-7.5pct，合成石英五/六期折旧与产品结构）；基准维持51%
A18: 航空航天 收入增速
A19: 悲观 | B19: % | I19: 0.1 | J19: 0.03 | K19: 0.03 | L19: 0.03 | M19: 0.03
A20: 基准 | B20: % | I20: 0.15 | J20: 0.12 | K20: 0.1 | L20: 0.07 | M20: 0.06
A21: 乐观 | B21: % | I21: 0.2 | J21: 0.18 | K21: 0.14 | L21: 0.1 | M21: 0.08
A22: 选用（航空航天 收入增速） | B22: % | I22: =CHOOSE($C$4,I19,I20,I21) -> 0.15 | J22: =CHOOSE($C$4,J19,J20,J21) -> 0.12 | K22: =CHOOSE($C$4,K19,K20,K21) -> 0.1 | L22: =CHOOSE($C$4,L19,L20,L21) -> 0.07 | M22: =CHOOSE($C$4,M19,M20,M21) -> 0.06 | N22: 2024需求回落、2025持续恢复、复合材料获批量订单；2026H1估算+19%，全年按+15%（下半年约+11%）；军工行业“十五五”批量采购预计2027年起改善
A23: 航空航天 毛利率
A24: 悲观 | B24: % | I24: 0.59 | J24: 0.54 | K24: 0.53 | L24: 0.53 | M24: 0.53
A25: 基准 | B25: % | I25: 0.61 | J25: 0.61 | K25: 0.6 | L25: 0.6 | M25: 0.59
A26: 乐观 | B26: % | I26: 0.64 | J26: 0.64 | K26: 0.64 | L26: 0.63 | M26: 0.63
A27: 选用（航空航天 毛利率） | B27: % | I27: =CHOOSE($C$4,I24,I25,I26) -> 0.61 | J27: =CHOOSE($C$4,J24,J25,J26) -> 0.61 | K27: =CHOOSE($C$4,K24,K25,K26) -> 0.6 | L27: =CHOOSE($C$4,L24,L25,L26) -> 0.6 | M27: =CHOOSE($C$4,M24,M25,M26) -> 0.59 | N27: 军品价格机制改革存在压价风险，基准毛利率较2021-23年高点下调
A28: 光学（合成石英/光掩膜基板） 收入增速
A29: 悲观 | B29: % | I29: 0.3 | J29: 0.12 | K29: 0.1 | L29: 0.08 | M29: 0.06
A30: 基准 | B30: % | I30: 0.38 | J30: 0.28 | K30: 0.22 | L30: 0.16 | M30: 0.12
A31: 乐观 | B31: % | I31: 0.45 | J31: 0.4 | K31: 0.32 | L31: 0.22 | M31: 0.15
A32: 选用（光学（合成石英/光掩膜基板） 收入增速） | B32: % | I32: =CHOOSE($C$4,I29,I30,I31) -> 0.38 | J32: =CHOOSE($C$4,J29,J30,J31) -> 0.28 | K32: =CHOOSE($C$4,K29,K30,K31) -> 0.22 | L32: =CHOOSE($C$4,L29,L30,L31) -> 0.16 | M32: =CHOOSE($C$4,M29,M30,M31) -> 0.12 | N32: 2025高端光学材料“大幅增长”；2026H1估算+46%，济南光微建成、合肥光微逐步批量出货，全年按+38%（目标达产收入4亿元）
A33: 光学（合成石英/光掩膜基板） 毛利率
A34: 悲观 | B34: % | I34: 0.47 | J34: 0.45 | K34: 0.45 | L34: 0.45 | M34: 0.45
A35: 基准 | B35: % | I35: 0.49 | J35: 0.5 | K35: 0.5 | L35: 0.5 | M35: 0.5
A36: 乐观 | B36: % | I36: 0.51 | J36: 0.53 | K36: 0.54 | L36: 0.54 | M36: 0.54
A37: 选用（光学（合成石英/光掩膜基板） 毛利率） | B37: % | I37: =CHOOSE($C$4,I34,I35,I36) -> 0.49 | J37: =CHOOSE($C$4,J34,J35,J36) -> 0.5 | K37: =CHOOSE($C$4,K34,K35,K36) -> 0.5 | L37: =CHOOSE($C$4,L34,L35,L36) -> 0.5 | M37: =CHOOSE($C$4,M34,M35,M36) -> 0.5 | N37: 光掩膜基板仍在爬坡、上海石创亏损；毛利率随规模提升
A38: 光通讯 收入增速
A39: 悲观 | B39: % | I39: 0.4 | J39: -0.08 | K39: -0.1 | L39: 0 | M39: 0
A40: 基准 | B40: % | I40: 0.45 | J40: 0.08 | K40: -0.05 | L40: 0 | M40: 0.03
A41: 乐观 | B41: % | I41: 0.55 | J41: 0.2 | K41: 0.05 | L41: 0.03 | M41: 0.03
A42: 选用（光通讯 收入增速） | B42: % | I42: =CHOOSE($C$4,I39,I40,I41) -> 0.45 | J42: =CHOOSE($C$4,J39,J40,J41) -> 0.08 | K42: =CHOOSE($C$4,K39,K40,K41) -> -0.05 | L42: =CHOOSE($C$4,L39,L40,L41) -> 0 | M42: =CHOOSE($C$4,M39,M40,M41) -> 0.03 | N42: 光纤预制棒价格自2025年底上涨数倍（AI数据中心），2025年制品一销量+31%；2026H1估算+62%。周期性回落风险在2028年
...

Sheet 业务拆分
A1: 业务拆分：按下游应用的收入与毛利（百万元）
A2: 历史拆分为基于公司公告（分产品/产销量/子公司/管理层口径）的估算，置信度见备注；预测由“假设”表情景驱动。
A4: 百万元 | B4: 单位 | C4: 2020A | D4: 2021A | E4: 2022A | F4: 2023A | G4: 2024A | H4: 2025A | I4: 2026E | J4: 2027E | K4: 2028E | L4: 2029E | M4: 2030E | N4: 说明 / 来源
A5: 半导体
A6: 收入 | B6: 百万元 | C6: 377.5 | D6: 487 | E6: 654.78 | F6: 726.52 | G6: 806.46 | H6: 897.5 | I6: =H6*(1+假设!I12) -> 1148.8 | J6: =I6*(1+假设!J12) -> 1355.584 | K6: =J6*(1+假设!K12) -> 1545.3658 | L6: =K6*(1+假设!L12) -> 1715.356 | M6: =L6*(1+假设!M12) -> 1869.738 | N6: 历史分业务为本报告估算：两套方法（自下而上产销量法、子公司+增速法，共用部分披露锚点）取均值，收入与毛利均与报表勾稽；航空航天收入与半导体、航空航天毛利率为倒算项（两法差异见“底稿”），半导体置信度中等，其余偏低
A7: 同比 | B7: % | D7: =IFERROR(D6/C6-1,0) -> 0.29006623 | E7: =IFERROR(E6/D6-1,0) -> 0.34451745 | F7: =IFERROR(F6/E6-1,0) -> 0.10956352 | G7: =IFERROR(G6/F6-1,0) -> 0.11003138 | H7: =IFERROR(H6/G6-1,0) -> 0.11288843 | I7: =IFERROR(I6/H6-1,0) -> 0.28 | J7: =IFERROR(J6/I6-1,0) -> 0.18 | K7: =IFERROR(K6/J6-1,0) -> 0.14 | ... M7: =IFERROR(M6/L6-1,0) -> 0.09
A8: 毛利率 | B8: % | C8: 0.5052 | D8: 0.5118 | E8: 0.548 | F8: 0.554 | G8: 0.4911 | H8: 0.5136 | I8: =假设!I17 -> 0.51 | J8: =假设!J17 -> 0.51 | K8: =假设!K17 -> 0.51 | L8: =假设!L17 -> 0.5 | M8: =假设!M17 -> 0.5
A9: 毛利 | B9: 百万元 | C9: =C6*C8 -> 190.713 | D9: =D6*D8 -> 249.2466 | E9: =E6*E8 -> 358.81944 | F9: =F6*F8 -> 402.49208 | G9: =G6*G8 -> 396.05251 | H9: =H6*H8 -> 460.956 | I9: =I6*I8 -> 585.888 | J9: =J6*J8 -> 691.34784 | ... M9: =M6*M8 -> 934.86902
A10: 航空航天
A11: 收入 | B11: 百万元 | C11: 306.14 | D11: 430.71 | E11: 545.74 | F11: 548.59 | G11: 322.58 | H11: 426.94 | I11: =H11*(1+假设!I22) -> 490.981 | J11: =I11*(1+假设!J22) -> 549.89872 | K11: =J11*(1+假设!K22) -> 604.88859 | L11: =K11*(1+假设!L22) -> 647.23079 | M11: =L11*(1+假设!M22) -> 686.06464 | N11: 历史分业务为本报告估算：两套方法（自下而上产销量法、子公司+增速法，共用部分披露锚点）取均值，收入与毛利均与报表勾稽；航空航天收入与半导体、航空航天毛利率为倒算项（两法差异见“底稿”），半导体置信度中等，其余偏低
A12: 同比 | B12: % | D12: =IFERROR(D11/C11-1,0) -> 0.40690534 | E12: =IFERROR(E11/D11-1,0) -> 0.26707065 | F12: =IFERROR(F11/E11-1,0) -> 0.005222267 | G12: =IFERROR(G11/F11-1,0) -> -0.41198345 | H12: =IFERROR(H11/G11-1,0) -> 0.32351665 | I12: =IFERROR(I11/H11-1,0) -> 0.15 | J12: =IFERROR(J11/I11-1,0) -> 0.12 | K12: =IFERROR(K11/J11-1,0) -> 0.1 | ... M12: =IFERROR(M11/L11-1,0) -> 0.06
A13: 毛利率 | B13: % | C13: 0.6307 | D13: 0.6288 | E13: 0.673 | F13: 0.6935 | G13: 0.5821 | H13: 0.6366 | I13: =假设!I27 -> 0.61 | J13: =假设!J27 -> 0.61 | K13: =假设!K27 -> 0.6 | L13: =假设!L27 -> 0.6 | M13: =假设!M27 -> 0.59
A14: 毛利 | B14: 百万元 | C14: =C11*C13 -> 193.0825 | D14: =D11*D13 -> 270.83045 | E14: =E11*E13 -> 367.28302 | F14: =F11*F13 -> 380.44716 | G14: =G11*G13 -> 187.77382 | H14: =H11*H13 -> 271.79 | I14: =I11*I13 -> 299.49841 | J14: =J11*J13 -> 335.43822 | ... M14: =M11*M13 -> 404.77814
A15: 光学（合成石英/光掩膜基板）
A16: 收入 | B16: 百万元 | C16: 72.5 | D16: 87.5 | E16: 104 | F16: 122.5 | G16: 128.5 | H16: 184 | I16: =H16*(1+假设!I32) -> 253.92 | J16: =I16*(1+假设!J32) -> 325.0176 | K16: =J16*(1+假设!K32) -> 396.52147 | L16: =K16*(1+假设!L32) -> 459.96491 | M16: =L16*(1+假设!M32) -> 515.1607 | N16: 历史分业务为本报告估算：两套方法（自下而上产销量法、子公司+增速法，共用部分披露锚点）取均值，收入与毛利均与报表勾稽；航空航天收入与半导体、航空航天毛利率为倒算项（两法差异见“底稿”），半导体置信度中等，其余偏低
A17: 同比 | B17: % | D17: =IFERROR(D16/C16-1,0) -> 0.20689655 | E17: =IFERROR(E16/D16-1,0) -> 0.18857143 | F17: =IFERROR(F16/E16-1,0) -> 0.17788462 | G17: =IFERROR(G16/F16-1,0) -> 0.048979592 | H17: =IFERROR(H16/G16-1,0) -> 0.43190661 | I17: =IFERROR(I16/H16-1,0) -> 0.38 | J17: =IFERROR(J16/I16-1,0) -> 0.28 | K17: =IFERROR(K16/J16-1,0) -> 0.22 | ... M17: =IFERROR(M16/L16-1,0) -> 0.12
A18: 毛利率 | B18: % | C18: 0.5045 | D18: 0.5045 | E18: 0.5025 | F18: 0.4975 | G18: 0.4725 | H18: 0.487 | I18: =假设!I37 -> 0.49 | J18: =假设!J37 -> 0.5 | K18: =假设!K37 -> 0.5 | L18: =假设!L37 -> 0.5 | M18: =假设!M37 -> 0.5
A19: 毛利 | B19: 百万元 | C19: =C16*C18 -> 36.57625 | D19: =D16*D18 -> 44.14375 | E19: =E16*E18 -> 52.26 | F19: =F16*F18 -> 60.94375 | G19: =G16*G18 -> 60.71625 | H19: =H16*H18 -> 89.608 | I19: =I16*I18 -> 124.4208 | J19: =J16*J18 -> 162.5088 | ... M19: =M16*M18 -> 257.58035
A20: 光通讯
A21: 收入 | B21: 百万元 | C21: 62.27 | D21: 73.76 | E21: 110.12 | F21: 146.83 | G21: 137.81 | H21: 167.26 | I21: =H21*(1+假设!I42) -> 242.527 | J21: =I21*(1+假设!J42) -> 261.92916 | K21: =J21*(1+假设!K42) -> 248.8327 | L21: =K21*(1+假设!L42) -> 248.8327 | M21: =L21*(1+假设!M42) -> 256.29768 | N21: 历史分业务为本报告估算：两套方法（自下而上产销量法、子公司+增速法，共用部分披露锚点）取均值，收入与毛利均与报表勾稽；航空航天收入与半导体、航空航天毛利率为倒算项（两法差异见“底稿”），半导体置信度中等，其余偏低
A22: 同比 | B22: % | D22: =IFERROR(D21/C21-1,0) -> 0.18451903 | E22: =IFERROR(E21/D21-1,0) -> 0.49295011 | F22: =IFERROR(F21/E21-1,0) -> 0.3333636 | G22: =IFERROR(G21/F21-1,0) -> -0.061431588 | H22: =IFERROR(H21/G21-1,0) -> 0.21370002 | I22: =IFERROR(I21/H21-1,0) -> 0.45 | J22: =IFERROR(J21/I21-1,0) -> 0.08 | K22: =IFERROR(K21/J21-1,0) -> -0.05 | ... M22: =IFERROR(M21/L21-1,0) -> 0.03
A23: 毛利率 | B23: % | C23: 0.31 | D23: 0.31 | E23: 0.31 | F23: 0.315 | G23: 0.23 | H23: 0.26 | I23: =假设!I47 -> 0.34 | J23: =假设!J47 -> 0.3 | K23: =假设!K47 -> 0.27 | L23: =假设!L47 -> 0.27 | M23: =假设!M47 -> 0.27
A24: 毛利 | B24: 百万元 | C24: =C21*C23 -> 19.3037 | D24: =D21*D23 -> 22.8656 | E24: =E21*E23 -> 34.1372 | F24: =F21*F23 -> 46.25145 | G24: =G21*G23 -> 31.6963 | H24: =H21*H23 -> 43.4876 | I24: =I21*I23 -> 82.45918 | J24: =J21*J23 -> 78.578748 | ... M24: =M21*M23 -> 69.200374
A25: 光伏
A26: 收入 | B26: 百万元 | C26: 26.5 | D26: 50 | E26: 168.45 | F26: 349.8 | G26: 180.34 | H26: 89.05 | I26: =H26*(1+假设!I52) -> 66.7875 | J26: =I26*(1+假设!J52) -> 66.7875 | K26: =J26*(1+假设!K52) -> 68.791125 | L26: =K26*(1+假设!L52) -> 70.854859 | M26: =L26*(1+假设!M52) -> 72.980505 | N26: 历史分业务为本报告估算：两套方法（自下而上产销量法、子公司+增速法，共用部分披露锚点）取均值，收入与毛利均与报表勾稽；航空航天收入与半导体、航空航天毛利率为倒算项（两法差异见“底稿”），半导体置信度中等，其余偏低
A27: 同比 | B27: % | D27: =IFERROR(D26/C26-1,0) -> 0.88679245 | E27: =IFERROR(E26/D26-1,0) -> 2.369 | F27: =IFERROR(F26/E26-1,0) -> 1.0765806 | G27: =IFERROR(G26/F26-1,0) -> -0.48444826 | H27: =IFERROR(H26/G26-1,0) -> -0.50621049 | I27: =IFERROR(I26/H26-1,0) -> -0.25 | J27: =IFERROR(J26/I26-1,0) -> 0 | K27: =IFERROR(K26/J26-1,0) -> 0.03 | ... M27: =IFERROR(M26/L26-1,0) -> 0.03
A28: 毛利率 | B28: % | C28: 0.24 | D28: 0.24 | E28: 0.265 | F28: 0.3 | G28: 0.126 | H28: 0.045 | I28: =假设!I57 -> 0.03 | J28: =假设!J57 -> 0.08 | K28: =假设!K57 -> 0.1 | L28: =假设!L57 -> 0.12 | M28: =假设!M57 -> 0.12
A29: 毛利 | B29: 百万元 | C29: =C26*C28 -> 6.36 | D29: =D26*D28 -> 12 | E29: =E26*E28 -> 44.63925 | F29: =F26*F28 -> 104.94 | G29: =G26*G28 -> 22.72284 | H29: =H26*H28 -> 4.00725 | I29: =I26*I28 -> 2.003625 | J29: =J26*J28 -> 5.343 | ... M29: =M26*M28 -> 8.7576605
A30: 石英电子布
A31: 年末有效产能 | B31: 万米/年 | H31: 100 | I31: =假设!I72 -> 250 | J31: =假设!J72 -> 700 | K31: =假设!K72 -> 1100 | L31: =假设!L72 -> 1400 | M31: =假设!M72 -> 1600 | N31: 年化有效产能（万米/年）。1,000吨电子纱约可支撑800万米以上电子布（按1吨纱≈1万平方米、幅宽1.27米，为自媒体经验口径，可信度低）；产能扩张节奏决定资本开支
A32: 销量 | B32: 万米 | H32: 37.8 | I32: =假设!I77 -> 134 | J32: =假设!J77 -> 320 | K32: =假设!K77 -> 650 | L32: =假设!L77 -> 950 | M32: =假设!M77 -> 1200
A33: 产能利用率（销量/年均产能） | B33: % | I33: =IFERROR(I32/AVERAGE(I31,H31),0) -> 0.76571429 | J33: =IFERROR(J32/AVERAGE(J31,I31),0) -> 0.67368421 | K33: =IFERROR(K32/AVERAGE(K31,J31),0) -> 0.72222222 | L33: =IFERROR(L32/AVERAGE(L31,K31),0) -> 0.76 | M33: =IFERROR(M32/AVERAGE(M31,L31),0) -> 0.8 | N33: >100% 说明销量假设超出产能，需上调产能或下调销量
A34: 均价（不含税） | B34: 元/米 | H34: 260 | I34: =假设!I82 -> 270 | J34: =假设!J82 -> 240 | K34: =假设!K82 -> 210 | L34: =假设!L82 -> 190 | M34: =假设!M82 -> 175
A35: 收入 | B35: 百万元 | C35: 0 | D35: 0 | E35: 0 | F35: 0 | G35: 2.5 | H35: 98.39 | I35: =I32*I34/100 -> 361.8 | J35: =J32*J34/100 -> 768 | K35: =K32*K34/100 -> 1365 | L35: =L32*L34/100 -> 1805 | M35: =M32*M34/100 -> 2100 | N35: 万米×元/米÷100 = 百万元；2025年石英电子布收入9,837.37万元（公司披露）；2026H1 1.53亿元
A36: 毛利率 | B36: % | C36: 0.6 | D36: 0.6 | E36: 0.6 | F36: 0.6 | G36: 0.45 | H36: 0.54 | I36: =假设!I87 -> 0.64 | J36: =假设!J87 -> 0.58 | K36: =假设!K87 -> 0.52 | L36: =假设!L87 -> 0.48 | M36: =假设!M87 -> 0.45
A37: 毛利 | B37: 百万元 | C37: =C35*C36 -> 0 | D37: =D35*D36 -> 0 | E37: =E35*E36 -> 0 | F37: =F35*F36 -> 0 | G37: =G35*G36 -> 1.125 | H37: =H35*H36 -> 53.1306 | I37: =I35*I36 -> 231.552 | J37: =J35*J36 -> 445.44 | ... M37: =M35*M36 -> 945
A38: 收入同比 | B38: % | D38: =IFERROR(D35/C35-1,0) -> 0 | E38: =IFERROR(E35/D35-1,0) -> 0 | F38: =IFERROR(F35/E35-1,0) -> 0 | G38: =IFERROR(G35/F35-1,0) -> 0 | H38: =IFERROR(H35/G35-1,0) -> 38.356 | I38: =IFERROR(I35/H35-1,0) -> 2.677203 | J38: =IFERROR(J35/I35-1,0) -> 1.1227197 | K38: =IFERROR(K35/J35-1,0) -> 0.77734375 | ... M38: =IFERROR(M35/L35-1,0) -> 0.1634349
A39: 玻纤工业布及其他
A40: 收入 | B40: 百万元 | C40: 18.67 | D40: 94.58 | E40: 136.28 | F40: 196.31 | G40: 163.62 | H40: 153.21 | I40: =H40*(1+假设!I62) -> 176.1915 | J40: =I40*(1+假设!J62) -> 183.23916 | K40: =J40*(1+假设!K62) -> 190.56873 | L40: =K40*(1+假设!L62) -> 196.28579 | M40: =L40*(1+假设!M62) -> 202.17436 | N40: 历史分业务为本报告估算：两套方法（自下而上产销量法、子公司+增速法，共用部分披露锚点）取均值，收入与毛利均与报表勾稽；航空航天收入与半导体、航空航天毛利率为倒算项（两法差异见“底稿”），半导体置信度中等，其余偏低
A41: 同比 | B41: % | D41: =IFERROR(D40/C40-1,0) -> 4.0658811 | E41: =IFERROR(E40/D40-1,0) -> 0.4408966 | F41: =IFERROR(F40/E40-1,0) -> 0.44049017 | G41: =IFERROR(G40/F40-1,0) -> -0.16652234 | H41: =IFERROR(H40/G40-1,0) -> -0.063623029 | I41: =IFERROR(I40/H40-1,0) -> 0.15 | J41: =IFERROR(J40/I40-1,0) -> 0.04 | K41: =IFERROR(K40/J40-1,0) -> 0.04 | ... M41: =IFERROR(M40/L40-1,0) -> 0.03
...

Sheet 资本开支
A1: 投资、在建工程、固定资产与折旧摊销（百万元）
A2: 项目级资本开支 → 在建工程 → 转固 → 分年度折旧（年中法）；历史值来自报表附注与现金流量表补充资料。
A4: 百万元 | B4: 单位 | C4: 2020A | D4: 2021A | E4: 2022A | F4: 2023A | G4: 2024A | H4: 2025A | I4: 2026E | J4: 2027E | K4: 2028E | L4: 2029E | M4: 2030E | N4: 说明 / 来源
A5: 一、项目级资本开支（现金口径，含设备预付）
A6: 其中：已开工电子布项目承诺投资（下限） | B6: 百万元 | I6: 450 | J6: 150 | K6: 0 | L6: 0 | M6: 0 | N6: 已开工的石英电子纱智能制造（一期，预算4.95亿元）与超薄石英电子布基材项目（预算2.00亿元）剩余投资，各情景相同
A7: 石英电子纱/电子布产能（与情景产能联动） | B7: 百万元 | I7: =MAX(I6,MAX(0,业务拆分!J31-业务拆分!I31)*$C$53)+0 -> 450 | J7: =MAX(J6,MAX(0,业务拆分!K31-业务拆分!J31)*$C$53)+0 -> 360 | K7: =MAX(K6,MAX(0,业务拆分!L31-业务拆分!K31)*$C$53)+0 -> 270 | L7: =MAX(L6,MAX(0,业务拆分!M31-业务拆分!L31)*$C$53)+0 -> 180 | M7: =MAX(M6,$C$54*$C$53)+0 -> 180 | N7: ＝下一年产能增量×单位产能投资（2030年按“资本开支”表2031E新增产能输入）。在建：石英电子纱智能制造（一期，湖北鼎益，预算4.95亿元，2026H1进度40%）、超薄石英电子布基材项目（预算2.00亿元，进度50%）
A8: 合成石英材料扩产（六/七期等） | B8: 百万元 | I8: 100 | J8: 100 | K8: 80 | L8: 60 | M8: 60 | N8: 五期（预算0.95亿元）2025年、六期（0.37亿元）2026年竣工投产，七期2026年启动建设
A9: 光掩膜基板（合肥光微/济南光微） | B9: 百万元 | I9: 50 | J9: 40 | K9: 30 | L9: 20 | M9: 20 | N9: 济南光微预算4.49亿元已投入4.04亿元（2026H1建设完成）；合肥光微预算2.46亿元已投入2.00亿元
A10: 嘉殷新材料基地（荆州，穿透持股65.64%） | B10: 百万元 | I10: 100 | J10: 120 | K10: 40 | L10: 0 | M10: 0 | N10: 基建工程预算3.28亿元，2026H1进度25%；合作方深创投新材料基金等
A11: 半导体材料/器件及航空航天复合材料扩产 | B11: 百万元 | I11: 120 | J11: 130 | K11: 120 | L11: 100 | M11: 100 | N11: 气熔/电熔材料、半导体器件（湖北石创）、立体编织与复合材料
A12: 光纤配套高纯精密石英材料（湖北聚通，持股51%） | B12: 百万元 | I12: 60 | J12: 40 | K12: 0 | L12: 0 | M12: 0 | N12: 注册资本1亿元，年产70吨衬管/套管（2026-06-09公告）
A13: 维护性资本开支 / 收入 | B13: % | I13: 0.03 | J13: 0.04 | K13: 0.05 | L13: 0.06 | M13: 0.065 | N13: 维护性及零星工程，随资产规模扩大逐年提高，使2030E资本开支不低于折旧摊销；2023-2025年资本开支/收入21%-28%，2026H1为32%
A14: 维护性及其他零星资本开支 | B14: 百万元 | I14: =I13*利润表!I5 -> 82.23021 | J14: =J13*利润表!J5 -> 140.41825 | K14: =K13*利润表!K5 -> 220.99842 | L14: =L13*利润表!L5 -> 308.6115 | M14: =M13*利润表!M5 -> 370.65703
A15: 土地使用权及其他无形资产购置 | B15: 百万元 | I15: 40 | J15: 30 | K15: 20 | L15: 20 | M15: 20 | N15: 新基地土地款；历史见无形资产附注
A16: 长期待摊费用新增（=当年摊销，维持余额） | B16: 百万元 | I16: =I47 -> 13.3 | J16: =J47 -> 13.3 | K16: =K47 -> 13.3 | L16: =L47 -> 13.3 | M16: =M47 -> 13.3
A17: 资本开支合计（购建长期资产支付的现金） | B17: 百万元 | C17: 203.6003 | D17: 318.8237 | E17: 572.6832 | F17: 544.5963 | G17: 369.8711 | H17: 558.9568 | I17: =I7+I8+I9+I10+I11+I12+I14+I15+I16 -> 1015.5302 | J17: =J7+J8+J9+J10+J11+J12+J14+J15+J16 -> 973.71825 | K17: =K7+K8+K9+K10+K11+K12+K14+K15+K16 -> 794.29842 | L17: =L7+L8+L9+L10+L11+L12+L14+L15+L16 -> 701.9115 | M17: =M7+M8+M9+M10+M11+M12+M14+M15+M16 -> 763.95703 | N17: 历史：来源：Wind（公司公告值），万元÷100
A18: 资本开支 / 收入 | B18: % | C18: =C17/利润表!C5 -> 0.23576357 | D18: =D17/利润表!D5 -> 0.26057302 | E18: =E17/利润表!E5 -> 0.33307828 | F18: =F17/利润表!F5 -> 0.26050476 | G18: =G17/利润表!G5 -> 0.21234854 | H18: =H17/利润表!H5 -> 0.27721234 | I18: =I17/利润表!I5 -> 0.3704953 | J18: =J17/利润表!J5 -> 0.27737656 | ... M18: =M17/利润表!M5 -> 0.13397077
A19: 资本开支 / 折旧摊销 | B19: x | C19: =IFERROR(C17/C49,0) -> 3.320032 | D19: =IFERROR(D17/D49,0) -> 3.745698 | E19: =IFERROR(E17/E49,0) -> 4.9787499 | F19: =IFERROR(F17/F49,0) -> 3.2501337 | G19: =IFERROR(G17/G49,0) -> 1.7869093 | H19: =IFERROR(H17/H49,0) -> 2.2510597 | I19: =I17/I49 -> 3.3792078 | J19: =J17/J49 -> 2.6742679 | K19: =K17/K49 -> 1.7905478 | L19: =L17/L49 -> 1.350187 | M19: =M17/M49 -> 1.2985676
A20: 二、设备及工程预付款（其他非流动资产）
A21: 预付款 / 当年资本开支 | B21: % | C21: =IFERROR(C22/C17,0) -> 0 | D21: =IFERROR(D22/D17,0) -> 0.29743021 | E21: =IFERROR(E22/E17,0) -> 0.12608681 | F21: =IFERROR(F22/F17,0) -> 0.31401646 | G21: =IFERROR(G22/G17,0) -> 0.42300818 | H21: =IFERROR(H22/H17,0) -> 0.41882056 | I21: 0.4 | J21: 0.4 | K21: 0.4 | L21: 0.4 | M21: 0.4
A22: 其他非流动资产余额 | B22: 百万元 | C22: 0 | D22: 94.8278 | E22: 72.2078 | F22: 171.0122 | G22: 156.4585 | H22: 234.1026 | I22: =I21*I17 -> 406.21208 | J22: =J21*J17 -> 389.4873 | K22: =K21*K17 -> 317.71937 | L22: =L21*L17 -> 280.7646 | M22: =M21*M17 -> 305.58281
A23: 预付款增加（占用现金、尚未进入在建工程） | B23: 百万元 | I23: =I22-H22 -> 172.10948 | J23: =J22-I22 -> -16.724786 | K23: =K22-J22 -> -71.767931 | L23: =L22-K22 -> -36.954767 | M23: =M22-L22 -> 24.818213
A24: 三、在建工程
A25: 期初 | B25: 百万元 | I25: =H29 -> 207.0485 | J25: =I29 -> 411.72256 | K25: =J29 -> 487.37894 | L25: =K29 -> 384.7014 | M25: =L29 -> 273.57966
A26: 本期增加（项目资本开支−预付款增加） | B26: 百万元 | I26: =I7+I8+I9+I10+I11+I12-I23 -> 707.89052 | J26: =J7+J8+J9+J10+J11+J12-J23 -> 806.72479 | K26: =K7+K8+K9+K10+K11+K12-K23 -> 611.76793 | L26: =L7+L8+L9+L10+L11+L12-L23 -> 396.95477 | M26: =M7+M8+M9+M10+M11+M12-M23 -> 335.18179
A27: 转固比例（期初+本期增加） | B27: % | I27: 0.55 | J27: 0.6 | K27: 0.65 | L27: 0.65 | M27: 0.65 | N27: 按项目投产节奏设定；历史转固见“底稿”在建工程表
A28: 转入固定资产 | B28: 百万元 | I28: =(I25+I26)*I27 -> 503.21646 | J28: =(J25+J26)*J27 -> 731.06841 | K28: =(K25+K26)*K27 -> 714.44546 | L28: =(L25+L26)*L27 -> 508.07651 | M28: =(M25+M26)*M27 -> 395.69494
A29: 期末在建工程 | B29: 百万元 | C29: 118.3541 | D29: 57.9785 | E29: 179.4215 | F29: 134.2695 | G29: 265.7579 | H29: 207.0485 | I29: =I25+I26-I28 -> 411.72256 | J29: =J25+J26-J28 -> 487.37894 | K29: =K25+K26-K28 -> 384.7014 | L29: =L25+L26-L28 -> 273.57966 | M29: =M25+M26-M28 -> 213.06651
A30: 四、固定资产与折旧
A31: 固定资产增加（在建转固+维护性开支） | B31: 百万元 | I31: =I28+I14 -> 585.44667 | J31: =J28+J14 -> 871.48665 | K31: =K28+K14 -> 935.44388 | L31: =L28+L14 -> 816.68801 | M31: =M28+M14 -> 766.35198
A32: 存量资产折旧（2025年末资产） | B32: 百万元 | I32: =H40*$C$55 -> 238.64263 | J32: =I32*(1-$C$52) -> 231.48335 | K32: =J32*(1-$C$52) -> 224.53885 | L32: =K32*(1-$C$52) -> 217.80269 | M32: =L32*(1-$C$52) -> 211.26861 | N32: 2026年含2025年新增资产的全年化效应；之后按到期比例逐年滚出
A33: 新增资产综合折旧年限 | B33: 年 | I33: 10 | J33: 10 | K33: 10 | L33: 10 | M33: 10 | N33: 机器设备10年、房屋20-30年，新增资产以设备为主，综合按10年；残值率5%
A34: 残值率 | B34: % | I34: 0.05 | J34: 0.05 | K34: 0.05 | L34: 0.05 | M34: 0.05
A35: 2026年新增资产折旧 | B35: 百万元 | I35: =$I$31*(1-$I$34)/$I$33*0.5 -> 27.808717 | J35: =$I$31*(1-$I$34)/$I$33*1 -> 55.617434 | K35: =$I$31*(1-$I$34)/$I$33*1 -> 55.617434 | L35: =$I$31*(1-$I$34)/$I$33*1 -> 55.617434 | M35: =$I$31*(1-$I$34)/$I$33*1 -> 55.617434
A36: 2027年新增资产折旧 | B36: 百万元 | J36: =$J$31*(1-$J$34)/$J$33*0.5 -> 41.395616 | K36: =$J$31*(1-$J$34)/$J$33*1 -> 82.791232 | L36: =$J$31*(1-$J$34)/$J$33*1 -> 82.791232 | M36: =$J$31*(1-$J$34)/$J$33*1 -> 82.791232
A37: 2028年新增资产折旧 | B37: 百万元 | K37: =$K$31*(1-$K$34)/$K$33*0.5 -> 44.433584 | L37: =$K$31*(1-$K$34)/$K$33*1 -> 88.867169 | M37: =$K$31*(1-$K$34)/$K$33*1 -> 88.867169
A38: 2029年新增资产折旧 | B38: 百万元 | L38: =$L$31*(1-$L$34)/$L$33*0.5 -> 38.792681 | M38: =$L$31*(1-$L$34)/$L$33*1 -> 77.585361
A39: 2030年新增资产折旧 | B39: 百万元 | M39: =$M$31*(1-$M$34)/$M$33*0.5 -> 36.401719
A40: 固定资产折旧合计 | B40: 百万元 | C40: 58.189 | D40: 77.6038 | E40: 103.5931 | F40: 151.4175 | G40: 182.7184 | H40: 220.9654 | I40: =I32+SUM(I35:I39) -> 266.45135 | J40: =J32+SUM(J35:J39) -> 328.4964 | K40: =K32+SUM(K35:K39) -> 407.3811 | L40: =L32+SUM(L35:L39) -> 483.8712 | M40: =M32+SUM(M35:M39) -> 552.53152 | N40: 历史：现金流量表补充资料
A41: 固定资产净值 | B41: 百万元 | C41: 605.6634 | D41: 970.4833 | E41: 1343.0813 | F41: 1765.0717 | G41: 1863.2982 | H41: 2318.4985 | I41: =H41+I31-I40 -> 2637.4938 | J41: =I41+J31-J40 -> 3180.4841 | K41: =J41+K31-K40 -> 3708.5468 | L41: =K41+L31-L40 -> 4041.3637 | M41: =L41+M31-M40 -> 4255.1841
...

Sheet 营运资本
A1: 营运资本：周转天数驱动（百万元 / 天）
A2: 应收类按营业收入、存货与应付类按营业成本计算周转天数（期末余额/年额×365）。历史天数为公式，预测天数为输入。
A4: 百万元 | B4: 单位 | C4: 2020A | D4: 2021A | E4: 2022A | F4: 2023A | G4: 2024A | H4: 2025A | I4: 2026E | J4: 2027E | K4: 2028E | L4: 2029E | M4: 2030E | N4: 说明 / 来源
A5: 周转天数（预测期为输入）
A6: 应收账款周转天数（基于收入） | B6: 天 | C6: =IFERROR(C21/利润表!C5*365,0) -> 92.72036 | D6: =IFERROR(D21/利润表!D5*365,0) -> 69.193685 | E6: =IFERROR(E21/利润表!E5*365,0) -> 71.126489 | F6: =IFERROR(F21/利润表!F5*365,0) -> 84.239533 | G6: =IFERROR(G21/利润表!G5*365,0) -> 105.07181 | H6: =IFERROR(H21/利润表!H5*365,0) -> 129.65476 | I6: 125 | J6: 124 | K6: 123 | L6: 122 | M6: 122 | N6: 年末应收天数低于上半年年化水平（2024年131→105天，2025年137→130天），2026H1年化129天，取125天
A7: 应收票据周转天数（基于收入） | B7: 天 | C7: =IFERROR(C22/利润表!C5*365,0) -> 92.499689 | D7: =IFERROR(D22/利润表!D5*365,0) -> 71.843 | E7: =IFERROR(E22/利润表!E5*365,0) -> 84.589348 | F7: =IFERROR(F22/利润表!F5*365,0) -> 70.836807 | G7: =IFERROR(G22/利润表!G5*365,0) -> 58.766606 | H7: =IFERROR(H22/利润表!H5*365,0) -> 63.490412 | I7: 60 | J7: 58 | K7: 56 | L7: 55 | M7: 55
A8: 应收款项融资周转天数（基于收入） | B8: 天 | C8: =IFERROR(C23/利润表!C5*365,0) -> 0 | D8: =IFERROR(D23/利润表!D5*365,0) -> 16.511756 | E8: =IFERROR(E23/利润表!E5*365,0) -> 8.7759503 | F8: =IFERROR(F23/利润表!F5*365,0) -> 18.542181 | G8: =IFERROR(G23/利润表!G5*365,0) -> 23.893052 | H8: =IFERROR(H23/利润表!H5*365,0) -> 16.188443 | I8: 15 | J8: 15 | K8: 15 | L8: 15 | M8: 15
A9: 预付款项周转天数（基于成本） | B9: 天 | C9: =IFERROR(C24/利润表!C7*365,0) -> 88.092231 | D9: =IFERROR(D24/利润表!D7*365,0) -> 23.930381 | E9: =IFERROR(E24/利润表!E7*365,0) -> 27.957249 | F9: =IFERROR(F24/利润表!F7*365,0) -> 68.04065 | G9: =IFERROR(G24/利润表!G7*365,0) -> 32.735618 | H9: =IFERROR(H24/利润表!H7*365,0) -> 37.19155 | I9: 30 | J9: 30 | K9: 30 | L9: 30 | M9: 30
A10: 其他应收款周转天数（基于收入） | B10: 天 | C10: =IFERROR(C25/利润表!C5*365,0) -> 0.29319924 | D10: =IFERROR(D25/利润表!D5*365,0) -> 1.7630279 | E10: =IFERROR(E25/利润表!E5*365,0) -> 0.39411202 | F10: =IFERROR(F25/利润表!F5*365,0) -> 0.49077139 | G10: =IFERROR(G25/利润表!G5*365,0) -> 4.0113485 | H10: =IFERROR(H25/利润表!H5*365,0) -> 8.198498 | I10: 4 | J10: 4 | K10: 4 | L10: 4 | M10: 4
A11: 存货周转天数（基于成本） | B11: 天 | C11: =IFERROR(C26/利润表!C7*365,0) -> 175.75333 | D11: =IFERROR(D26/利润表!D7*365,0) -> 196.30002 | E11: =IFERROR(E26/利润表!E7*365,0) -> 201.90417 | F11: =IFERROR(F26/利润表!F7*365,0) -> 230.1033 | G11: =IFERROR(G26/利润表!G7*365,0) -> 269.29101 | H11: =IFERROR(H26/利润表!H7*365,0) -> 315.10793 | I11: 330 | J11: 320 | K11: 310 | L11: 300 | M11: 295 | N11: 存货天数年末高于上半年（2025年302→315天），2026H1为311天，取330天后逐步优化
A12: 其他流动资产周转天数（基于收入） | B12: 天 | C12: =IFERROR(C27/利润表!C5*365,0) -> 7.0850918 | D12: =IFERROR(D27/利润表!D5*365,0) -> 4.3436414 | E12: =IFERROR(E27/利润表!E5*365,0) -> 10.297055 | F12: =IFERROR(F27/利润表!F5*365,0) -> 13.78537 | G12: =IFERROR(G27/利润表!G5*365,0) -> 16.770423 | H12: =IFERROR(H27/利润表!H5*365,0) -> 11.931154 | I12: 10 | J12: 10 | K12: 10 | L12: 10 | M12: 10
A13: 应付票据周转天数（基于成本） | B13: 天 | C13: =IFERROR(C28/利润表!C7*365,0) -> 99.647195 | D13: =IFERROR(D28/利润表!D7*365,0) -> 68.161315 | E13: =IFERROR(E28/利润表!E7*365,0) -> 58.037717 | F13: =IFERROR(F28/利润表!F7*365,0) -> 109.67827 | G13: =IFERROR(G28/利润表!G7*365,0) -> 59.85492 | H13: =IFERROR(H28/利润表!H7*365,0) -> 69.388136 | I13: 75 | J13: 75 | K13: 75 | L13: 75 | M13: 75 | N13: 2026H1应付票据大幅增加（3.55亿元）
A14: 应付账款周转天数（基于成本） | B14: 天 | C14: =IFERROR(C29/利润表!C7*365,0) -> 134.96086 | D14: =IFERROR(D29/利润表!D7*365,0) -> 123.33193 | E14: =IFERROR(E29/利润表!E7*365,0) -> 135.22879 | F14: =IFERROR(F29/利润表!F7*365,0) -> 104.78632 | G14: =IFERROR(G29/利润表!G7*365,0) -> 78.204626 | H14: =IFERROR(H29/利润表!H7*365,0) -> 117.85549 | I14: 110 | J14: 112 | K14: 112 | L14: 112 | M14: 112
A15: 合同负债周转天数（基于收入） | B15: 天 | C15: =IFERROR(C30/利润表!C5*365,0) -> 4.2820952 | D15: =IFERROR(D30/利润表!D5*365,0) -> 2.6689439 | E15: =IFERROR(E30/利润表!E5*365,0) -> 4.9204881 | F15: =IFERROR(F30/利润表!F5*365,0) -> 2.9720224 | G15: =IFERROR(G30/利润表!G5*365,0) -> 4.7579402 | H15: =IFERROR(H30/利润表!H5*365,0) -> 3.6981353 | I15: 4 | J15: 4 | K15: 4 | L15: 4 | M15: 4
A16: 应付职工薪酬周转天数（基于收入） | B16: 天 | C16: =IFERROR(C31/利润表!C5*365,0) -> 17.372256 | D16: =IFERROR(D31/利润表!D5*365,0) -> 13.53734 | E16: =IFERROR(E31/利润表!E5*365,0) -> 10.022015 | F16: =IFERROR(F31/利润表!F5*365,0) -> 10.557687 | G16: =IFERROR(G31/利润表!G5*365,0) -> 13.365874 | H16: =IFERROR(H31/利润表!H5*365,0) -> 14.497822 | I16: 14 | J16: 14 | K16: 14 | L16: 14 | M16: 14
A17: 应交税费周转天数（基于收入） | B17: 天 | C17: =IFERROR(C32/利润表!C5*365,0) -> 10.155928 | D17: =IFERROR(D32/利润表!D5*365,0) -> 10.253574 | E17: =IFERROR(E32/利润表!E5*365,0) -> 10.370974 | F17: =IFERROR(F32/利润表!F5*365,0) -> 8.6930561 | G17: =IFERROR(G32/利润表!G5*365,0) -> 4.7224421 | H17: =IFERROR(H32/利润表!H5*365,0) -> 13.579054 | I17: 11 | J17: 11 | K17: 11 | L17: 11 | M17: 11
A18: 其他应付款周转天数（基于收入） | B18: 天 | C18: =IFERROR(C33/利润表!C5*365,0) -> 4.7550095 | D18: =IFERROR(D33/利润表!D5*365,0) -> 8.8369165 | E18: =IFERROR(E33/利润表!E5*365,0) -> 5.945328 | F18: =IFERROR(F33/利润表!F5*365,0) -> 5.3845176 | G18: =IFERROR(G33/利润表!G5*365,0) -> 1.0187578 | H18: =IFERROR(H33/利润表!H5*365,0) -> 18.039176 | I18: 14 | J18: 12 | K18: 12 | L18: 12 | M18: 12 | N18: 2026年含限制性股票回购义务
A19: 其他流动负债周转天数（基于收入） | B19: 天 | C19: =IFERROR(C34/利润表!C5*365,0) -> 1.2000585 | D19: =IFERROR(D34/利润表!D5*365,0) -> 16.831965 | E19: =IFERROR(E34/利润表!E5*365,0) -> 11.048001 | F19: =IFERROR(F34/利润表!F5*365,0) -> 16.528253 | G19: =IFERROR(G34/利润表!G5*365,0) -> 14.410113 | H19: =IFERROR(H34/利润表!H5*365,0) -> 15.968213 | I19: 16 | J19: 16 | K19: 16 | L19: 16 | M19: 16
A20: 期末余额
A21: 应收账款 | B21: 百万元 | C21: 219.3734 | D21: 231.9502 | E21: 335.0477 | F21: 482.4831 | G21: 501.4117 | H21: 716.2445 | I21: =I6/365*利润表!I5 -> 938.70103 | J21: =J6/365*利润表!J5 -> 1192.5933 | K21: =K6/365*利润表!K5 -> 1489.4688 | L21: =L6/365*利润表!L5 -> 1719.2056 | M21: =M6/365*利润表!M5 -> 1906.013
A22: 应收票据 | B22: 百万元 | C22: 218.8513 | D22: 240.8312 | E22: 398.4657 | F22: 405.7188 | G22: 280.4393 | H22: 350.7365 | I22: =I7/365*利润表!I5 -> 450.57649 | J22: =J7/365*利润表!J5 -> 557.82591 | K22: =K7/365*利润表!K5 -> 678.13213 | L22: =L7/365*利润表!L5 -> 775.05172 | M22: =M7/365*利润表!M5 -> 859.26815
A23: 应收款项融资 | B23: 百万元 | C23: 0 | D23: 55.3505 | E23: 41.3399 | F23: 106.2006 | G23: 114.0197 | H23: 89.4289 | I23: =I8/365*利润表!I5 -> 112.64412 | J23: =J8/365*利润表!J5 -> 144.26532 | K23: =K8/365*利润表!K5 -> 181.64254 | L23: =L8/365*利润表!L5 -> 211.37774 | M23: =M8/365*利润表!M5 -> 234.34586
A24: 预付款项 | B24: 百万元 | C24: 99.8956 | D24: 39.4738 | E24: 64.245 | F24: 196.8847 | G24: 90.3373 | H24: 108.1176 | I24: =I9/365*利润表!I7 -> 112.11694 | J24: =J9/365*利润表!J7 -> 143.65661 | K24: =K9/365*利润表!K7 -> 184.3515 | L24: =L9/365*利润表!L7 -> 220.45938 | M24: =M9/365*利润表!M7 -> 249.67825
A25: 其他应收款 | B25: 百万元 | C25: 0.6937 | D25: 5.91 | E25: 1.8565 | F25: 2.8109 | G25: 19.1425 | H25: 45.2905 | I25: =I10/365*利润表!I5 -> 30.038433 | J25: =J10/365*利润表!J5 -> 38.470752 | K25: =K10/365*利润表!K5 -> 48.43801 | L25: =L10/365*利润表!L5 -> 56.367398 | M25: =M10/365*利润表!M5 -> 62.492229
A26: 存货 | B26: 百万元 | C26: 199.3023 | D26: 323.8021 | E26: 463.9703 | F26: 665.8346 | G26: 743.1362 | H26: 916.0337 | I26: =I11/365*利润表!I7 -> 1233.2864 | J26: =J11/365*利润表!J7 -> 1532.3372 | K26: =K11/365*利润表!K7 -> 1904.9655 | L26: =L11/365*利润表!L7 -> 2204.5938 | M26: =M11/365*利润表!M7 -> 2455.1694
A27: 其他流动资产 | B27: 百万元 | C27: 16.7631 | D27: 14.5607 | E27: 48.5052 | F27: 78.9559 | G27: 80.0299 | H27: 65.9106 | I27: =I12/365*利润表!I5 -> 75.096082 | J27: =J12/365*利润表!J5 -> 96.176881 | K27: =K12/365*利润表!K5 -> 121.09502 | L27: =L12/365*利润表!L5 -> 140.91849 | M27: =M12/365*利润表!M5 -> 156.23057
A28: 应付票据 | B28: 百万元 | C28: 112.9988 | D28: 112.4339 | E28: 133.3691 | F28: 317.3687 | G28: 165.1758 | H28: 201.7146 | I28: =I13/365*利润表!I7 -> 280.29235 | J28: =J13/365*利润表!J7 -> 359.14153 | K28: =K13/365*利润表!K7 -> 460.87874 | L28: =L13/365*利润表!L7 -> 551.14846 | M28: =M13/365*利润表!M7 -> 624.19562
A29: 应付账款 | B29: 百万元 | C29: 153.0441 | D29: 203.4393 | E29: 310.7521 | F29: 303.2132 | G29: 215.8137 | H29: 342.6115 | I29: =I14/365*利润表!I7 -> 411.09545 | J29: =J14/365*利润表!J7 -> 536.31802 | K29: =K14/365*利润表!K7 -> 688.24558 | L29: =L14/365*利润表!L7 -> 823.04836 | M29: =M14/365*利润表!M7 -> 932.13213
A30: 合同负债 | B30: 百万元 | C30: 10.1313 | D30: 8.9468 | E30: 23.1784 | F30: 17.0223 | G30: 22.7053 | H30: 20.4294 | I30: =I15/365*利润表!I5 -> 30.038433 | J30: =J15/365*利润表!J5 -> 38.470752 | K30: =K15/365*利润表!K5 -> 48.43801 | L30: =L15/365*利润表!L5 -> 56.367398 | M30: =M15/365*利润表!M5 -> 62.492229
A31: 应付职工薪酬 | B31: 百万元 | C31: 41.1022 | D31: 45.3797 | E31: 47.2096 | F31: 60.4693 | G31: 63.7831 | H31: 80.0895 | I31: =I16/365*利润表!I5 -> 105.13452 | J31: =J16/365*利润表!J5 -> 134.64763 | K31: =K16/365*利润表!K5 -> 169.53303 | L31: =L16/365*利润表!L5 -> 197.28589 | M31: =M16/365*利润表!M5 -> 218.7228
A32: 应交税费 | B32: 百万元 | C32: 24.0286 | D32: 34.3719 | E32: 48.8534 | F32: 49.7896 | G32: 22.5359 | H32: 75.014 | I32: =I17/365*利润表!I5 -> 82.60569 | J32: =J17/365*利润表!J5 -> 105.79457 | K32: =K17/365*利润表!K5 -> 133.20453 | L32: =L17/365*利润表!L5 -> 155.01034 | M32: =M17/365*利润表!M5 -> 171.85363
A33: 其他应付款 | B33: 百万元 | C33: 11.2502 | D33: 29.623 | E33: 28.006 | F33: 30.8399 | G33: 4.8616 | H33: 99.6528 | I33: =I18/365*利润表!I5 -> 105.13452 | J33: =J18/365*利润表!J5 -> 115.41226 | K33: =K18/365*利润表!K5 -> 145.31403 | L33: =L18/365*利润表!L5 -> 169.10219 | M33: =M18/365*利润表!M5 -> 187.47669
A34: 其他流动负债 | B34: 百万元 | C34: 2.8393 | D34: 56.4239 | E34: 52.0426 | F34: 94.6658 | G34: 68.7663 | H34: 88.2123 | I34: =I19/365*利润表!I5 -> 120.15373 | J34: =J19/365*利润表!J5 -> 153.88301 | K34: =K19/365*利润表!K5 -> 193.75204 | L34: =L19/365*利润表!L5 -> 225.46959 | M34: =M19/365*利润表!M5 -> 249.96892
A35: 经营性流动资产 | B35: 百万元 | C35: =C21+C22+C23+C24+C25+C26+C27 -> 754.8794 | D35: =D21+D22+D23+D24+D25+D26+D27 -> 911.8785 | E35: =E21+E22+E23+E24+E25+E26+E27 -> 1353.4303 | F35: =F21+F22+F23+F24+F25+F26+F27 -> 1938.8886 | G35: =G21+G22+G23+G24+G25+G26+G27 -> 1828.5166 | H35: =H21+H22+H23+H24+H25+H26+H27 -> 2291.7623 | I35: =I21+I22+I23+I24+I25+I26+I27 -> 2952.4595 | J35: =J21+J22+J23+J24+J25+J26+J27 -> 3705.326 | ... M35: =M21+M22+M23+M24+M25+M26+M27 -> 5923.1975
A36: 经营性流动负债 | B36: 百万元 | C36: =C28+C29+C30+C31+C32+C33+C34 -> 355.3945 | D36: =D28+D29+D30+D31+D32+D33+D34 -> 490.6185 | E36: =E28+E29+E30+E31+E32+E33+E34 -> 643.4112 | F36: =F28+F29+F30+F31+F32+F33+F34 -> 873.3688 | G36: =G28+G29+G30+G31+G32+G33+G34 -> 563.6417 | H36: =H28+H29+H30+H31+H32+H33+H34 -> 907.7241 | I36: =I28+I29+I30+I31+I32+I33+I34 -> 1134.4547 | J36: =J28+J29+J30+J31+J32+J33+J34 -> 1443.6678 | ... M36: =M28+M29+M30+M31+M32+M33+M34 -> 2446.842
A37: 经营性净营运资本 | B37: 百万元 | C37: =C35-C36 -> 399.4849 | D37: =D35-D36 -> 421.26 | E37: =E35-E36 -> 710.0191 | F37: =F35-F36 -> 1065.5198 | G37: =G35-G36 -> 1264.8749 | H37: =H35-H36 -> 1384.0382 | I37: =I35-I36 -> 1818.0048 | J37: =J35-J36 -> 2261.6582 | ... M37: =M35-M36 -> 3476.3555
A38: 净营运资本 / 收入 | B38: % | C38: =C37/利润表!C5 -> 0.46259256 | D38: =D37/利润表!D5 -> 0.3442937 | E38: =E37/利润表!E5 -> 0.41295421 | F38: =F37/利润表!F5 -> 0.50968576 | G38: =G37/利润表!G5 -> 0.72618362 | H38: =H37/利润表!H5 -> 0.68640809 | I38: =I37/利润表!I5 -> 0.66326163 | J38: =J37/利润表!J5 -> 0.64426335 | ... M38: =M37/利润表!M5 -> 0.60962854
A39: 净营运资本增加（现金流出为正） | B39: 百万元 | D39: =D37-C37 -> 21.7751 | E39: =E37-D37 -> 288.7591 | F39: =F37-E37 -> 355.5007 | G39: =G37-F37 -> 199.3551 | H39: =H37-G37 -> 119.1633 | I39: =I37-H37 -> 433.96656 | J39: =J37-I37 -> 443.65346 | K39: =K37-J37 -> 507.06926 | ... M39: =M37-L37 -> 325.81352
A40: 现金转换周期
A41: 应收类合计天数（应收账款+票据+应收款项融资） | B41: 天 | C41: =(C21+C22+C23)/利润表!C5*365 -> 185.22005 | D41: =(D21+D22+D23)/利润表!D5*365 -> 157.54844 | E41: =(E21+E22+E23)/利润表!E5*365 -> 164.49179 | F41: =(F21+F22+F23)/利润表!F5*365 -> 173.61852 | G41: =(G21+G22+G23)/利润表!G5*365 -> 187.73146 | H41: =(H21+H22+H23)/利润表!H5*365 -> 209.33362 | I41: =(I21+I22+I23)/利润表!I5*365 -> 200 | J41: =(J21+J22+J23)/利润表!J5*365 -> 197 | ... M41: =(M21+M22+M23)/利润表!M5*365 -> 192
...

Sheet 费用税率
A1: 期间费用、其他收益、减值、所得税与少数股东损益（百万元 / %）
A2: 费用率含股份支付摊销；股份支付金额单列于“融资”表用于现金流加回与资本公积。
A4: 百万元 | B4: 单位 | C4: 2020A | D4: 2021A | E4: 2022A | F4: 2023A | G4: 2024A | H4: 2025A | I4: 2026E | J4: 2027E | K4: 2028E | L4: 2029E | M4: 2030E | N4: 说明 / 来源
A5: 费用率（占营业收入）
A6: 税金及附加率 | B6: % | C6: =利润表!C10/利润表!C5 -> 0.010376477 | D6: =利润表!D10/利润表!D5 -> 0.0070204824 | E6: =利润表!E10/利润表!E5 -> 0.0098192054 | F6: =利润表!F10/利润表!F5 -> 0.010327606 | G6: =利润表!G10/利润表!G5 -> 0.010165796 | H6: =利润表!H10/利润表!H5 -> 0.012280563 | I6: 0.013 | J6: 0.013 | K6: 0.013 | L6: 0.013 | M6: 0.013
A7: 销售费用率 | B7: % | C7: =利润表!C11/利润表!C5 -> 0.014151583 | D7: =利润表!D11/利润表!D5 -> 0.011999035 | E7: =利润表!E11/利润表!E5 -> 0.010405526 | F7: =利润表!F11/利润表!F5 -> 0.01159742 | G7: =利润表!G11/利润表!G5 -> 0.014311882 | H7: =利润表!H11/利润表!H5 -> 0.015614758 | I7: 0.013 | J7: 0.012 | K7: 0.012 | L7: 0.012 | M7: 0.012
A8: 管理费用率（不含股份支付） | B8: % | C8: =(利润表!C12-N(融资!C26))/利润表!C5 -> 0.10454779 | D8: =(利润表!D12-N(融资!D26))/利润表!D5 -> 0.060323809 | E8: =(利润表!E12-N(融资!E26))/利润表!E5 -> 0.041591397 | F8: =(利润表!F12-N(融资!F26))/利润表!F5 -> 0.06054476 | G8: =(利润表!G12-N(融资!G26))/利润表!G5 -> 0.096779422 | H8: =(利润表!H12-N(融资!H26))/利润表!H5 -> 0.080836109 | I8: 0.062 | J8: 0.06 | K8: 0.057 | L8: 0.055 | M8: 0.053 | N8: 不含股份支付；2026H1管理费用+51%（薪酬、水电及折旧）
A9: 研发费用率 | B9: % | C9: =利润表!C13/利润表!C5 -> 0.085102532 | D9: =利润表!D13/利润表!D5 -> 0.077552306 | E9: =利润表!E13/利润表!E5 -> 0.089978906 | F9: =利润表!F13/利润表!F5 -> 0.10676979 | G9: =利润表!G13/利润表!G5 -> 0.14349659 | H9: =利润表!H13/利润表!H5 -> 0.13999408 | I9: 0.126 | J9: 0.11 | K9: 0.1 | L9: 0.093 | M9: 0.089 | N9: 2025年14.0%，2026H1 12.3%；下半年研发通常环比增加（2022/2023/2025年+26%/+35%/+31%），2026年取12.6%；之后随收入放量下降，且不低于2026H1年化金额
A10: 研发费用下限（2026H1年化） | B10: 百万元 | I10: 321.3 | J10: 321.3 | K10: 321.3 | L10: 321.3 | M10: 321.3 | N10: 研发团队与项目具有刚性，收入下行时研发费用不低于2026H1年化水平（160.63×2）
A11: 其他经营性损益
A12: 其他收益（政府补助、加计抵减等）/ 收入 | B12: % | C12: =利润表!C15/利润表!C5 -> 0.011384608 | D12: =利润表!D15/利润表!D5 -> 0.017061115 | E12: =利润表!E15/利润表!E5 -> 0.0085560648 | F12: =利润表!F15/利润表!F5 -> 0.024665749 | G12: =利润表!G15/利润表!G5 -> 0.033352807 | H12: =利润表!H15/利润表!H5 -> 0.026381595 | I12: 0.018 | J12: 0.016 | K12: 0.015 | L12: 0.014 | M12: 0.013 | N12: 政府补助及增值税加计抵减；2025年2.6%，2026H1 1.6%
A13: 信用减值损失 / 收入（损失为负） | B13: % | C13: =利润表!C18/利润表!C5 -> -0.00096343319 | D13: =利润表!D18/利润表!D5 -> -0.00049667018 | E13: =利润表!E18/利润表!E5 -> -0.0037095086 | F13: =利润表!F18/利润表!F5 -> -0.0050969543 | G13: =利润表!G18/利润表!G5 -> -0.004815906 | H13: =利润表!H18/利润表!H5 -> -0.0084916851 | I13: -0.006 | J13: -0.005 | K13: -0.005 | L13: -0.005 | M13: -0.005
A14: 资产减值损失 / 收入（损失为负） | B14: % | C14: =利润表!C19/利润表!C5 -> -0.00065321234 | D14: =利润表!D19/利润表!D5 -> -0.0018489665 | E14: =利润表!E19/利润表!E5 -> -0.0036490212 | F14: =利润表!F19/利润表!F5 -> -0.0047654135 | G14: =利润表!G19/利润表!G5 -> -0.011520421 | H14: =利润表!H19/利润表!H5 -> -0.017759129 | I14: -0.008 | J14: -0.007 | K14: -0.006 | L14: -0.006 | M14: -0.006 | N14: 主要为存货跌价；光伏相关产品价格压力
A15: 营业外收支净额 + 资产处置收益 | B15: 百万元 | C15: =利润表!C22+利润表!C20 -> -6.2964 | D15: =利润表!D22+利润表!D20 -> -7.7595 | E15: =利润表!E22+利润表!E20 -> -1.9804 | F15: =利润表!F22+利润表!F20 -> -3.7817 | G15: =利润表!G22+利润表!G20 -> -9.0021 | H15: =利润表!H22+利润表!H20 -> 11.3967 | I15: 0 | J15: 0 | K15: 0 | L15: 0 | M15: 0
A16: 所得税
A17: 法定税率（高新技术企业） | B17: % | I17: 0.15 | J17: 0.15 | K17: 0.15 | L17: 0.15 | M17: 0.15 | N17: 母公司、融鉴、湖北石创半导体高新证书2026年到期，已重新申请；若未通过适用25%
A18: 研发费用加计扣除比例 | B18: % | I18: 1 | J18: 1 | K18: 1 | L18: 1 | M18: 1 | N18: 2025年税率调节表：加计扣除节税46.51百万元（利润总额的10.0pct），约为研发费用×16.5%
A19: 研发加计扣除节税 | B19: 百万元 | I19: =利润表!I13*I18*I17 -> 51.805032 | J19: =利润表!J13*J18*J17 -> 57.922526 | K19: =利润表!K13*K18*K17 -> 66.299526 | L19: =利润表!L13*L18*L17 -> 71.752174 | M19: =利润表!M13*M18*M17 -> 76.127253
A20: 电子布利润留存于湖北鼎益（25%税率）的比例 | B20: % | I20: =MAX(0,1-业务拆分!I93/0.5189) -> 0.036423203 | J20: =MAX(0,1-业务拆分!J93/0.5189) -> 0.15205242 | K20: =MAX(0,1-业务拆分!K93/0.5189) -> 0.26768163 | L20: =MAX(0,1-业务拆分!L93/0.5189) -> 0.32549624 | M20: =MAX(0,1-业务拆分!M93/0.5189) -> 0.32549624 | N20: 由电子布少数股东比例反推：中益少数股东51.89%，其余利润视为留在全资子公司鼎益
A21: 鼎益25%税率的额外税负 | B21: 百万元 | I21: =I20*MAX(0,业务拆分!I86)*(0.25-I17) -> 0.68878347 | J21: =J20*MAX(0,业务拆分!J86)*(0.25-J17) -> 5.4188614 | K21: =K20*MAX(0,业务拆分!K86)*(0.25-K17) -> 15.204366 | L21: =L20*MAX(0,业务拆分!L86)*(0.25-L17) -> 22.508408 | M21: =M20*MAX(0,业务拆分!M86)*(0.25-M17) -> 24.441553
A22: 其他调整（占利润总额） | B22: % | I22: 0.035 | J22: 0.025 | K22: 0.015 | L22: 0.01 | M22: 0.01 | N22: 亏损子公司未确认递延所得税资产、不可抵扣项及25%税率主体；2025年约+3.6pct，2024年约+0.8pct（税率调节表倒算），随石创/济南光微减亏下降
A23: 有效所得税率 | B23: % | C23: =利润表!C24/利润表!C23 -> 0.12138366 | D23: =利润表!D24/利润表!D23 -> 0.11117402 | E23: =利润表!E24/利润表!E23 -> 0.094064065 | F23: =利润表!F24/利润表!F23 -> 0.10827052 | G23: =利润表!G24/利润表!G23 -> 0.052506904 | H23: =利润表!H24/利润表!H23 -> 0.086022665 | I23: =I17+(I21-I19)/利润表!I23+I22 -> 0.1170462 | J23: =J17+(J21-J19)/利润表!J23+J22 -> 0.12232914 | K23: =K17+(K21-K19)/利润表!K23+K22 -> 0.12713403 | L23: =L17+(L21-L19)/利润表!L23+L22 -> 0.1288001 | M23: =M17+(M21-M19)/利润表!M23+M22 -> 0.1302594 | N23: ＝法定15% − 研发加计扣除节税/利润总额 + 鼎益25%税率额外税负/利润总额 + 其他调整。2020-2025年全年有效税率5.3%-12.1%；半年报税率通常高于全年（加计扣除多在汇算清缴时确认）
A24: 少数股东损益
A25: 分部加权少数股东比例（按分部经营利润加权） | B25: % | I25: =IFERROR(SUMPRODUCT(业务拆分!I81:I87,业务拆分!I88:I94)/SUM(业务拆分!I81:I87),0) -> 0.14943767 | J25: =IFERROR(SUMPRODUCT(业务拆分!J81:J87,业务拆分!J88:J94)/SUM(业务拆分!J81:J87),0) -> 0.18705245 | K25: =IFERROR(SUMPRODUCT(业务拆分!K81:K87,业务拆分!K88:K94)/SUM(业务拆分!K81:K87),0) -> 0.19789524 | L25: =IFERROR(SUMPRODUCT(业务拆分!L81:L87,业务拆分!L88:L94)/SUM(业务拆分!L81:L87),0) -> 0.19614939 | M25: =IFERROR(SUMPRODUCT(业务拆分!M81:M87,业务拆分!M88:M94)/SUM(业务拆分!M81:M87),0) -> 0.20131985 | N25: 随业务结构变化：电子布、半导体加工等非全资主体占比提升会推高少数股东损益
A26: 亏损主体由少数股东分担的金额（上海石创/济南光微等） | B26: 百万元 | I26: -53 | J26: -40 | K26: -20 | L26: -5 | M26: 0 | N26: 上海石创2025年净亏损0.77亿元、2026H1亏损0.31亿元（少数股东48.87%，济南光微穿透少数股东约69%）；2026H1其他非全资子公司少数股东损益合计-6.5百万元，全年按-13计入；随光掩膜基板放量逐步收窄
A27: 少数股东损益 / 净利润 | B27: % | C27: =利润表!C26/利润表!C25 -> 0.0055927468 | D27: =利润表!D26/利润表!D25 -> 0.015097763 | E27: =利润表!E26/利润表!E25 -> 0.046869418 | F27: =利润表!F26/利润表!F25 -> 0.06400787 | G27: =利润表!G26/利润表!G25 -> 0.036959766 | H27: =利润表!H26/利润表!H25 -> -0.039365205 | I27: =利润表!I26/利润表!I25 -> 0.069639554 | J27: =利润表!J26/利润表!J25 -> 0.14133215 | ... M27: =利润表!M26/利润表!M25 -> 0.20131985 | N27: ＝ 分部经营利润加权的少数股东比例（见“业务拆分”）；2026H1实际4.4%（中益+41.8，石创-21.6，其他-6.5）

Sheet 融资
A1: 融资、金融资产与股东回报（百万元 / 百万股）
A2: 借款余额为输入；利息按平均余额计；现金为三表平衡项（来自现金流量表）。
A4: 百万元 | B4: 单位 | C4: 2020A | D4: 2021A | E4: 2022A | F4: 2023A | G4: 2024A | H4: 2025A | I4: 2026E | J4: 2027E | K4: 2028E | L4: 2029E | M4: 2030E | N4: 说明 / 来源
A5: 一、有息负债
A6: 短期借款 | B6: 百万元 | C6: 0 | D6: 0 | E6: 3 | F6: 142.9382 | G6: 117.4009 | H6: 195.6741 | I6: 120 | J6: 120 | K6: 120 | L6: 120 | M6: 120
A7: 一年内到期的非流动负债 | B7: 百万元 | C7: 0 | D7: 1.7833 | E7: 3.7349 | F7: 38.5681 | G7: 149.9592 | H7: 5.0356 | I7: 152 | J7: 50 | K7: 50 | L7: 50 | M7: 50
A8: 长期借款 | B8: 百万元 | C8: 0 | D8: 0 | E8: 32.9718 | F8: 113.5195 | G8: 69.012 | H8: 148.5 | I8: 29 | J8: 80 | K8: 80 | L8: 80 | M8: 80
A9: 有息负债合计 | B9: 百万元 | C9: =C6+C7+C8 -> 0 | D9: =D6+D7+D8 -> 1.7833 | E9: =E6+E7+E8 -> 39.7067 | F9: =F6+F7+F8 -> 295.0258 | G9: =G6+G7+G8 -> 336.3721 | H9: =H6+H7+H8 -> 349.2097 | I9: =I6+I7+I8 -> 301 | J9: =J6+J7+J8 -> 250 | ... M9: =M6+M7+M8 -> 250
A10: 借款利率 | B10: % | D10: =IFERROR(D11/AVERAGE(D9,C9),0) -> 0.31660405 | E10: =IFERROR(E11/AVERAGE(E9,D9),0) -> 0.02483008 | F10: =IFERROR(F11/AVERAGE(F9,E9),0) -> 0.02719007 | G10: =IFERROR(G11/AVERAGE(G9,F9),0) -> 0.041850313 | H10: =IFERROR(H11/AVERAGE(H9,G9),0) -> 0.027245764 | I10: 0.025 | J10: 0.025 | K10: 0.025 | L10: 0.025 | M10: 0.025
A11: 利息费用 | B11: 百万元 | C11: 0 | D11: 0.2823 | E11: 0.5151 | F11: 4.5507 | G11: 13.2121 | H11: 9.3396 | I11: =AVERAGE(I9,H9)*I10+H12*$C$39 -> 8.1276213 | J11: =AVERAGE(J9,I9)*J10+I12*$C$39 -> 6.8875 | K11: =AVERAGE(K9,J9)*K10+J12*$C$39 -> 6.25 | L11: =AVERAGE(L9,K9)*L10+K12*$C$39 -> 6.25 | M11: =AVERAGE(M9,L9)*M10+L12*$C$39 -> 6.25 | N11: 预测期含循环贷款利息（按期初余额计，避免循环引用）
A12: 循环贷款余额（最低现金缺口融资） | B12: 百万元 | C12: 0 | D12: 0 | E12: 0 | F12: 0 | G12: 0 | H12: 0 | I12: =MAX(0,H12+$C$38-资产负债表!H6-现金流量表!I27) -> 0 | J12: =MAX(0,I12+$C$38-资产负债表!I6-现金流量表!J27) -> 0 | K12: =MAX(0,J12+$C$38-资产负债表!J6-现金流量表!K27) -> 0 | L12: =MAX(0,K12+$C$38-资产负债表!K6-现金流量表!L27) -> 0 | M12: =MAX(0,L12+$C$38-资产负债表!L6-现金流量表!M27) -> 0 | N12: ＝ MAX(0, 期初余额 + 最低现金 − 期初现金 − 提款前现金净增加额)；现金充裕时自动偿还
A13: 二、现金与金融资产
A14: 货币资金（来自资产负债表） | B14: 百万元 | C14: 394.6839 | D14: 678.8377 | E14: 824.4059 | F14: 586.4147 | G14: 685.1896 | H14: 811.7069 | I14: =资产负债表!I6 -> 883.6335 | J14: =资产负债表!J6 -> 660.81006 | K14: =资产负债表!K6 -> 897.09512 | L14: =资产负债表!L6 -> 1562.8319 | M14: =资产负债表!M6 -> 2374.4046
A15: 现金收益率 | B15: % | D15: =IFERROR(D16/AVERAGE(D14,C14),0) -> 0.020741455 | E15: =IFERROR(E16/AVERAGE(E14,D14),0) -> 0.01733731 | F15: =IFERROR(F16/AVERAGE(F14,E14),0) -> 0.022655184 | G15: =IFERROR(G16/AVERAGE(G14,F14),0) -> 0.01438372 | H15: =IFERROR(H16/AVERAGE(H14,G14),0) -> 0.012917393 | I15: 0.01 | J15: 0.01 | K15: 0.01 | L15: 0.01 | M15: 0.01
A16: 利息收入 | B16: 百万元 | C16: 7.0732 | D16: 11.1332 | E16: 13.0311 | F16: 15.9812 | G16: 9.1452 | H16: 9.668 | I16: =H14*I15 -> 8.117069 | J16: =I14*J15 -> 8.836335 | K16: =J14*K15 -> 6.6081006 | L16: =K14*L15 -> 8.9709512 | M16: =L14*M15 -> 15.628319 | N16: 按期初现金计，避免循环引用
A17: 汇兑损益及手续费等（损失为正） | B17: 百万元 | C17: =利润表!C14-C11+C16 -> 8.6867 | D17: =利润表!D14-D11+D16 -> 2.81 | E17: =利润表!E14-E11+E16 -> -11.8685 | F17: =利润表!F14-F11+F16 -> -3.0723 | G17: =利润表!G14-G11+G16 -> -4.1674 | H17: =利润表!H14-H11+H16 -> 6.5618 | I17: 12 | J17: 0 | K17: 0 | L17: 0 | M17: 0 | N17: 2026H1汇兑损失较大（美元走弱）；境外收入约三成
A18: 交易性金融资产 | B18: 百万元 | C18: 452.7902 | D18: 280.944 | E18: 204.1341 | F18: 363.8887 | G18: 392.1992 | H18: 708.1757 | I18: 500 | J18: 500 | K18: 500 | L18: 500 | M18: 500 | N18: 结构性存款/理财，视同现金类资产
A19: 其他非流动金融资产 | B19: 百万元 | C19: 0 | D19: 0 | E19: 0 | F19: 566.2206 | G19: 452.9046 | H19: 244.1042 | I19: 170 | J19: 170 | K19: 170 | L19: 170 | M19: 170 | N19: 大额存单等
A20: 金融资产收益率（投资收益+公允价值变动） | B20: % | D20: =IFERROR((利润表!D16+利润表!D17)/AVERAGE(D18+D19,C18+C19),0) -> 0.038143786 | E20: =IFERROR((利润表!E16+利润表!E17)/AVERAGE(E18+E19,D18+D19),0) -> 0.034667407 | F20: =IFERROR((利润表!F16+利润表!F17)/AVERAGE(F18+F19,E18+E19),0) -> 0.033445202 | G20: =IFERROR((利润表!G16+利润表!G17)/AVERAGE(G18+G19,F18+F19),0) -> 0.032103977 | H20: =IFERROR((利润表!H16+利润表!H17)/AVERAGE(H18+H19,G18+G19),0) -> 0.02623313 | I20: 0.022 | J20: 0.022 | K20: 0.022 | L20: 0.022 | M20: 0.022
A21: 投资收益（含公允价值变动） | B21: 百万元 | I21: =AVERAGE(I18+I19,H18+H19)*I20 -> 17.845079 | J21: =AVERAGE(J18+J19,I18+I19)*J20 -> 14.74 | K21: =AVERAGE(K18+K19,J18+J19)*K20 -> 14.74 | L21: =AVERAGE(L18+L19,K18+K19)*L20 -> 14.74 | M21: =AVERAGE(M18+M19,L18+L19)*M20 -> 14.74
A22: 净现金（货币资金+金融资产−有息负债−循环贷款） | B22: 百万元 | C22: =C14+C18+C19-C9 -> 847.4741 | D22: =D14+D18+D19-D9 -> 957.9984 | E22: =E14+E18+E19-E9 -> 988.8333 | F22: =F14+F18+F19-F9 -> 1221.4982 | G22: =G14+G18+G19-G9 -> 1193.9213 | H22: =H14+H18+H19-H9 -> 1414.7771 | I22: =I14+I18+I19-I9-I12 -> 1252.6335 | J22: =J14+J18+J19-J9-J12 -> 1080.8101 | K22: =K14+K18+K19-K9-K12 -> 1317.0951 | L22: =L14+L18+L19-L9-L12 -> 1982.8319 | M22: =M14+M18+M19-M9-M12 -> 2794.4046
A23: 三、股本、股权融资与股份支付
A24: 新增股份（定增/股权激励行权） | B24: 百万股 | F24: 12.91 | G24: 2.45 | H24: 0 | I24: 3.46 | J24: 0.881 | K24: 0.881 | L24: 1.322 | M24: 1.322 | N24: 2026年：以简易程序定增3,459,409股（86.72元，2026-06-01上市）；2027-2030年：2026年计划（第二类限制性股票）首次授予440.60万股（2026-09-24授予，价格45.98元），按20%/20%/30%/30%四期归属，归属时发行并缴款；考核为以2025年营收为基数，2026-2029年增长不低于20%/40%/60%/80%（媒体报道口径）
A25: 上市公司股权融资现金（含激励行权款） | B25: 百万元 | I25: 294 | J25: 40.5 | K25: 40.5 | L25: 60.8 | M25: 60.8 | N25: 定增募资净额2.94亿元；之后为限制性股票归属缴款（归属股数×45.98元）
A26: 股份支付费用（非现金，计入费用） | B26: 百万元 | D26: 38.98 | E26: 86.47 | F26: 55.23 | G26: -21.71 | H26: 16.23 | I26: 66 | J26: 112 | K26: 56 | L26: 26 | M26: 10 | N26: 2025年计划总成本7,543万元（2026H1确认2,411万元）；2026年计划为第二类限制性股票（媒体报道），2026-09-24首次授予440.60万股、授予价45.98元，按公允价值约48元/股、四期归属估算总成本约2.1亿元；2024年因业绩未达标冲回2,171万元
A27: 股份回购（计入库存股） | B27: 百万元 | I27: 0 | J27: 0 | K27: 0 | L27: 0 | M27: 0
A28: 期末总股本 | B28: 百万股 | C28: 337.94 | D28: 337.94 | E28: 506.91 | F28: 519.82 | G28: 522.27 | H28: 522.27 | I28: =H28+I24 -> 525.73 | J28: =I28+J24 -> 526.611 | K28: =J28+K24 -> 527.492 | L28: =K28+L24 -> 528.814 | M28: =L28+M24 -> 530.136
A29: 摊薄股本（用于EPS） | B29: 百万股 | C29: 506.91 | D29: 506.91 | E29: 506.91 | F29: 519.82 | G29: 522.27 | H29: 522.27 | I29: =I28 -> 525.73 | J29: =J28 -> 526.611 | K29: =K28 -> 527.492 | L29: =L28 -> 528.814 | M29: =M28 -> 530.136 | N29: 按期末股本摊薄，与一致预期口径一致；2020–2021年按2022年每10股转增5股追溯调整
A30: 四、分红
A31: 分红率（上一年归母净利润） | B31: % | I31: 0.2016 | J31: 0.22 | K31: 0.22 | L31: 0.22 | M31: 0.22 | N31: 2024年度每10股派1.30元（2025年支付6,768万元）；2025年度未作年末分配，改为2026年中期每10股派1.70元（8,933万元，2026年下半年支付）；之后按上年归母净利润22%（公司章程：成长期现金分红比例不低于20%）
A32: 当年支付现金股利（上市公司股东） | B32: 百万元 | I32: =I31*利润表!H27 -> 89.346036 | J32: =J31*利润表!I27 -> 135.94309 | K32: =K31*利润表!J27 -> 165.27181 | L32: =L31*利润表!K27 -> 212.24139 | M32: =M31*利润表!L27 -> 244.27219
A33: 每股股利（按支付年） | B33: 元 | I33: =I32/H28 -> 0.1710725 | J33: =J32/I28 -> 0.25857966 | K33: =K32/J28 -> 0.31384041 | L33: =L32/K28 -> 0.40235944 | M33: =M32/L28 -> 0.46192459
A34: 五、少数股东
A35: 子公司吸收少数股东投资 | B35: 百万元 | C35: 0 | D35: 170.3155 | E35: 296.7675 | F35: 57.1025 | G35: 267.81 | H35: 503.4 | I35: 60 | J35: 0 | K35: 0 | L35: 0 | M35: 0 | N35: 2026H1子公司吸收少数股东投资0.60亿元
A36: 支付少数股东股利 | B36: 百万元 | C36: 0.8 | D36: 0.4 | E36: 6 | F36: 0.4 | G36: 11.4029 | H36: 8.4177 | I36: 8 | J36: 10 | K36: 15 | L36: 20 | M36: 25
A38: 最低现金余额 | B38: 百万元 | C38: 300 | D38: 最低经营现金（约1个月营业成本+费用）；现金低于此水平时自动提取循环贷款，有盈余时优先偿还
A39: 循环贷款利率 | B39: % | C39: 0.03

Sheet 利润表
A1: 利润表（百万元）
A2: 2020A–2025A 为公司公告值（Wind）；2026E–2030E 为模型预测。
A4: 百万元 | B4: 单位 | C4: 2020A | D4: 2021A | E4: 2022A | F4: 2023A | G4: 2024A | H4: 2025A | I4: 2026E | J4: 2027E | K4: 2028E | L4: 2029E | M4: 2030E | N4: 说明 / 来源
A5: 营业收入 | B5: 百万元 | C5: 863.5783 | D5: 1223.5484 | E5: 1719.3652 | F5: 2090.5426 | G5: 1741.8114 | H5: 2016.3489 | I5: =业务拆分!I45 -> 2741.007 | J5: =业务拆分!J45 -> 3510.4561 | K5: =业务拆分!K45 -> 4419.9684 | L5: =业务拆分!L45 -> 5143.525 | M5: =业务拆分!M45 -> 5702.4159
A6: 同比 | B6: % | D6: =D5/C5-1 -> 0.41683551 | E6: =E5/D5-1 -> 0.4052286 | F6: =F5/E5-1 -> 0.21588049 | G6: =G5/F5-1 -> -0.16681373 | H6: =H5/G5-1 -> 0.15761609 | I6: =I5/H5-1 -> 0.35939122 | J6: =J5/I5-1 -> 0.28071769 | K6: =K5/J5-1 -> 0.25908663 | ... M6: =M5/L5-1 -> 0.10865911
A7: 营业成本 | B7: 百万元 | C7: 413.9059 | D7: 602.0772 | E7: 838.7601 | F7: 1056.1762 | G7: 1007.255 | H7: 1061.0723 | I7: =业务拆分!I50 -> 1364.0894 | J7: =业务拆分!J50 -> 1747.8221 | K7: =业务拆分!K50 -> 2242.9432 | L7: =业务拆分!L50 -> 2682.2558 | M7: =业务拆分!M50 -> 3037.752
A8: 毛利 | B8: 百万元 | C8: =C5-C7 -> 449.6724 | D8: =D5-D7 -> 621.4712 | E8: =E5-E7 -> 880.6051 | F8: =F5-F7 -> 1034.3664 | G8: =G5-G7 -> 734.5564 | H8: =H5-H7 -> 955.2766 | I8: =I5-I7 -> 1376.9175 | J8: =J5-J7 -> 1762.634 | ... M8: =M5-M7 -> 2664.6639
A9: 毛利率 | B9: % | C9: =C8/C5 -> 0.52070831 | D9: =D8/D5 -> 0.50792531 | E9: =E8/E5 -> 0.51216874 | F9: =F8/F5 -> 0.4947837 | G9: =G8/G5 -> 0.42171983 | H9: =H8/H5 -> 0.47376553 | I9: =I8/I5 -> 0.50234003 | J9: =J8/J5 -> 0.50210968 | ... M9: =M8/M5 -> 0.46728684
A10: 税金及附加 | B10: 百万元 | C10: 8.9609 | D10: 8.5899 | E10: 16.8828 | F10: 21.5903 | G10: 17.7069 | H10: 24.7619 | I10: =I5*费用税率!I6 -> 35.633091 | J10: =J5*费用税率!J6 -> 45.63593 | K10: =K5*费用税率!K6 -> 57.459589 | L10: =L5*费用税率!L6 -> 66.865826 | M10: =M5*费用税率!M6 -> 74.131407
A11: 销售费用 | B11: 百万元 | C11: 12.221 | D11: 14.6814 | E11: 17.8909 | F11: 24.2449 | G11: 24.9286 | H11: 31.4848 | I11: =I5*费用税率!I7 -> 35.633091 | J11: =J5*费用税率!J7 -> 42.125474 | K11: =K5*费用税率!K7 -> 53.039621 | L11: =L5*费用税率!L7 -> 61.722301 | M11: =M5*费用税率!M7 -> 68.428991
A12: 管理费用 | B12: 百万元 | C12: 90.2852 | D12: 112.7891 | E12: 157.9808 | F12: 181.8014 | G12: 146.8615 | H12: 179.2238 | I12: =I5*费用税率!I8+融资!I26 -> 235.94243 | J12: =J5*费用税率!J8+融资!J26 -> 322.62737 | K12: =K5*费用税率!K8+融资!K26 -> 307.9382 | L12: =L5*费用税率!L8+融资!L26 -> 308.89388 | M12: =M5*费用税率!M8+融资!M26 -> 312.22804 | N12: 预测期 = 收入×管理费用率（不含股份支付）+ 股份支付费用
A13: 研发费用 | B13: 百万元 | C13: 73.4927 | D13: 94.889 | E13: 154.7066 | F13: 223.2068 | G13: 249.944 | H13: 282.2769 | I13: =MAX(I5*费用税率!I9,费用税率!I10) -> 345.36688 | J13: =MAX(J5*费用税率!J9,费用税率!J10) -> 386.15018 | K13: =MAX(K5*费用税率!K9,费用税率!K10) -> 441.99684 | L13: =MAX(L5*费用税率!L9,费用税率!L10) -> 478.34783 | M13: =MAX(M5*费用税率!M9,费用税率!M10) -> 507.51502 | N13: ＝ MAX(收入×研发费用率, 研发费用下限)
A14: 财务费用 | B14: 百万元 | C14: 1.6135 | D14: -8.0409 | E14: -24.3845 | F14: -14.5028 | G14: -0.1005 | H14: 6.2334 | I14: =融资!I11-融资!I16+融资!I17 -> 12.010552 | J14: =融资!J11-融资!J16+融资!J17 -> -1.948835 | K14: =融资!K11-融资!K16+融资!K17 -> -0.35810057 | L14: =融资!L11-融资!L16+融资!L17 -> -2.7209512 | M14: =融资!M11-融资!M16+融资!M17 -> -9.3783194
A15: 加：其他收益 | B15: 百万元 | C15: 9.8315 | D15: 20.8751 | E15: 14.711 | F15: 51.5648 | G15: 58.0943 | H15: 53.1945 | I15: =I5*费用税率!I12 -> 49.338126 | J15: =J5*费用税率!J12 -> 56.167298 | K15: =K5*费用税率!K12 -> 66.299526 | L15: =L5*费用税率!L12 -> 72.009351 | M15: =M5*费用税率!M12 -> 74.131407
A16: 投资净收益 | B16: 百万元 | C16: 4.5059 | D16: 13.0497 | E16: 7.9385 | F16: 2.8456 | G16: 11.9771 | H16: 3.7216 | I16: =融资!I21 -> 17.845079 | J16: =融资!J21 -> 14.74 | K16: =融资!K21 -> 14.74 | L16: =融资!L21 -> 14.74 | M16: =融资!M21 -> 14.74
A17: 公允价值变动净收益 | B17: 百万元 | C17: 2.7902 | D17: 0.944 | E17: 0.4697 | F17: 16.1219 | G17: 16.5186 | H17: 19.8539 | I17: 7.28 | J17: 0 | K17: 0 | L17: 0 | M17: 0 | N17: 2026E取上半年实际值；之后并入投资收益
A18: 信用减值损失 | B18: 百万元 | C18: -0.832 | D18: -0.6077 | E18: -6.378 | F18: -10.6554 | G18: -8.3884 | H18: -17.1222 | I18: =I5*费用税率!I13 -> -16.446042 | J18: =J5*费用税率!J13 -> -17.552281 | K18: =K5*费用税率!K13 -> -22.099842 | L18: =L5*费用税率!L13 -> -25.717625 | M18: =M5*费用税率!M13 -> -28.51208
A19: 资产减值损失 | B19: 百万元 | C19: -0.5641 | D19: -2.2623 | E19: -6.274 | F19: -9.9623 | G19: -20.0664 | H19: -35.8086 | I19: =I5*费用税率!I14 -> -21.928056 | J19: =J5*费用税率!J14 -> -24.573193 | K19: =K5*费用税率!K14 -> -26.51981 | L19: =L5*费用税率!L14 -> -30.86115 | M19: =M5*费用税率!M14 -> -34.214496
A20: 资产处置收益 | B20: 百万元 | C20: -0.0964 | D20: -5.3795 | E20: 0.2296 | F20: 0.3183 | G20: -2.0721 | H20: 0.7567 | I20: 3.8 | J20: 0 | K20: 0 | L20: 0 | M20: 0 | N20: 2026E取上半年实际值
A21: 营业利润 | B21: 百万元 | C21: =C8-C10-C11-C12-C13-C14+C15+C16+C17+C18+C19+C20 -> 278.7342 | D21: =D8-D10-D11-D12-D13-D14+D15+D16+D17+D18+D19+D20 -> 425.182 | E21: =E8-E10-E11-E12-E13-E14+E15+E16+E17+E18+E19+E20 -> 568.2253 | F21: =F8-F10-F11-F12-F13-F14+F15+F16+F17+F18+F19+F20 -> 648.2587 | G21: =G8-G10-G11-G12-G13-G14+G15+G16+G17+G18+G19+G20 -> 351.279 | H21: =H8-H10-H11-H12-H13-H14+H15+H16+H17+H18+H19+H20 -> 455.8917 | I21: =I8-I10-I11-I12-I13-I14+I15+I16+I17+I18+I19+I20 -> 752.22061 | J21: =J8-J10-J11-J12-J13-J14+J15+J16+J17+J18+J19+J20 -> 996.82572 | ... M21: =M8-M10-M11-M12-M13-M14+M15+M16+M17+M18+M19+M20 -> 1737.8836
A22: 加：营业外收支净额 | B22: 百万元 | C22: -6.2 | D22: -2.38 | E22: -2.21 | F22: -4.1 | G22: -6.93 | H22: 10.64 | I22: =费用税率!I15 -> 0 | J22: =费用税率!J15 -> 0 | K22: =费用税率!K15 -> 0 | L22: =费用税率!L15 -> 0 | M22: =费用税率!M15 -> 0
A23: 利润总额 | B23: 百万元 | C23: =C21+C22 -> 272.5342 | D23: =D21+D22 -> 422.802 | E23: =E21+E22 -> 566.0153 | F23: =F21+F22 -> 644.1587 | G23: =G21+G22 -> 344.349 | H23: =H21+H22 -> 466.5317 | I23: =I21+I22 -> 752.22061 | J23: =J21+J22 -> 996.82572 | ... M23: =M21+M22 -> 1737.8836
A24: 减：所得税 | B24: 百万元 | C24: 33.0812 | D24: 47.0046 | E24: 53.2417 | F24: 69.7434 | G24: 18.0807 | H24: 40.1323 | I24: =I23*费用税率!I23 -> 88.044563 | J24: =J23*费用税率!J23 -> 121.94084 | K24: =K23*费用税率!K23 -> 171.55071 | L24: =L23*费用税率!L23 -> 203.28918 | M24: =M23*费用税率!M23 -> 226.37568
A25: 净利润 | B25: 百万元 | C25: =C23-C24 -> 239.453 | D25: =D23-D24 -> 375.7974 | E25: =E23-E24 -> 512.7736 | F25: =F23-F24 -> 574.4153 | G25: =G23-G24 -> 326.2683 | H25: =H23-H24 -> 426.3994 | I25: =I23-I24 -> 664.17604 | J25: =J23-J24 -> 874.88488 | ... M25: =M23-M24 -> 1511.5079
A26: 减：少数股东损益 | B26: 百万元 | C26: 1.3392 | D26: 5.6737 | E26: 24.0334 | F26: 36.7671 | G26: 12.0588 | H26: -16.7853 | I26: =I25*费用税率!I25+费用税率!I26 -> 46.252923 | J26: =J25*费用税率!J25+费用税率!J26 -> 123.64936 | K26: =K25*费用税率!K25+费用税率!K26 -> 213.08462 | L26: =L25*费用税率!L25+费用税率!L26 -> 264.7136 | M26: =M25*费用税率!M25+费用税率!M26 -> 304.29654 | N26: ＝ 净利润×分部加权少数股东比例 + 亏损主体少数股东分担额
A27: 归属于母公司股东的净利润 | B27: 百万元 | C27: =C25-C26 -> 238.1138 | D27: =D25-D26 -> 370.1237 | E27: =E25-E26 -> 488.7402 | F27: =F25-F26 -> 537.6482 | G27: =G25-G26 -> 314.2095 | H27: =H25-H26 -> 443.1847 | I27: =I25-I26 -> 617.92312 | J27: =J25-J26 -> 751.23552 | ... M27: =M25-M26 -> 1207.2114
A28: 同比 | B28: % | D28: =D27/C27-1 -> 0.55439836 | E28: =E27/D27-1 -> 0.32047799 | F28: =F27/E27-1 -> 0.10006953 | G28: =G27/F27-1 -> -0.41558532 | H28: =H27/G27-1 -> 0.41047518 | I28: =I27/H27-1 -> 0.394279 | J28: =J27/I27-1 -> 0.2157427 | K28: =K27/J27-1 -> 0.28419591 | ... M28: =M27/L27-1 -> 0.087256413
A29: 每股收益（摊薄） | B29: 元 | C29: =C27/融资!C29 -> 0.46973585 | D29: =D27/融资!D29 -> 0.73015664 | E29: =E27/融资!E29 -> 0.96415577 | F29: =F27/融资!F29 -> 1.0342969 | G29: =G27/融资!G29 -> 0.60162272 | H29: =H27/融资!H29 -> 0.84857392 | I29: =I27/融资!I29 -> 1.1753621 | J29: =J27/融资!J29 -> 1.4265473 | ... M29: =M27/融资!M29 -> 2.277173
A30: 核心指标
A31: 期间费用合计（税金及附加+销售+管理+研发） | B31: 百万元 | C31: =C10+C11+C12+C13 -> 184.9598 | D31: =D10+D11+D12+D13 -> 230.9494 | E31: =E10+E11+E12+E13 -> 347.4611 | F31: =F10+F11+F12+F13 -> 450.8434 | G31: =G10+G11+G12+G13 -> 439.441 | H31: =H10+H11+H12+H13 -> 517.7474 | I31: =I10+I11+I12+I13 -> 652.5755 | J31: =J10+J11+J12+J13 -> 796.53895 | ... M31: =M10+M11+M12+M13 -> 962.30346
A32: EBIT（营业利润+财务费用−投资收益−公允价值变动） | B32: 百万元 | C32: =C21+C14-C16-C17 -> 273.0516 | D32: =D21+D14-D16-D17 -> 403.1474 | E32: =E21+E14-E16-E17 -> 535.4326 | F32: =F21+F14-F16-F17 -> 614.7884 | G32: =G21+G14-G16-G17 -> 322.6828 | H32: =H21+H14-H16-H17 -> 438.5496 | I32: =I21+I14-I16-I17 -> 739.10608 | J32: =J21+J14-J16-J17 -> 980.13688 | ... M32: =M21+M14-M16-M17 -> 1713.7653
A33: EBITDA | B33: 百万元 | C33: =C32+资本开支!C49 -> 334.3764 | D33: =D32+资本开支!D49 -> 488.2647 | E33: =E32+资本开支!E49 -> 650.4581 | F33: =F32+资本开支!F49 -> 782.3496 | G33: =G32+资本开支!G49 -> 529.6721 | H33: =H32+资本开支!H49 -> 686.8579 | I33: =I32+资本开支!I49 -> 1039.6292 | J33: =J32+资本开支!J49 -> 1344.2434 | ... M33: =M32+资本开支!M49 -> 2302.0727
A34: EBIT率 | B34: % | C34: =C32/C5 -> 0.31618627 | D34: =D32/D5 -> 0.32949036 | E34: =E32/E5 -> 0.31141296 | F34: =F32/F5 -> 0.29408078 | G34: =G32/G5 -> 0.18525703 | H34: =H32/H5 -> 0.21749688 | I34: =I32/I5 -> 0.26964764 | J34: =J32/J5 -> 0.27920499 | ... M34: =M32/M5 -> 0.30053319
A35: 归母净利率 | B35: % | C35: =C27/C5 -> 0.27572925 | D35: =D27/D5 -> 0.30250025 | E35: =E27/E5 -> 0.28425619 | F35: =F27/F5 -> 0.25718117 | G35: =G27/G5 -> 0.18039238 | H35: =H27/H5 -> 0.21979564 | I35: =I27/I5 -> 0.22543653 | J35: =J27/J5 -> 0.2139994 | ... M35: =M27/M5 -> 0.21170174
A36: 研发费用率 | B36: % | C36: =C13/C5 -> 0.085102532 | D36: =D13/D5 -> 0.077552306 | E36: =E13/E5 -> 0.089978906 | F36: =F13/F5 -> 0.10676979 | G36: =G13/G5 -> 0.14349659 | H36: =H13/H5 -> 0.13999408 | I36: =I13/I5 -> 0.126 | J36: =J13/J5 -> 0.11 | ... M36: =M13/M5 -> 0.089
A37: ROE（归母，期末） | B37: % | C37: =C27/资产负债表!C59 -> 0.11444528 | D37: =D27/资产负债表!D59 -> 0.15027944 | E37: =E27/资产负债表!E59 -> 0.16256808 | F37: =F27/资产负债表!F59 -> 0.13714292 | G37: =G27/资产负债表!G59 -> 0.076101319 | H37: =H27/资产负债表!H59 -> 0.09577148 | I37: =I27/资产负债表!I59 -> 0.11202174 | J37: =J27/资产负债表!J59 -> 0.1195494 | ... M37: =M27/资产负债表!M59 -> 0.13124031
A38: ROIC（税后EBIT/（净营运资本+固定资产+在建工程+无形资产）） | B38: % | C38: =C32*(1-费用税率!C23)/(营运资本!C37+资本开支!C41+资本开支!C29+资本开支!C46) -> 0.20327466 | D38: =D32*(1-费用税率!D23)/(营运资本!D37+资本开支!D41+资本开支!D29+资本开支!D46) -> 0.23173654 | E38: =E32*(1-费用税率!E23)/(营运资本!E37+资本开支!E41+资本开支!E29+资本开支!E46) -> 0.20347904 | F38: =F32*(1-费用税率!F23)/(营运资本!F37+资本开支!F41+资本开支!F29+资本开支!F46) -> 0.17418573 | G38: =G32*(1-费用税率!G23)/(营运资本!G37+资本开支!G41+资本开支!G29+资本开支!G46) -> 0.084769611 | H38: =H32*(1-费用税率!H23)/(营运资本!H37+资本开支!H41+资本开支!H29+资本开支!H46) -> 0.096138643 | I38: =I32*(1-费用税率!I23)/(营运资本!I37+资本开支!I41+资本开支!I29+资本开支!I46) -> 0.12681388 | J38: =J32*(1-费用税率!J23)/(营运资本!J37+资本开支!J41+资本开支!J29+资本开支!J46) -> 0.13838892 | ... M38: =M32*(1-费用税率!M23)/(营运资本!M37+资本开支!M41+资本开支!M29+资本开支!M46) -> 0.18126193
